Workbook

Sheet Read Me
A1: Microsoft Excel – Beginner to Advanced
A2: Subject: Microsoft Excel · Learner: Self learner, English · Cards: 40
A3: Source: Claude knowledge
A5: How to study a card
A6: 1. Read Side 1 only. Try to say the meaning, answer or formula out loud before looking further.
A7: 2. Check yourself against Side 2. Read the examples and the common mistake.
A8: 3. Do the practice on Side 3 without looking back. Then mark Status: New → Learning → Known.
A9: 4. Review on days 1, 3, 7, 15, 30, 60 after first study: write the date or ✓ in that day's column.
A10: Got it wrong on a review? Start that card's days again from Day 1.
A11: 5. Follow 'Study order': prerequisites come first, then easy to hard.
A13: Colours
A14: Shaded cells were added by Claude, not taken from your own book or notes. Check them against a trusted source,
A15: and mark the card 'Fix' in the OK / Fix column if anything is wrong. Unshaded cells came from your source.

Sheet Code concept (56-pt) cards
A1: Card | F1: Side 1 · Recognition | R1: Side 2 · Understanding | AT1: Side 3 · Real life & Practice | BD1: Auto | BF1: My review
A2: ID | B2: Topic | C2: Level | D2: Study order | E2: Source | F2: Concept | G2: Recall cue | H2: Read aloud | I2: Type | J2: How often used | K2: Importance (1-5) | L2: Origin / why it exists | M2: Pro tip | N2: Typing hint | O2: Memory story | P2: Picture it | Q2: Emotion hook | R2: Meaning (short) | S2: Meaning in learner's language | T2: Code | U2: Output | V2: Explanation | W2: Simple explanation (Hinglish) | X2: Real-life analogy | Y2: Syntax pattern | Z2: Anatomy | AA2: Example 1 | AB2: Example 2 | AC2: Example 3 | AD2: Variation | AE2: Used with | AF2: Related concepts | AG2: Alternatives | AH2: Family / group | AI2: Where it is used | AJ2: Mini conversation | AK2: Common mistake | AL2: Commonly confused with | AM2: Avoid / don't | AN2: Wrong code | AO2: Right code | AP2: Memory trick | AQ2: Real life: project / work | AR2: Real life: interview / exam | AS2: Real life: daily life | AT2: MCQ question | AU2: MCQ options | AV2: MCQ answer | AW2: Why that answer | AX2: Fill the blank | AY2: Task in learner's language | AZ2: Task answer | BA2: Write your own | BB2: Practice question | BC2: Practice answer | BD2: Importance ★ | BE2: Quick recall (reverse) | BF2: Status | BG2: Day 1 | BH2: Day 3 | BI2: Day 7 | BJ2: Day 15 | BK2: Day 30 | BL2: Day 60 | BM2: OK / Fix | BN2: My note
A3: XL-001 | B3: 01 Basics & Cells | C3: Beginner | D3: 1 | E3: Claude knowledge | F3: Cells, ranges and cell references | G3: How does Excel name one box on the sheet, and how do you point to a whole block of boxes in a formula? | H3: cell = सेल | range = रेंज | reference = रेफ़रेंस | I3: Core concept | J3: Very high | K3: 5 | L3: A worksheet is a grid, so each box needs an address; the column letter plus row number, like C3, works like a map coordinate. | M3: Click a cell and look at the Name Box on the left of the formula bar to see its exact address. | N3: Write the column letter first, then the row number: C3, not 3C. A colon joins two corners of a range. | O3: Think of a cinema seat: Row 3, Seat C is C3. A range A1:B2 is a small group of friends booking four seats together. | P3: A chessboard where one square glows with the label C3 and a rectangle of four squares is outlined in green. | Q3: The calm feeling of finally knowing exactly where every number lives. | R3: A cell is one box on the sheet, and a range is a block of cells. | S3: सेल = शीट का एक खाना; रेंज = कई खानों का समूह | T3: A1: 10 A2: 20 A3: 30 B1: =SUM(A1:A3) | U3: 60 | V3: A cell address is the column letter followed by the row number. A range uses a colon between its first and last cell, so A1:A3 means A1, A2 and A3. Formulas use these addresses so the answer updates when the numbers change. | W3: Har khane ka ek address hota hai, jaise A1. Kai khane ek saath lene hon to colon lagate hain, jaise A1:A3. Formula me address likhne se number badalne par answer khud badal jata hai. | X3: Like a cinema seat number: row and seat together tell you exactly one seat, and a seat block is a group of neighbouring seats. | Y3: =FUNCTION(first_cell:last_cell) | Z3: A = column letter | 1 = row number | A1 = one cell | A1:A3 = range from A1 down to A3 | AA3: A1: 10 B1: =A1 (shows 10, B1 just points to one cell) | AB3: A1: 10 A2: 20 A3: 30 B1: =SUM(A1:A3) (shows 60, a range down one column) | AC3: A1: 5 A2: 10 B1: 15 B2: 20 C1: =SUM(A1:B2) (shows 50, a block across two columns) | AD3: =SUM(A1,A3) adds only A1 and A3 (comma picks separate cells) =SUM(A:A) adds the whole column A Name Box: type D10 and press Enter to jump to D10 | AE3: SUM, AVERAGE, Name Box, formulas | AF3: Worksheet, Workbook, Named range, Table | AG3: Named range, Excel Table column reference | AH3: cell, range, row, column, address, selection | AI3: Budgets and totals | Marks sheets | Any formula you write | AJ3: A: My total shows 0, what did I do wrong? | B: Check your range; you may have typed A1:A2 instead of A1:A3 and missed a row. | AK3: ✗ A1:A3 means only the two cells A1 and A3 → ✓ A1:A3 means every cell from A1 through A3, including A2 | AL3: A1:A3 vs A1,A3: the colon takes the whole block, the comma takes only the cells you name. | AM3: Do not type numbers into a formula when the cell address can be used, or the answer will not update. | AN3: A1: 10 A2: 20 A3: 30 B1: =SUM(A1,A3) | AO3: A1: 10 A2: 20 A3: 30 B1: =SUM(A1:A3) | AP3: Colon = continues through all cells; comma = counts only the ones named. | AQ3: A school clerk sums the marks of one student by pointing a formula at the row range of that student. | AR3: Interview question: What is the difference between a cell reference and a range, and which symbol makes a range? | AS3: It is like telling a friend your flat number instead of saying the whole street, and a floor range instead of one flat. | AT3: A sheet has A1 = 4, A2 = 6, A3 = 8 and A4 = 10. What does =SUM(A2:A4) return? | AU3: A) 18 B) 24 C) 28 D) 30 | AV3: B | AW3: A2:A4 covers A2, A3 and A4, so 6 + 8 + 10 = 24; 28 would include A1 only by mistake, and 30 is a different total. | AX3: The address of the cell in column C and row 3 is ____ → C3 | AY3: Write a formula that adds the numbers in cells B2 down to B6. | AZ3: B7: =SUM(B2:B6) | BA3: Type five numbers in column A and write a SUM formula for them in A6. | BB3: A1: 4 A2: 6 A3: 8 A4: 10 B1: =SUM(A2:A4) What does B1 show? | BC3: 24 | BD3: =IF(K3="","",REPT("★",K3)&REPT("☆",5-K3)&" ("&K3&"/5)") | BE3: =IF(S3="","","Meaning: "&S3&" = ______ (Answer: "&F3&")") | BF3: New
A4: XL-002 | B4: 01 Basics & Cells | C4: Beginner | D4: 2 | E4: Claude knowledge | F4: Data types: text, number, date | G4: Why can a cell that looks like a number refuse to add up, and what does Excel secretly store behind a date? | H4: text = टेक्स्ट | number = नंबर | date = डेट | I4: Core concept | J4: Very high | K4: 5 | L4: Excel must know whether a value is a word, an amount or a day, because each kind follows different maths rules. | M4: If a number sits on the left of its cell, it is probably stored as text, so check it before you add it. | N4: Typing an apostrophe before a number, like '100, makes Excel store it as text on purpose. | O4: Excel is a strict clerk with three boxes marked Words, Amounts and Days, and he drops every entry into one box without asking you. | P4: Three coloured trays on a desk, with a paper marked 100 sitting in the Words tray looking out of place. | Q4: Relief when a total that showed the wrong value finally starts adding correctly. | R4: Excel stores each entry as text, a number or a date, and treats them differently. | S4: टेक्स्ट = शब्द, नंबर = संख्या, डेट = तारीख | T4: A1: 100 A2: '100 (typed with an apostrophe, so it is text) B1: =ISNUMBER(A1) B2: =ISNUMBER(A2) | U4: B1 shows TRUE and B2 shows FALSE | V4: ISNUMBER checks if a cell holds a real number. A1 is a number, but A2 was stored as text because of the apostrophe, even though it looks the same. Dates are numbers too: Excel counts days from 1 January 1900, and 1 January 2024 is stored as 45292. | W4: Excel teen cheez alag rakhta hai: text, number aur date. Text ke andar 100 likha ho to wo jodne me nahi aata. Date asal me ek number hai jo din ginta hai. | X4: Like a bank counter with separate windows for cash, cheques and letters, each handled by different rules. | Y4: =ISNUMBER(cell) | =ISTEXT(cell) | Z4: ISNUMBER = test function | cell = what to check | result = TRUE or FALSE | AA4: A1: Asha B1: =ISTEXT(A1) (shows TRUE, a word is text) | AB4: A1: 100 A2: '100 B1: =SUM(A1:A2) (shows 100, SUM skips the text one) | AC4: A1: =DATE(2024,1,1) A2: =DATE(2024,3,1) B1: =A2-A1 (cell format General, shows 60 days) | AD4: Format cell as General to see the date serial number, for example 45292 =VALUE(A2) converts text like "100" into the number 100 Data tab > Text to Columns > Finish converts a column of text numbers | AE4: ISNUMBER, ISTEXT, VALUE, Format Cells | AF4: Number format, Text to Columns, Date serial number, VALUE | AG4: VALUE function, Text to Columns, multiply by 1 | AH4: text, number, date, time, logical, error value | AI4: Importing data from other systems | Cleaning mark lists | Date calculations like due dates | AJ4: A: My SUM ignores some numbers in the column, why? | B: They are probably stored as text; look for left-aligned values and convert them. | AK4: ✗ Anything that looks like a number is a number → ✓ A value can look like 100 but be stored as text, and then SUM ignores it | AL4: Text 100 vs number 100: text looks the same but is ignored by SUM and sorts like a word. | AM4: Do not type numbers with extra spaces or apostrophes if you need to calculate with them. | AN4: A1: 100 A2: '100 A3: 50 B1: =SUM(A1:A3) (expecting 250) | AO4: A1: 100 A2: '100 A3: 50 B2: =VALUE(A2) B1: =SUM(A1,B2,A3) (shows 250) | AP4: Left = Letters (text), Right = Right numbers; this is the default alignment. | AQ4: A sales analyst imports a CSV and converts text numbers so that totals match the source report. | AR4: Interview question: Why does SUM give the wrong total when some numbers are stored as text? | AS4: It is like a shopkeeper who counts only real notes and puts photocopies of notes aside. | AT4: A cell shows 2500 on the left side of the cell, and SUM leaves it out. What is the most likely reason? | AU4: A) It is stored as text B) It is formatted as currency C) It is stored as a date D) The column is too narrow | AV4: A | AW4: Numbers align right by default and SUM skips text; currency or date formats do not make SUM skip a value. | AX4: Excel stores the date 1 January 2024 internally as the number ____ → 45292 | AY4: Write a formula that tells whether cell A1 holds a number. | AZ4: B1: =ISNUMBER(A1) | BA4: Type a number and the same number with an apostrophe, then compare them with ISNUMBER. | BB4: A1: 50 A2: '50 (text) A3: 50 B1: =SUM(A1:A3) What does B1 show? | BC4: 100 | BD4: =IF(K4="","",REPT("★",K4)&REPT("☆",5-K4)&" ("&K4&"/5)") | BE4: =IF(S4="","","Meaning: "&S4&" = ______ (Answer: "&F4&")") | BF4: New
A5: XL-003 | B5: 01 Basics & Cells | C5: Beginner | D5: 3 | E5: Claude knowledge | F5: AutoFill and the fill handle | G5: Which tiny square at a cell's corner lets you drag a pattern or formula down a column? | H5: AutoFill = ऑटोफ़िल | fill handle = फ़िल हैंडल | I5: Excel feature | J5: Very high | K5: 5 | L5: Typing the same pattern a hundred times is slow, so Excel guesses the pattern and repeats it for you. | M5: Double-click the fill handle to fill down as far as the data in the next column goes. | N5: Select the cell, then grab the small square at its bottom-right corner; the pointer turns into a thin black plus. | O5: The fill handle is a tiny tap at the corner of a water tank; pull it down and the pattern pours into every cell below. | P5: A green square at the corner of a cell, being dragged down while numbers appear one after another. | Q5: A happy surprise when a whole column fills itself in one second. | R5: AutoFill copies or continues a pattern by dragging the fill handle. | S5: ऑटोफ़िल = खींचकर पैटर्न या फ़ॉर्मूला अपने आप भरना | T5: A1: 1 A2: 2 Select A1:A2, drag the fill handle down to A5 | U5: A3 shows 3, A4 shows 4, A5 shows 5 | V5: Excel reads the first two values to find the step, here +1, and continues it. For text such as day names it continues the built-in list. For formulas it copies the formula and moves the relative references. | W5: Do cell select karke handle kheenchoge to Excel pattern samajh kar aage bhar deta hai. Ek hi number ho to wo copy ho jata hai. Formula ho to wo bhi neeche copy hota hai. | X5: Like showing a child 2, 4 and then saying carry on; the child continues 6, 8, 10 by the same rule. | Y5: Select cells > drag the fill handle (bottom-right square) | Z5: Selected cells = the pattern | fill handle = small square | drag direction = where the pattern continues | AA5: A1: 1 A2: 2 Select A1:A2, drag the handle to A5 (A5 shows 5, a number series) | AB5: A1: Mon Drag the handle down to A3 (A2 shows Tue, A3 shows Wed, a text list) | AC5: A1: 5 A2: 7 A3: 9 B1: =A1*2 Double-click the handle of B1 (B2 shows 14, B3 shows 18, a formula copy) | AD5: A single number such as 5 is copied, not counted, when you drag Hold Ctrl while dragging a single number to make it count up (Windows) Click the small Auto Fill Options button after dragging to choose Copy Cells or Fill Series | AE5: Fill series, relative references, Flash Fill, Ctrl+D | AF5: Relative reference, Custom lists, Ctrl+D, Flash Fill | AG5: Ctrl+D to fill down, Home tab > Fill > Series | AH5: AutoFill, fill handle, fill series, fill down, fill right, series | AI5: Serial numbers on a list | Dates and months across columns | Copying one formula to every row | AJ5: A: I typed 1 and dragged but I got 1, 1, 1; why? | B: A single number is copied, so enter 1 and 2 first and drag both cells. | AK5: ✗ Dragging one number always counts up, 1, 2, 3 → ✓ A single number is copied; give two cells to show the step, or hold Ctrl while dragging | AL5: Fill handle vs Ctrl+D: the handle drags to any distance and pattern, Ctrl+D copies the cell above into the selected cells. | AM5: Do not drag blindly over a long list when double-clicking the fill handle does the work in one move. | AN5: A1: 1 Drag the handle down to A5 (expecting 1, 2, 3, 4, 5) | AO5: A1: 1 A2: 2 Select A1:A2 and drag the handle down to A5 | AP5: Two cells show the step; one cell shows only copy. | AQ5: An office assistant numbers 200 employee rows by dragging the handle instead of typing every number. | AR5: Interview question: How do you quickly copy a formula down 500 rows without dragging? | AS5: It is like a teacher writing the first two roll numbers and asking the class monitor to continue the list. | AT5: A1 contains 5 and nothing else. You drag the fill handle from A1 down to A3 without pressing any key. What does A3 show? | AU5: A) 3 B) 5 C) 7 D) 15 | AV5: B | AW5: One plain number is copied, so A2 and A3 both show 5; counting needs two example cells or the Ctrl key. | AX5: The small square at the bottom-right corner of a selected cell is called the ____ → fill handle | AY5: Fill the numbers 10, 20, 30, 40 in column A using only two typed cells. | AZ5: A1: 10 A2: 20 Select A1:A2 and drag the fill handle down to A4 | BA5: Type Jan in one cell and drag it across to see the months continue. | BB5: A1: 10 A2: 20 You select A1:A2 and drag the fill handle down to A4. What does A4 show? | BC5: 40 | BD5: =IF(K5="","",REPT("★",K5)&REPT("☆",5-K5)&" ("&K5&"/5)") | BE5: =IF(S5="","","Meaning: "&S5&" = ______ (Answer: "&F5&")") | BF5: New
A6: XL-004 | B6: 01 Basics & Cells | C6: Beginner | D6: 4 | E6: Claude knowledge | F6: Flash Fill | G6: Which feature watches one example you type and then completes the whole column without a formula? | H6: Flash Fill = फ़्लैश फ़िल | I6: Excel feature | J6: Medium | K6: 3 | L6: Added in Excel 2013, it learns a pattern from your typed example so you can split or join text without writing formulas. | M6: Press Ctrl+E on Windows right after typing the first example to apply it instantly. On other versions use Data tab > Flash Fill. | N6: Type the first result in the cell next to your data, move to the next cell below, then press Ctrl+E. | O6: A parrot hears you say Asha once and then repeats the first name for every row on its own. | P6: A column of full names with a lightning bolt, and the first names appearing in the next column row by row. | Q6: A little delight when messy text sorts itself out in a blink. | R6: Flash Fill copies a pattern you typed once to the other rows. | S6: फ़्लैश फ़िल = एक उदाहरण देखकर बाकी पंक्तियाँ अपने आप भरना | T6: A1: Asha Rao A2: Sita Devi B1: Asha (typed by you) Click B2, press Ctrl+E | U6: B2 shows Sita | V6: Excel compares your typed example with the cell beside it and finds the pattern, here the first word. It then fills the rest of the column using that pattern. The result is plain text, not a formula, so it will not update later. | W6: Pehli row me jo chahiye wo khud likho, phir Ctrl+E dabao. Excel pattern pehchan kar baaki sab bhar deta hai. Ye formula nahi hai, sirf text hai. | X6: Like showing a tailor one sample shirt, then asking him to stitch the rest in exactly the same style. | Y6: Type first example > Ctrl+E (or Data tab > Flash Fill) | Z6: Source column = the data | typed example = the pattern | Ctrl+E = apply to all rows | AA6: A1: Asha Rao A2: Sita Devi B1: Asha Click B2, press Ctrl+E (B2 shows Sita, a split) | AB6: A1: Asha B1: Rao C1: Asha Rao (typed) Click C2, press Ctrl+E (joins first and last name for each row) | AC6: A1: 9876543210 B1: 98765-43210 (typed) Click B2, press Ctrl+E (adds a dash in the same place for all rows) | AD6: Data tab > Flash Fill does the same as Ctrl+E File > Options > Advanced > Automatically Flash Fill turns the live suggestion on or off If the grey preview appears while you type, press Enter to accept it | AE6: Text to Columns, LEFT, MID, CONCAT | AF6: Text to Columns, LEFT and RIGHT, TEXTJOIN, AutoFill | AG6: Text to Columns, LEFT/MID/RIGHT formulas, TEXTSPLIT in Microsoft 365 | AH6: Flash Fill, pattern, split, join, extract, clean | AI6: Splitting full names | Fixing phone number format | Making email IDs from names | AJ6: A: I have full names in one column, can I get only first names fast? | B: Type the first name once next to it and press Ctrl+E. | AK6: ✗ Flash Fill creates a formula that updates when the data changes → ✓ Flash Fill writes fixed values, so you must run it again after the source changes | AL6: Flash Fill vs AutoFill: Flash Fill learns a text pattern from an example, while AutoFill continues a number or list series. | AM6: Do not trust Flash Fill blindly on messy data; always scan the results for wrong rows. | AN6: A1: Asha Rao A2: Sita Devi Select B2 and press Ctrl+E with B1 left empty | AO6: A1: Asha Rao A2: Sita Devi B1: Asha (typed) Click B2, press Ctrl+E | AP6: Type one, press Ctrl+E, check all. | AQ6: A data entry person splits 1,000 full names into first and last name columns in a few seconds. | AR6: Interview question: How can you split a name column without writing a formula? | AS6: It is like showing a friend one correctly written address label and asking him to copy the style on the rest. | AT6: You used Flash Fill to get first names in column B. Later you change the name in A2. What happens to the value in B2? | AU6: A) It updates by itself B) It turns into an error C) It stays as it was D) It is deleted | AV6: C | AW6: Flash Fill pastes fixed values, not formulas, so B2 does not follow A2 afterwards. | AX6: The Windows shortcut for Flash Fill is Ctrl + ____ → E | AY6: Column A has full names. Get only the first name in column B using Flash Fill. | AZ6: B1: type the first name by hand Click B2 and press Ctrl+E | BA6: Take five full names and use Flash Fill to make short names such as A. Rao. | BB6: A1: Ravi Kumar A2: Sita Devi You type Ravi in B1, click B2 and press Ctrl+E. What does B2 show? | BC6: Sita | BD6: =IF(K6="","",REPT("★",K6)&REPT("☆",5-K6)&" ("&K6&"/5)") | BE6: =IF(S6="","","Meaning: "&S6&" = ______ (Answer: "&F6&")") | BF6: New
A7: XL-005 | B7: 01 Basics & Cells | C7: Beginner | D7: 5 | E7: Claude knowledge | F7: Relative vs absolute references ($) | G7: Why does a copied formula sometimes point to the wrong cell, and what sign pins a cell in place? | H7: absolute = एब्सोल्यूट | relative = रिलेटिव | dollar sign = डॉलर साइन | I7: Core concept | J7: Very high | K7: 5 | L7: Excel moves references when you copy a formula, and the dollar sign was added so you can lock a part that must not move. | M7: Press F4 while the cursor is on a reference to cycle through A1, $A$1, A$1 and $A1 (on some laptops press Fn+F4). | N7: The dollar sign goes before the part to lock: $B$1 locks column and row, B$1 locks only the row. | O7: A dollar sign is a pin that nails the cell to the board, so the formula cannot slide it when you copy it. | P7: A cell with a gold pin pushed through it while other cell references slide downward with the copied formulas. | Q7: A moment of relief when a whole column of answers turns out right after one tiny dollar sign. | R7: A relative reference moves when copied; an absolute reference with dollar signs stays fixed. | S7: रिलेटिव = कॉपी करने पर बदलता है; एब्सोल्यूट ($) = जगह पर टिका रहता है | T7: A2: 200 A3: 300 B1: 0.1 (rate) C2: =A2*$B$1 C3: =A3*$B$1 | U7: C2 shows 20 and C3 shows 30 | V7: When C2 is copied down, A2 becomes A3 because it is relative. $B$1 stays B1 because both its column and row are locked. This lets every row use the same rate cell. | W7: Normal reference formula ke saath neeche khisakta hai. Dollar lagane se wo cell wahi rukta hai. Isliye rate wale cell par $ lagate hain. | X7: Like asking each student to check the person next to them (relative), but also asking everyone to look at one fixed notice board (absolute). | Y7: A1 (relative) | $A$1 (absolute) | A$1 or $A1 (mixed) | Z7: $ before the letter = lock the column | $ before the number = lock the row | no $ = free to move | AA7: A2: 200 A3: 300 C2: =A2*2 (copied to C3 it becomes =A3*2 and shows 600, relative) | AB7: A2: 200 A3: 300 B1: 0.1 C2: =A2*$B$1 (copied to C3 it stays $B$1 and shows 30, absolute) | AC7: A2: 2 A3: 3 B1: 4 C1: 5 B2: =$A2*B$1 (shows 8; copied to C3 it becomes =$A3*C$1 and shows 15, mixed) | AD7: F4 once makes $A$1, twice makes A$1, three times makes $A1, four times gives A1 again Named range, for example Rate, works like an absolute reference Copying a formula right changes the column letter; copying down changes the row number | AE7: AutoFill, SUM, VLOOKUP, percentage calculations | AF7: AutoFill, Named range, Mixed reference, F4 key | AG7: Named range, Excel Table structured references | AH7: relative, absolute, mixed, anchor, lock, F4 | AI7: Applying one tax or discount rate to a price list | Multiplication tables | Lookup tables that must not shift | AJ7: A: Only my first row is right after I drag the formula down; the rest show zero. | B: Your rate cell moved; press F4 to lock it as $B$1. | AK7: ✗ A copied formula always points to the same cells as the original → ✓ A normal reference shifts when copied; only the ones with $ stay fixed | AL7: B1 vs $B$1: B1 shifts when copied, $B$1 never shifts. | AM7: Do not copy a formula that uses a fixed rate cell without first adding the dollar signs. | AN7: B1: 10 A2: 200 A3: 300 C2: =A2*B1 C3 (copied) becomes =A3*B2 and shows 0 | AO7: B1: 10 A2: 200 A3: 300 C2: =A2*$B$1 C3 (copied) stays =A3*$B$1 and shows 3000 | AP7: Dollar = Done moving; no dollar means the cell can wander. | AQ7: A finance analyst applies one GST rate cell to hundreds of price rows using $ in the formula. | AR7: Interview question: What does $A$1 mean, and when would you use it instead of A1? | AS7: It is like fixing one price tag to a shelf so that it does not move while the other items change places. | AT7: C2 holds =A2*B1. You copy C2 down to C3. What does C3 contain? | AU7: A) =A3*B1 B) =A3*B2 C) =A2*B2 D) =A3*$B$1 | AV7: B | AW7: Without dollar signs both references move down by one row, so A2 becomes A3 and B1 becomes B2. | AX7: To lock both the column and row of B1 in a formula, write ____ → $B$1 | AY7: Price is in A2:A4 and the discount rate is in D1. Write the formula for C2 so it can be copied down. | AZ7: C2: =A2*$D$1 | BA7: Make a small price list and one tax cell, then copy a formula that uses the tax with a dollar sign. | BB7: A1: 5 B2: 10 B3: 20 C2: =B2*$A$1 You copy C2 to C3. What does C3 show? | BC7: 100 | BD7: =IF(K7="","",REPT("★",K7)&REPT("☆",5-K7)&" ("&K7&"/5)") | BE7: =IF(S7="","","Meaning: "&S7&" = ______ (Answer: "&F7&")") | BF7: New
A8: XL-006 | B8: 02 Basic Functions | C8: Beginner | D8: 6 | E8: Claude knowledge | F8: SUM and AutoSum | G8: Which function adds a block of numbers, and what shortcut types it for you? | H8: SUM = सम | AutoSum = ऑटो-सम | I8: Function | J8: Very high | K8: 5 | L8: Adding is the most common job in a spreadsheet, so Excel gives a ready-made function and a button for it. | M8: Select the cells below a column and press Alt+= on Windows to get the SUM written for you. | N8: Type =SUM( then select the range with the mouse and close the bracket; do not forget the equals sign. | O8: A shopkeeper tips all the coins from a tray into one pile, and the pile's weight is the SUM. | P8: A column of numbers with a bold total line under it, drawn as a green rectangle with the formula. | Q8: Confidence from seeing the correct total appear without a calculator. | R8: SUM adds all the numbers in the cells you give it. | S8: SUM = जोड़ना, सारी संख्याओं का कुल | T8: A1: 10 A2: 20 A3: 30 A4: =SUM(A1:A3) | U8: 60 | V8: SUM adds every number in the range. It ignores text and empty cells in the range. AutoSum, on the Home tab or with Alt+=, writes the SUM formula and guesses the range for you. | W8: SUM sab number jod deta hai. Text ya khali cell ho to use chhod deta hai. Alt+= dabane se Excel khud formula likh deta hai. | X8: Like emptying all small piles of money on a table into one big pile and counting that pile. | Y8: =SUM(number1, [number2], ...) | Z8: = starts a formula | SUM = function name | ( ) = brackets | A1:A3 = numbers to add | AA8: A1: 10 A2: 20 A3: 30 A4: =SUM(A1:A3) (shows 60, a simple range) | AB8: A1: 10 A2: 20 A3: 30 B1: =SUM(A1:A3,5) (shows 65, a range plus a typed number) | AC8: A1: 10 A2: n/a A3: 30 B1: =SUM(A1:A3) (shows 40, the text n/a is ignored) | AD8: =SUM(A:A) adds the whole column A Select A4 under the numbers and press Alt+= then Enter (Windows) for AutoSum Home tab > Editing group > AutoSum button (the sigma sign) does the same | AE8: AVERAGE, SUMIF, AutoSum, Alt+= | AF8: SUMIF, SUMIFS, AVERAGE, COUNT | AG8: Plus signs like =A1+A2+A3, the status bar total, SUMIF for conditions | AH8: SUM, SUMIF, SUMIFS, SUMPRODUCT, SUBTOTAL, AutoSum | AI8: Monthly expense totals | Marks totals | Sales reports | AJ8: A: How do I add the whole column quickly? | B: Click the empty cell below it and press Alt+=, then Enter. | AK8: ✗ SUM will turn text like "five" into 5 → ✓ SUM ignores text in a range, so type real numbers | AL8: SUM vs SUBTOTAL: SUM adds everything in the range, while SUBTOTAL can skip rows hidden by a filter. | AM8: Do not add a long column with plus signs when one SUM range can do it. | AN8: A1: 10 A2: 20 A3: 30 A4: SUM(A1:A3) | AO8: A1: 10 A2: 20 A3: 30 A4: =SUM(A1:A3) | AP8: SUM = Stack Up Many numbers. | AQ8: An accounts assistant totals daily sales in a month column with one SUM formula. | AR8: Interview question: How do you add a column of numbers quickly, and what does SUM do with text? | AS8: It is like adding up all the bills on a monthly grocery list. | AT8: A1 = 2, A2 holds the text '3 (typed with an apostrophe) and A3 = 4. What does =SUM(A1:A3) show? | AU8: A) 9 B) 6 C) #VALUE! D) 2 | AV8: B | AW8: SUM skips text inside a range, so only 2 and 4 are added; 9 would count the text as 3. | AX8: The Windows shortcut for AutoSum is Alt + ____ → = | AY8: Add the numbers in A1 to A2 and also B2 in one formula. | AZ8: C1: =SUM(A1:A2,B2) | BA8: Type five expenses in a column and use AutoSum to get the total. | BB8: A1: 12 A2: 8 B1: 5 B2: 15 C1: =SUM(A1:A2,B2) What does C1 show? | BC8: 35 | BD8: =IF(K8="","",REPT("★",K8)&REPT("☆",5-K8)&" ("&K8&"/5)") | BE8: =IF(S8="","","Meaning: "&S8&" = ______ (Answer: "&F8&")") | BF8: New
A9: XL-007 | B9: 02 Basic Functions | C9: Beginner | D9: 7 | E9: Claude knowledge | F9: AVERAGE, MIN and MAX | G9: Which three functions give the typical, smallest and biggest number of a list? | H9: AVERAGE = एवरेज | MIN = मिन | MAX = मैक्स | I9: Function | J9: Very high | K9: 5 | L9: These names come from the maths words average, minimum and maximum, which are needed in almost every report. | M9: Click the AutoSum drop-down arrow on the Home tab to pick Average, Min or Max without typing. | N9: Spell AVERAGE fully, because =AVG( is not an Excel function and gives a #NAME? error. | O9: Three friends stand in a line by height: the shortest is MIN, the tallest is MAX and the typical height is AVERAGE. | P9: A row of bars with the smallest in blue, the tallest in orange and a dotted line across the middle. | Q9: A sense of control when you can summarise a long list in three quick numbers. | R9: AVERAGE gives the mean, MIN the lowest and MAX the highest value. | S9: एवरेज = औसत, MIN = सबसे छोटा, MAX = सबसे बड़ा | T9: A1: 70 A2: 80 A3: 90 A4: 60 B1: =AVERAGE(A1:A4) B2: =MIN(A1:A4) B3: =MAX(A1:A4) | U9: B1 shows 75, B2 shows 60, B3 shows 90 | V9: AVERAGE adds the numbers and divides by how many numbers there are: (70+80+90+60)/4 = 75. MIN finds the lowest, which is 60, and MAX finds the highest, which is 90. All three ignore text and empty cells in a range. | W9: AVERAGE sab jodkar number ginti se bhaag deta hai. MIN sabse chhota aur MAX sabse bada number batata hai. Khali ya text cell ginti me nahi aate. | X9: Like checking a class: the shortest student, the tallest student and the typical height of all students. | Y9: =AVERAGE(range) | =MIN(range) | =MAX(range) | Z9: AVERAGE, MIN, MAX = function names | range = cells to look at | brackets = hold the range | AA9: A1: 70 A2: 80 A3: 90 A4: 60 B1: =AVERAGE(A1:A4) (shows 75, the mean) | AB9: A1: 70 A2: 80 A3: 90 B1: =MAX(A1:A3,100) (shows 100, a typed number joins the range) | AC9: A1: -5 A2: 3 A3: 0 B1: =MIN(A1:A3) (shows -5, negatives count too) | AD9: =AVERAGE(A1:A4) skips blank cells but counts zero =LARGE(A1:A4,2) gives the second biggest number Status bar at the bottom shows Average, Count and Sum for selected cells | AE9: SUM, COUNT, IF, LARGE, SMALL | AF9: MEDIAN, LARGE, SMALL, COUNT | AG9: MEDIAN, LARGE and SMALL, PivotTable summaries | AH9: AVERAGE, AVERAGEIF, MIN, MAX, MEDIAN, LARGE | AI9: Class marks analysis | Price comparison | Sales performance reports | AJ9: A: My class average looks too low, why? | B: Check whether absent students were typed as 0, because zero is counted but blank is not. | AK9: ✗ AVERAGE ignores zero values like blanks → ✓ AVERAGE counts a typed 0 as a number, but skips empty cells | AL9: AVERAGE vs MEDIAN: AVERAGE is the sum divided by the count, MEDIAN is the middle value when sorted. | AM9: Do not type 0 for missing marks if the average must skip them; leave the cell blank. | AN9: A1: 70 A2: 80 A3: 90 B1: =AVG(A1:A3) | AO9: A1: 70 A2: 80 A3: 90 B1: =AVERAGE(A1:A3) | AP9: MIN is little, MAX is big, AVERAGE is the middle ground. | AQ9: A teacher finds the highest, lowest and average score of a class test in three cells. | AR9: Interview question: What is the difference between AVERAGE and MEDIAN, and how does a zero affect AVERAGE? | AS9: It is like checking the cheapest, costliest and usual price of tomatoes in the market. | AT9: Cells A1, A2, A3 hold 50, 0 (typed zero) and 100. What does =AVERAGE(A1:A3) show? | AU9: A) 75 B) 50 C) 150 D) 0 | AV9: B | AW9: The zero counts as a value, so the total 150 is divided by 3 giving 50; 75 would ignore the zero. | AX9: The function that returns the biggest number in a range is ____ → MAX | AY9: Find the lowest mark in cells A1 to A5 using a formula. | AZ9: B1: =MIN(A1:A5) | BA9: Type six marks and write all three formulas, then check them with your eyes. | BB9: A1: 4 A2: 8 A3: (empty) A4: 12 B1: =AVERAGE(A1:A4) What does B1 show? | BC9: 8 | BD9: =IF(K9="","",REPT("★",K9)&REPT("☆",5-K9)&" ("&K9&"/5)") | BE9: =IF(S9="","","Meaning: "&S9&" = ______ (Answer: "&F9&")") | BF9: New
A10: XL-008 | B10: 02 Basic Functions | C10: Beginner | D10: 8 | E10: Claude knowledge | F10: COUNT, COUNTA and COUNTBLANK | G10: Which functions count only numbers, count every filled cell, or count the empty ones? | H10: COUNT = काउंट | COUNTA = काउंट-ए | COUNTBLANK = काउंट-ब्लैंक | I10: Function | J10: High | K10: 4 | L10: Lists often need to be counted, not added, so Excel gives separate counters for numbers, any entry and empty cells. | M10: Select a range and look at the status bar: Count there shows how many filled cells you picked. | N10: COUNTBLANK is one word with no space; COUNTA ends with a capital A that means All entries. | O10: A bus conductor counts tickets (COUNT numbers), every passenger (COUNTA) and the empty seats (COUNTBLANK). | P10: A bus with some seats filled by people with number tickets and some seats left empty and dotted. | Q10: A quiet satisfaction when attendance or form counts match. | R10: COUNT counts numbers, COUNTA counts any filled cell and COUNTBLANK counts empty cells. | S10: COUNT = सिर्फ़ संख्याएँ गिनो, COUNTA = भरे हुए सारे खाने, COUNTBLANK = खाली खाने | T10: A1: 10 A2: Asha A3: (empty) A4: 25 B1: =COUNT(A1:A4) B2: =COUNTA(A1:A4) B3: =COUNTBLANK(A1:A4) | U10: B1 shows 2, B2 shows 3, B3 shows 1 | V10: COUNT counts only numbers (10 and 25), so it gives 2. COUNTA counts every cell that holds something, here 10, Asha and 25, so it gives 3. COUNTBLANK counts the single empty cell A3, and it also counts cells that hold a formula returning empty text. | W10: COUNT sirf number ginta hai. COUNTA jo bhi likha ho wo sab ginta hai. COUNTBLANK khali khane ginta hai. | X10: Like counting only the ticket numbers, then every person on the bus, then the empty seats. | Y10: =COUNT(range) | =COUNTA(range) | =COUNTBLANK(range) | Z10: COUNT = numbers only | COUNTA = anything filled | COUNTBLANK = empty cells | range = where to look | AA10: A1: 10 A2: Asha A3: 25 B1: =COUNT(A1:A3) (shows 2, numbers only) | AB10: A1: Ravi A2: Sita A3: Amit B1: =COUNTA(A1:A3) (shows 3, names are counted) | AC10: B1: P B2: (empty) B3: P B4: (empty) C1: =COUNTBLANK(B1:B4) (shows 2, empty attendance rows) | AD10: =COUNTA(A:A)-1 counts the entries in a column after removing a header row =COUNTIF(A1:A10,"P") counts only cells equal to P =ROWS(A1:A10)-COUNTA(A1:A10) also gives the empty cells count | AE10: COUNTIF, SUM, IF, ISBLANK | AF10: COUNTIF, COUNTIFS, ISBLANK, ROWS | AG10: COUNTIF, status bar Count, PivotTable count | AH10: COUNT, COUNTA, COUNTBLANK, COUNTIF, COUNTIFS, ROWS | AI10: Attendance sheets | Survey responses | Checking missing data in a form | AJ10: A: I need to know how many students submitted their name. | B: Use COUNTA on the name column; COUNT would give zero since names are text. | AK10: ✗ COUNT counts every filled cell → ✓ COUNT counts only numbers; use COUNTA to count text and numbers together | AL10: COUNT vs COUNTA: COUNT counts numbers only, COUNTA counts any non-empty cell including text. | AM10: Do not use COUNT on a column of names, because it will return 0. | AN10: A1: Ravi A2: Sita A3: Amit B1: =COUNT(A1:A3) (expecting 3) | AO10: A1: Ravi A2: Sita A3: Amit B1: =COUNTA(A1:A3) | AP10: A in COUNTA = All entries; COUNT alone = numbers only. | AQ10: A coordinator counts how many feedback forms are still blank using COUNTBLANK. | AR10: Interview question: What is the difference between COUNT and COUNTA, and how do you count empty cells? | AS10: It is like counting how many seats on a train are taken and how many are still free. | AT10: A1 = 5, A2 = Amit, A3 is empty and A4 = 9. What does =COUNT(A1:A4) return? | AU10: A) 4 B) 3 C) 2 D) 1 | AV10: C | AW10: COUNT counts only numbers, so 5 and 9 give 2; 3 would be COUNTA, which also counts the name. | AX10: The function that counts empty cells in a range is ____ → COUNTBLANK | AY10: Count how many cells from A1 to A10 contain anything at all. | AZ10: B1: =COUNTA(A1:A10) | BA10: Make a short list with a name, a number and a blank cell, and write all three counting formulas. | BB10: A1: 7 A2: hello A3: (empty) A4: 3 A5: (empty) B1: =COUNTA(A1:A5)-COUNT(A1:A5) What does B1 show? | BC10: 1 | BD10: =IF(K10="","",REPT("★",K10)&REPT("☆",5-K10)&" ("&K10&"/5)") | BE10: =IF(S10="","","Meaning: "&S10&" = ______ (Answer: "&F10&")") | BF10: New
A11: XL-009 | B11: 02 Basic Functions | C11: Beginner | D11: 9 | E11: Claude knowledge | F11: ROUND, ROUNDUP and ROUNDDOWN | G11: Which three functions change a number to fewer digits, rounding normally, always up or always down? | H11: ROUND = राउंड | ROUNDUP = राउंड-अप | ROUNDDOWN = राउंड-डाउन | I11: Function | J11: High | K11: 4 | L11: Calculations such as tax or interest give long decimals, so Excel offers functions that cut them to the digits you need. | M11: A negative digits value, like -2, rounds to the left of the decimal point, to hundreds. | N11: The second argument counts digits after the decimal point; ROUND(7.456,2) needs the comma and the 2. | O11: A lift stops at a floor: ROUND goes to the nearest floor, ROUNDUP always goes up and ROUNDDOWN always goes down. | P11: A glass lift in a tall building with three buttons, an up arrow, a down arrow and a middle button. | Q11: Tidy satisfaction when long decimals become clean amounts. | R11: These functions change the stored value to a chosen number of digits. | S11: ROUND = पास की पूर्ण संख्या पर, ROUNDUP = हमेशा ऊपर, ROUNDDOWN = हमेशा नीचे | T11: A1: 7.456 B1: =ROUND(A1,2) B2: =ROUNDUP(A1,2) B3: =ROUNDDOWN(A1,2) | U11: B1 shows 7.46, B2 shows 7.46, B3 shows 7.45 | V11: ROUND looks at the next digit, 6, and rounds up to 7.46. ROUNDUP always moves away from zero, so it also gives 7.46. ROUNDDOWN always cuts toward zero, so it gives 7.45. The second number is how many decimal places to keep. | W11: ROUND paas wali value par le jata hai. ROUNDUP hamesha upar le jata hai aur ROUNDDOWN hamesha neeche. Doosra number batata hai kitne decimal rakhne hain. | X11: Like deciding the bus fare: round to the nearest rupee, always charge up, or always drop the paise. | Y11: =ROUND(number, num_digits) | Z11: number = value or cell | num_digits = decimals to keep | negative digits = round tens, hundreds | AA11: A1: 2.5 B1: =ROUND(A1,0) (shows 3, a half rounds away from zero) | AB11: A1: 1234 B1: =ROUND(A1,-2) (shows 1200, a negative digits value rounds to hundreds) | AC11: A1: 9.99 B1: =ROUNDDOWN(A1,0) (shows 9, the decimals are cut off) | AD11: =ROUNDUP(4.01,0) gives 5 =ROUNDDOWN(-3.7,0) gives -3 because it moves toward zero =INT(7.9) gives 7 and always goes to the lower whole number | AE11: SUM, IF, percentage formulas, currency | AF11: INT, TRUNC, CEILING, FLOOR | AG11: INT, TRUNC, Number format with fewer decimals, MROUND | AH11: ROUND, ROUNDUP, ROUNDDOWN, INT, TRUNC, MROUND | AI11: Bills and invoices | Tax and interest calculations | Marks converted to whole numbers | AJ11: A: I formatted the cell to two decimals, but my total is off by a paisa. | B: Formatting only changes the display; use ROUND to change the actual value. | AK11: ✗ Formatting a cell to 2 decimals also rounds the stored number → ✓ Format only changes how it looks; ROUND changes the stored value | AL11: ROUNDDOWN vs INT: for negative numbers ROUNDDOWN moves toward zero, while INT moves to the lower whole number. | AM11: Do not rely on cell formatting when the rounded value must be used in later formulas. | AN11: A1: 7.456 B1: =ROUND(A1) (expecting 7.46) | AO11: A1: 7.456 B1: =ROUND(A1,2) | AP11: ROUND is Regular, UP is Upwards always, DOWN is Down always. | AQ11: A billing clerk rounds each line item to two decimals so that the invoice total matches the bank amount. | AR11: Interview question: What is the difference between formatting to two decimals and using ROUND? | AS11: It is like a shopkeeper rounding the bill to the nearest rupee when no small change is available. | AT11: What does the formula =ROUNDDOWN(-3.7,0) return? | AU11: A) -4 B) -3 C) -3.7 D) 0 | AV11: B | AW11: ROUNDDOWN moves toward zero, so -3.7 becomes -3; -4 would be ROUNDUP, which moves away from zero. | AX11: =ROUND(1234,-2) gives ____ → 1200 | AY11: Round the number in A1 to one decimal place and always upwards. | AZ11: B1: =ROUNDUP(A1,1) | BA11: Take the number 5.678 and write ROUND, ROUNDUP and ROUNDDOWN to two decimals. | BB11: A1: 15.249 B1: =ROUNDUP(A1,1) What does B1 show? | BC11: 15.3 | BD11: =IF(K11="","",REPT("★",K11)&REPT("☆",5-K11)&" ("&K11&"/5)") | BE11: =IF(S11="","","Meaning: "&S11&" = ______ (Answer: "&F11&")") | BF11: New
A12: XL-010 | B12: 03 Formatting & Organising | C12: Beginner | D12: 10 | E12: Claude knowledge | F12: Number formats (currency, date, percent) | G12: How can the same stored value appear as money, as a percentage or as a calendar date? | H12: format = फ़ॉर्मेट | currency = करेंसी | percent = परसेंट | I12: Excel feature | J12: Very high | K12: 5 | L12: Excel stores one plain value, and number formats were added so the same value can be shown in a readable style. | M12: Press Ctrl+1 to open Format Cells with all the number formats and decimal options in one place. | N12: On Windows, Ctrl+Shift+4 is currency, Ctrl+Shift+5 is percent and Ctrl+Shift+3 is date; the symbol depends on your region. | O12: A cell wears a costume: the same value 0.25 can go to the party as 25%, and 1234.5 puts on a rupee or dollar sign. | P12: One plain number in the middle with three outfits beside it labelled money, percent and date. | Q12: Pride when a plain sheet suddenly looks like a professional report. | R12: A number format changes how a value looks without changing the value itself. | S12: नंबर फ़ॉर्मेट = वही संख्या अलग रूप में दिखाना (पैसा, प्रतिशत, तारीख) | T12: A1: 0.25 Select A1, press Ctrl+Shift+5 (Home tab > Number group > %) | U12: A1 shows 25% | V12: The number format changes only the display. The stored value of A1 is still 0.25, and Percentage format multiplies it by 100 for display and adds the % sign. Dates are stored as serial numbers, so Date format turns 45292 into a calendar date. | W12: Number format sirf dikhane ka tareeka badalta hai, asli value wahi rehti hai. 0.25 ko percent format dene par 25% dikhta hai. Date bhi asal me ek number hai jise date jaisa dikhaya jata hai. | X12: Like a person who stays the same but wears different clothes for office, a wedding or a gym. | Y12: Ctrl+1 > Number tab > choose Category (Currency, Percentage, Date) | Z12: Category = type of format | Decimal places = digits shown | Symbol = currency sign | AA12: A1: 1234.5 Select A1, press Ctrl+Shift+4 (shows $1,234.50 with US English settings, a currency format) | AB12: A1: 0.25 Select A1, press Ctrl+Shift+5 (shows 25%, a percent format) | AC12: A1: 45292 Select A1, press Ctrl+Shift+3 (shows 1-Jan-24 with US English settings, a date format) | AD12: Ctrl+1 > Currency lets you choose the symbol such as the rupee Home tab > Increase Decimal or Decrease Decimal changes the digits shown Typing 25% directly in an empty cell stores 0.25 with Percentage format | AE12: ROUND, TEXT, Format Cells, Home tab | AF12: Format Cells, ROUND, TEXT function, Date serial number | AG12: TEXT function, Accounting format, Custom number formats | AH12: General, Number, Currency, Accounting, Percentage, Date | AI12: Invoices and price lists | Growth and discount percentages | Date columns in schedules | AJ12: A: I typed 0.5 but I want to show 50%. Should I type 50 instead? | B: No, keep 0.5 and apply the Percentage format. | AK12: ✗ Applying the Percentage format to 5 changes it into 5% → ✓ It shows 500%, because the format multiplies the stored value by 100 | AL12: Number format vs ROUND: a format changes only how the value looks, ROUND changes the stored value. | AM12: Do not type the currency symbol by hand when a Currency format can add it for you. | AN12: A1: 5 Select A1 and apply Percentage format (expecting 5%) | AO12: A1: 0.05 Select A1 and press Ctrl+Shift+5 (shows 5%) | AP12: Shift+4 is the dollar key, Shift+5 is the percent key. | AQ12: A finance assistant formats a price column as currency and a growth column as percent before sending a report. | AR12: Interview question: If you format 0.25 as a percentage, what is stored in the cell? | AS12: It is like the same weight shown in kilograms on one scale and in grams on another. | AT12: You type 25% directly into an empty cell. What value does Excel store in that cell? | AU12: A) 25 B) 0.25 C) 2.5 D) 0.025 | AV12: B | AW12: Excel stores a percent as a fraction of 1, so 25% is 0.25; the % sign is only how it is displayed. | AX12: The Windows shortcut to apply Percentage format is Ctrl+Shift+____ → 5 | AY12: Make the number 1234.5 in cell A1 appear as currency with two decimals. | AZ12: Select A1 and press Ctrl+Shift+4 | BA12: Type 0.18 and show it as a percent, then type a big number and show it as currency. | BB12: A1: 0.07 Select A1 and press Ctrl+Shift+5. What does A1 show? | BC12: 7% | BD12: =IF(K12="","",REPT("★",K12)&REPT("☆",5-K12)&" ("&K12&"/5)") | BE12: =IF(S12="","","Meaning: "&S12&" = ______ (Answer: "&F12&")") | BF12: New
A13: XL-011 | B13: 03 Formatting & Organising | C13: Beginner | D13: 11 | E13: Claude knowledge | F13: Sort | G13: Which Excel feature puts rows in order, such as A to Z or smallest to largest, without retyping anything? | H13: Sort = सॉर्ट (sort) | I13: Data tab feature | J13: Very high | K13: 5 | L13: The word sort means to arrange things in order; Excel has had a Sort button on the Data tab for many versions to reorder rows by one or more columns. | M13: Click one cell inside your table before sorting so Excel picks the whole table, and rows stay together. | N13: No typing needed. Click one cell in the column, then Data tab > Sort A to Z or Sort Z to A. | O13: A teacher lines up students by height for a photo: the tallest goes first and every student keeps their own bag with them. | P13: A long line of school children standing from shortest to tallest, each holding their own bag. | Q13: The calm feeling of a messy list turning neat in one click. | R13: Sort rearranges the rows of a table in order based on the values in one or more columns. | S13: डेटा को क्रम में लगाना (A से Z या छोटे से बड़े) | T13: A1: Name B1: Marks A2: Ravi B2: 72 A3: Asha B3: 90 A4: Meena B4: 65 Steps: click B2 > Data tab > Sort Largest to Smallest | U13: Rows become: Asha 90, Ravi 72, Meena 65 (each name stays with its own marks) | V13: Sort reorders whole rows, not just the column you clicked, as long as Excel sees your data as one table. The header row stays on top when Excel detects headers. You can sort text A to Z, numbers small to large, or dates old to new. | W13: Sort ka matlab hai list ko order me lagana. Ek cell par click karo, Data tab me Sort dabao, aur poori row apne data ke saath move hoti hai. | X13: Like arranging books on a shelf by their title: every book moves to a new spot, but each book stays in one piece. | Y13: Data tab > Sort A to Z / Sort Z to A, or Data tab > Sort for the full dialog | Z13: Data tab = where the buttons live | Sort A to Z = smallest or alphabetical first | Sort Z to A = largest or reverse alphabetical first | Sort dialog = choose column, order and extra levels | AA13: A1: Name A2: Ravi A3: Asha A4: Meena Steps: click A2 > Data tab > Sort A to Z Result: Asha, Meena, Ravi | AB13: A1: Class, B1: Marks (class A and B mixed) Steps: Data tab > Sort > Sort by Class (A to Z) > Add Level > Then by Marks (Largest to Smallest) > OK Result: classes grouped, and highest marks first inside each class | AC13: Select only column B (Marks) and click Sort Smallest to Largest Excel asks: Expand the selection or Continue with the current selection Choose Expand the selection so names move with the marks | AD13: Data tab > Sort > Add Level (sort by two columns) Data tab > Sort > My data has headers (tick when row 1 is headings) Data tab > Sort > Order: Custom List... (for Low, Medium, High) | AE13: Filter, Excel Tables, Freeze Panes, Conditional Formatting | AF13: Filter, SORT function, Custom Lists, Excel Tables | AG13: SORT function (Microsoft 365 or Excel 2021 or later), Filter button drop-down sort options | AH13: Sort, Filter, Group, Rank, Order | AI13: Ranking students by marks | Arranging a customer list A to Z | Putting dates in order before a report | AJ13: A: My marks list is all mixed up and I need the topper first. | B: Click any cell in the Marks column, then use Data tab > Sort Largest to Smallest. | AK13: ✗ Sorting one column changes only that column's order → ✓ If you select only one column and choose Continue with the current selection, the other columns do not move and the rows no longer match; pick Expand the selection | AL13: Sort vs Filter: Sort changes the order of all rows, while Filter only hides rows that do not match and keeps the order. | AM13: Do not select a single column in the middle of a table and sort it alone, because the rows will no longer match. | AN13: Select only B2:B4 > Data tab > Sort Smallest to Largest > Continue with the current selection | AO13: Click one cell inside the table (for example B2) > Data tab > Sort Smallest to Largest (or choose Expand the selection) | AP13: Sort = Same rows Stay together, they only change order. | AQ13: A teacher sorts the class result sheet by total marks so the top ten students are at the top of the report. | AR13: Interviewer asks: How do you sort a table by two columns, such as Department and then Salary? | AS13: Arranging contacts in your phone by name so you can find a friend quickly. | AT13: You select only column B (Marks) in a Name and Marks table and sort it, choosing Continue with the current selection. What happens to the names in column A? | AU13: A) They move together with the marks B) They stay where they were, so names no longer match marks C) They are sorted A to Z as well D) Excel deletes them | AV13: B | AW13: Continue with the current selection sorts only the selected cells, so column A is untouched and the rows no longer match. | AX13: To keep names with their marks, choose ____ the selection when Excel asks → Expand | AY13: Make a small list of three items with prices and put it in order from the lowest price to the highest. | AZ13: A1: Item B1: Price A2: Pen B2: 20 A3: Book B3: 50 A4: Ink B4: 5 Steps: click B2 > Data tab > Sort Smallest to Largest Result: Ink 5, Pen 20, Book 50 | BA13: Write down five of your own expenses in two columns and sort them from the biggest amount to the smallest. | BB13: A1: Item, B1: Price. A2: Pen 20, A3: Book 50, A4: Ink 5. You click B2 and use Data tab > Sort Smallest to Largest. In what order do the items appear from row 2 to row 4? | BC13: Ink, Pen, Book (prices 5, 20, 50) | BD13: =IF(K13="","",REPT("★",K13)&REPT("☆",5-K13)&" ("&K13&"/5)") | BE13: =IF(S13="","","Meaning: "&S13&" = ______ (Answer: "&F13&")") | BF13: New
A14: XL-012 | B14: 03 Formatting & Organising | C14: Beginner | D14: 12 | E14: Claude knowledge | F14: Filter | G14: Which Excel feature lets you show only the rows you want, such as one city, while the other rows stay safe but out of sight? | H14: Filter = फ़िल्टर (filter) | I14: Data tab feature | J14: Very high | K14: 5 | L14: A filter lets some things pass and blocks others; Excel borrowed the word for AutoFilter, which adds small drop-down arrows to the header row. | M14: Press Ctrl+Shift+L to turn filter arrows on or off quickly on Windows Excel. | N14: Click a cell in your table, then press Ctrl+Shift+L. Do not select a blank row first. | O14: A tea strainer lets only the liquid through and keeps the leaves aside, but the leaves are still in the strainer, not thrown away. | P14: A tea strainer over a cup, with tea leaves resting in it and clear tea dripping through. | Q14: Relief when a huge sheet shrinks to just the rows you care about. | R14: Filter hides the rows that do not match your condition and shows only the rows that do. | S14: सिर्फ़ ज़रूरी पंक्तियाँ दिखाना, बाकी छिपाना | T14: A1: Name B1: City A2: Asha B2: Delhi A3: Ravi B3: Pune A4: Meena B4: Delhi Steps: click A1 > Ctrl+Shift+L > click arrow in B1 > untick Select All > tick Delhi > OK | U14: Only Asha and Meena rows are visible; row 3 (Ravi) is hidden, not deleted, and the row numbers on the left skip from 2 to 4 | V14: Filter adds a drop-down arrow to each header cell. When you pick values, Excel hides every row that does not match. The hidden rows are still in the sheet and come back when you clear the filter. | W14: Filter se aap sirf wahi rows dekhte ho jo aapko chahiye. Baaki rows delete nahi hoti, bas chhup jaati hain, aur filter hatane par wapas aa jaati hain. | X14: Like a shop website's filter for Size: M, which hides other sizes but does not remove them from the shop. | Y14: Data tab > Filter (or Ctrl+Shift+L), then use the arrow in a header cell | Z14: Header arrow = opens the filter menu | Tick boxes = choose which values to show | Text Filters / Number Filters = conditions such as contains or greater than | Clear = removes the filter | AA14: Text filter: click arrow in City > tick only Delhi > OK Result: only rows where City is Delhi are shown | AB14: Number filter: A1: Item, B1: Qty. A2: Pen 10, A3: Book 3, A4: Ink 7 Click arrow in Qty > Number Filters > Greater Than > 5 > OK Result: Pen and Ink rows are shown | AC14: Remove the filter: Data tab > Clear (to show all rows again) or press Ctrl+Shift+L to switch the arrows off Result: all rows are visible again | AD14: Text Filters > Contains... (names that include some letters) Number Filters > Top 10... (largest values) Filter by Color (cell colour or font colour) | AE14: Sort, Excel Tables, Conditional Formatting, Freeze Panes | AF14: Sort, Advanced Filter, FILTER function, Slicers | AG14: FILTER function (Microsoft 365 or Excel 2021 or later), Advanced Filter, PivotTable | AH14: Filter, AutoFilter, Slicer, Search box, Clear | AI14: Looking at one city or one month of sales | Finding all unpaid fees in a list | Checking only the rows that need follow-up | AJ14: A: I only want to see the students from class 10, but the sheet has 500 rows. | B: Press Ctrl+Shift+L, click the arrow on the Class column and tick only 10. | AK14: ✗ Filter deletes the rows that do not match → ✓ Filter only hides them; they come back when you clear the filter, so your data is safe | AL14: Filter vs Sort: Filter hides rows that do not match, while Sort keeps every row and only changes their order. | AM14: Do not copy numbers from a filtered sheet and assume hidden rows are included; check what was visible before you total or send it. | AN14: Select row 3 (Ravi) > right-click > Delete to remove people who are not in Delhi | AO14: Click A1 > Ctrl+Shift+L > click arrow in City > tick only Delhi > OK | AP14: Filter = Few rows Visible, rest Hidden (not gone). | AQ14: A shop owner filters the sales sheet to one product and one month to prepare a short report. | AR14: Interviewer asks: What is the difference between hiding rows with Filter and deleting them? | AS14: Using the Show only vegetarian option on a food app to see fewer dishes. | AT14: After you filter a City column to show only Delhi, where do the Pune rows go? | AU14: A) They are permanently deleted B) They are moved to a new sheet C) They are hidden but still in the sheet D) They are changed to Delhi | AV14: C | AW14: Filter only hides non-matching rows; the row numbers skip, and clearing the filter brings them back. | AX14: The keyboard shortcut to turn filter arrows on or off is ____ → Ctrl+Shift+L | AY14: Show only the items that have a quantity greater than 5 from a small three-row list. | AZ14: A1: Item B1: Qty A2: Pen B2: 10 A3: Book B3: 3 A4: Ink B4: 7 Steps: click A1 > Ctrl+Shift+L > arrow in B1 > Number Filters > Greater Than > 5 > OK Result: Pen and Ink are visible | BA14: Make a list of ten of your friends with their cities and filter it to show only one city. | BB14: A1: Item, B1: Qty. A2: Pen 10, A3: Book 3, A4: Ink 7. You apply Number Filters > Greater Than > 5 on Qty. Which items stay visible? | BC14: Pen and Ink (Book is hidden) | BD14: =IF(K14="","",REPT("★",K14)&REPT("☆",5-K14)&" ("&K14&"/5)") | BE14: =IF(S14="","","Meaning: "&S14&" = ______ (Answer: "&F14&")") | BF14: New
