Workbook

Sheet Read Me
A1: Cloud Basics – Beginner to Advanced Flashcards
A2: Subject: Cloud computing (AWS first, Azure and GCP mapped) · Learner: Self learner, English · Cards: 50
A3: Source: Claude knowledge
A5: How to study a card
A6: 1. Read Side 1 only. Try to say the meaning, answer or formula out loud before looking further.
A7: 2. Check yourself against Side 2. Read the examples and the common mistake.
A8: 3. Do the practice on Side 3 without looking back. Then mark Status: New → Learning → Known.
A9: 4. Review on days 1, 3, 7, 15, 30, 60 after first study: write the date or ✓ in that day's column.
A10: Got it wrong on a review? Start that card's days again from Day 1.
A11: 5. Follow 'Study order': prerequisites come first, then easy to hard.
A13: Colours
A14: Shaded cells were added by Claude, not taken from your own book or notes. Check them against a trusted source,
A15: and mark the card 'Fix' in the OK / Fix column if anything is wrong. Unshaded cells came from your source.

Sheet Topic (56-pt) cards
A1: Card | F1: Side 1 · Recognition | P1: Side 2 · Understanding | AJ1: Side 3 · Real life & Practice | AR1: Auto | AT1: My review
A2: ID | B2: Topic | C2: Level | D2: Study order | E2: Source | F2: Term / topic | G2: Recall cue | H2: Category | I2: How often used | J2: Importance (1-5) | K2: Origin / why it exists | L2: Pro tip | M2: Memory story | N2: Picture it | O2: Emotion hook | P2: Definition (simple) | Q2: Meaning in learner's language | R2: How / why it works | S2: Simple explanation (Hinglish) | T2: Real-life analogy | U2: Formula / rule | V2: Example 1 | W2: Example 2 | X2: Example 3 | Y2: Related concepts | Z2: Family / group | AA2: Where it is used | AB2: Mini conversation | AC2: Common mistake | AD2: Don't confuse with | AE2: Avoid / don't | AF2: Memory trick | AG2: Real life: project / work | AH2: Real life: interview / exam | AI2: Real life: daily life | AJ2: MCQ question | AK2: MCQ options | AL2: MCQ answer | AM2: Why that answer | AN2: Fill the blank | AO2: Apply it | AP2: Explain it yourself | AQ2: Write your own | AR2: Importance ★ | AS2: Quick recall (reverse) | AT2: Status | AU2: Day 1 | AV2: Day 3 | AW2: Day 7 | AX2: Day 15 | AY2: Day 30 | AZ2: Day 60 | BA2: OK / Fix | BB2: My note
A3: CLD-001 | B3: 01 Basics | C3: Beginner | D3: 1 | E3: Claude knowledge | F3: IaaS, PaaS and SaaS | G3: Which three service models differ in how much of the stack you manage yourself? | H3: Core concept | I3: Very high | J3: 5 | K3: Companies wanted to rent computing instead of buying it, and providers offered it at different levels of finished product, from raw servers to complete applications. | L3: Ask who patches the operating system. That one question tells you which model you are in. | M3: IaaS is renting an empty kitchen, PaaS is renting a kitchen with a chef's tools set up, and SaaS is ordering the finished meal. | N3: A layered stack where the shaded part you manage shrinks from IaaS to SaaS. | O3: The relief of handing the boring maintenance to someone else. | P3: IaaS rents virtual infrastructure such as servers and networks, PaaS rents a platform for running your code without managing servers, and SaaS delivers a finished application over the internet. | R3: With IaaS, such as AWS EC2, you manage the operating system and everything above it. With PaaS, such as Elastic Beanstalk, App Service or App Engine, you deploy code and the provider runs the servers. With SaaS, such as Gmail or Salesforce, you only use the product. The more the provider manages, the less control and the less work you have. | S3: IaaS gives you servers, PaaS gives you a place to run code, SaaS gives you the finished app. Each step hands more work to the provider. | T3: IaaS is an empty rented kitchen, PaaS is a kitchen with tools ready, and SaaS is a meal delivered to your table. | U3: More provider management = less control for you, and less work for you. | V3: Launching an EC2 virtual machine and installing your own web server on it. | W3: Deploying a Python app to a platform service that handles servers for you. | X3: Using a hosted email service through a web browser. | Y3: cloud vs on-premises, shared responsibility, virtual machines | Z3: infrastructure, platform, software, service, managed | AA3: Choosing hosting | Planning budgets | Customer architecture talks | AB3: A: Do we patch the operating system ourselves? | B: Only if we pick IaaS. A platform service patches it for us. | AC3: ✗ SaaS and PaaS are the same because both are managed → ✓ PaaS runs your code, while SaaS is a finished product you simply use | AD3: IaaS vs PaaS: with IaaS you manage the operating system, with PaaS you only manage your code and data. | AE3: Do not choose IaaS only for control if nobody on the team wants to patch servers. | AF3: Infrastructure, platform, software, each hands over more. | AG3: Moving a customer script from a rented server to a managed platform to avoid patching work. | AH3: An interviewer may ask: What is the difference between IaaS, PaaS and SaaS? | AI3: It is like cooking in a rented kitchen versus ordering delivery. | AJ3: Which model leaves you managing the operating system? | AK3: A) SaaS B) None of them C) IaaS D) PaaS | AL3: C | AM3: IaaS gives you virtual hardware, so everything above it is yours. | AN3: With ____ you only use the finished product through a browser → SaaS | AO3: A team wants to run code without managing any servers. Which model fits? → PaaS | AP3: Explain the three service models in three lines. | AQ3: Name one product you use that is SaaS and one service that is IaaS. | AR3: =IF(J3="","",REPT("★",J3)&REPT("☆",5-J3)&" ("&J3&"/5)") | AS3: =IF(Q3="","","Meaning: "&Q3&" = ______ (Answer: "&F3&")") | AT3: New
A4: CLD-002 | B4: 01 Basics | C4: Beginner | D4: 2 | E4: Claude knowledge | F4: Regions and availability zones | G4: Which two ideas describe where in the world your cloud resources physically run, and how they survive a failure? | H4: Core concept | I4: Very high | J4: 5 | K4: One data centre can fail or be far from users, so providers built groups of separate data centres in many parts of the world. | L4: Spread important services over at least two availability zones in one region. | M4: A region is a city, and availability zones are separate buildings in that city with their own power. | N4: A map with a region circle and three separate buildings inside it. | O4: The comfort of knowing one building failing will not stop your app. | P4: A region is a geographic area containing several availability zones, and an availability zone is one or more isolated data centres with independent power and networking. | R4: Resources are created in a chosen region, such as ap-south-1 in Mumbai. Zones inside a region are connected with fast links, so you can run copies of a service in several zones. Data does not leave a region unless you move it. Azure calls them regions and availability zones, and GCP calls them regions and zones. Not every service exists in every region. | S4: Pick a region close to your users and rules, and spread copies across zones inside it for resilience. | T4: A region is a city, and zones are separate buildings with their own power supply. | U4: Region = location. Zone = isolated data centre inside it. | V4: Running a web server in two zones of Mumbai so one can fail safely. | W4: Storing customer data only in a region that meets local law. | X4: Choosing a nearby region to reduce latency for users. | Y4: disaster recovery, latency, data residency, load balancers | Z4: region, zone, data centre, latency, resilience | AA4: Architecture design | Compliance | Cost and speed decisions | AB4: A: If one data centre burns down, are we down? | B: Not if we run in two zones. | AC4: ✗ Data automatically copies to every region → ✓ Data stays in the chosen region unless you set up replication | AD4: Region vs zone: a region is a whole area, a zone is one isolated location inside it. | AE4: Do not put every copy of a critical service in a single zone. | AF4: Regions are cities, zones are buildings inside. | AG4: Placing a customer database in a regional location to meet their data residency rule. | AH4: An interviewer may ask: How do you make an application survive a data centre failure? | AI4: It is like keeping backups in separate buildings of one city. | AJ4: What is an availability zone? | AK4: A) An isolated data centre inside a region B) A billing plan C) A country's border D) A type of server | AL4: A | AM4: Zones have independent power and networking inside one region. | AN4: Data stays in one region unless you configure ____ → replication | AO4: You want a service to survive one building failing. What do you spread across? → Availability zones | AP4: Explain regions and zones to a customer in three lines. | AQ4: Find the region closest to you and note two services it offers. | AR4: =IF(J4="","",REPT("★",J4)&REPT("☆",5-J4)&" ("&J4&"/5)") | AS4: =IF(Q4="","","Meaning: "&Q4&" = ______ (Answer: "&F4&")") | AT4: New
A5: CLD-003 | B5: 01 Basics | C5: Beginner | D5: 3 | E5: Claude knowledge | F5: Shared responsibility model | G5: Which model says what the provider secures and what you must secure? | H5: Core concept | I5: Very high | J5: 5 | K5: Customers kept assuming the cloud was secured entirely by the provider, so providers published a clear split of duties. | L5: The provider secures the cloud itself, and you secure what you put in it. | M5: The landlord secures the building, and you lock your own apartment door. | N5: A line dividing provider duties at the bottom from customer duties at the top. | O5: The sobering clarity of knowing which part is yours. | P5: The shared responsibility model divides security duties, so the provider secures the underlying infrastructure and the customer secures their data, access and configuration. | R5: The provider handles buildings, hardware and the virtualisation layer. You handle identity and access, data, encryption choices, network rules and, with IaaS, the operating system. Many cloud breaches come from customer misconfiguration, such as a public storage bucket or an exposed key. The line moves up as you use more managed services. | S5: The provider protects the cloud, and you protect what you place in it and how you configure it. | T5: The landlord secures the building, and you lock your own door. | U5: Provider = security of the cloud. Customer = security in the cloud. | V5: A provider securing the data centre while you set the storage permissions. | W5: A leaked access key causing a breach, which is the customer's duty. | X5: A managed database where the provider patches the engine but you control who can connect. | Y5: IAM, least privilege, encryption, secrets | Z5: responsibility, security, configuration, compliance, provider | AA5: Security reviews | Customer questions | Audits | AB5: A: Is our data safe because we are on AWS? | B: Only if we set permissions and encryption correctly. | AC5: ✗ The cloud provider secures everything, including my settings → ✓ You remain responsible for access, data and configuration | AD5: Security of the cloud vs security in the cloud: the first is the provider's job, the second is yours. | AE5: Do not assume a default setting is safe without checking it. | AF5: Provider secures the cloud, you secure contents. | AG5: Fixing a public bucket found in a review, which was a customer-side mistake. | AH5: An interviewer may ask: Who is responsible when a storage bucket is left public? | AI5: It is like the landlord securing the building while you lock your door. | AJ5: Who is responsible for who can access your stored data? | AK5: A) The internet B) The provider only C) No one D) The customer | AL5: D | AM5: Access configuration is on the customer's side of the line. | AN5: The provider secures the cloud, and you secure what is ____ it → in | AO5: A public bucket leaks data. Whose duty was it to prevent it? → The customer's | AP5: Explain the shared responsibility model in three lines. | AQ5: List three things you must secure even on a managed database. | AR5: =IF(J5="","",REPT("★",J5)&REPT("☆",5-J5)&" ("&J5&"/5)") | AS5: =IF(Q5="","","Meaning: "&Q5&" = ______ (Answer: "&F5&")") | AT5: New
A6: CLD-004 | B6: 01 Basics | C6: Beginner | D6: 4 | E6: Claude knowledge | F6: Pay-as-you-go pricing | G6: Which pricing idea means you pay for what you use rather than buying equipment upfront? | H6: Core concept | I6: High | J6: 4 | K6: Buying servers meant a large upfront cost and unused capacity, so clouds introduced metered billing by the hour or second. | L6: Turn off or delete what you are not using, because idle resources keep billing. | M6: Pay-as-you-go is a taxi meter, and buying servers is buying a car. | N6: A meter ticking next to a running server icon. | O6: The freedom of paying only for what you need. | P6: Pay-as-you-go pricing charges for the resources and time you actually use, with options to commit for a lower price. | R6: Compute is often billed per second, storage per gigabyte per month, and data leaving the cloud per gigabyte. Savings plans or reserved capacity give a discount for committing. Spot capacity is cheaper but can be taken back. Free tiers have limits and expire. Forgotten resources are the most common surprise on a bill. | S6: You are billed for usage, so stop what you do not need and set budget alerts. | T6: It is like a taxi meter instead of buying a car. | U6: Cost = quantity used × price per unit × time. | V6: A test server that costs money only while it is switched on. | W6: A stored backup billed per gigabyte per month. | X6: A discount for committing to steady usage for a year. | Y6: cost alerts, tagging, spot instances, cleanup | Z6: metered, billing, reserved, spot, commitment | AA6: Budget planning | Cost reviews | Customer estimates | AB6: A: Why is the bill high? | B: A forgotten test server ran all month. | AC6: ✗ If I stop using a service it stops costing money → ✓ Resources keep billing until you stop or delete them | AD6: On-demand vs reserved: on-demand has no commitment, reserved is cheaper for steady use. | AE6: Do not leave test resources running after a demo. | AF6: Idle resources still ring the meter. | AG6: Deleting forgotten test resources after a bill alert and saving the monthly budget. | AH6: An interviewer may ask: How do you control cloud cost? | AI6: It is like a taxi meter that runs until you get out. | AJ6: Which is most likely to cause a surprise bill? | AK6: A) A tag B) A forgotten running resource C) A budget alert D) A free tier limit | AL6: B | AM6: Unused resources keep accumulating charges. | AN6: Capacity that can be taken back at short notice is called ____ capacity → spot | AO6: A demo ended, but the server is still running. What should you do? → Stop or delete it | AP6: Explain pay-as-you-go in two lines. | AQ6: Write three habits that stop surprise cloud bills. | AR6: =IF(J6="","",REPT("★",J6)&REPT("☆",5-J6)&" ("&J6&"/5)") | AS6: =IF(Q6="","","Meaning: "&Q6&" = ______ (Answer: "&F6&")") | AT6: New
A7: CLD-005 | B7: 01 Basics | C7: Beginner | D7: 5 | E7: Claude knowledge | F7: Cloud vs on-premises | G7: Which two ways of running servers differ in who owns and maintains the hardware? | H7: Core concept | I7: High | J7: 4 | K7: Organisations once had to own every server, and the cloud offered a rented alternative with different trade-offs. | L7: Compare on cost over several years, control and rules, not just on price today. | M7: On-premises is owning a house, and the cloud is renting a flat with services included. | N7: A server room on one side and a cloud icon on the other. | O7: The weight lifted when you stop maintaining hardware. | P7: On-premises means running servers you own in your own location, while cloud means renting computing resources from a provider over the internet. | R7: On-premises gives full control and can suit strict rules or steady heavy workloads, but needs upfront cost and staff. Cloud gives fast setup, easy scaling and no hardware to maintain, but ongoing fees and dependence on a provider. Hybrid setups mix both. Many customers keep sensitive systems on-premises and connect them to the cloud. | S7: Cloud rents capacity on demand, on-premises owns it. Many companies use both. | T7: On-premises is owning a house, cloud is renting a flat with services included. | U7: Own = control and upfront cost. Rent = speed and ongoing cost. | V7: A hospital keeping patient records on its own servers. | W7: A start-up renting servers for a new product launch. | X7: A bank linking its own data centre to a cloud analytics service. | Y7: hybrid cloud, regions, compliance, shared responsibility | Z7: on-premises, hybrid, colocation, capacity, ownership | AA7: Customer discovery | Migration planning | Architecture reviews | AB7: A: Why can we not move everything to the cloud? | B: Some data must stay in our own data centre by rule. | AC7: ✗ The cloud is always cheaper than on-premises → ✓ It depends on usage, because steady heavy loads can cost less on owned hardware | AD7: Cloud vs on-premises: cloud is flexible and rented, on-premises is owned and controlled. | AE7: Do not recommend a move without checking rules and total cost. | AF7: Own the house, or rent the flat. | AG7: Designing a link between a customer's own servers and a cloud analytics service. | AH7: An interviewer may ask: When would a customer stay on-premises? | AI7: It is like owning a house versus renting a furnished flat. | AJ7: What is a hybrid setup? | AK7: A) A mix of on-premises and cloud B) Only cloud C) Only on-premises D) Two clouds only | AL7: A | AM7: Hybrid combines your own systems with cloud resources. | AN7: Servers you own in your own building are called on-____ → premises | AO7: A customer must keep data in its own building but wants cloud analytics. What setup? → Hybrid | AP7: Explain cloud versus on-premises in three lines. | AQ7: List two reasons a customer might keep a system on-premises. | AR7: =IF(J7="","",REPT("★",J7)&REPT("☆",5-J7)&" ("&J7&"/5)") | AS7: =IF(Q7="","","Meaning: "&Q7&" = ______ (Answer: "&F7&")") | AT7: New
A8: CLD-006 | B8: 01 Basics | C8: Intermediate | D8: 6 | E8: Claude knowledge | F8: Well-architected ideas | G8: Which set of design principles guides building cloud systems that are reliable, secure and efficient? | H8: Core concept | I8: Medium | J8: 4 | K8: Teams kept repeating the same design mistakes, so providers published checklists of good practice organised into pillars. | L8: Use the pillars as a review checklist before launching anything for a customer. | M8: The pillars are the supports under a roof, and removing one makes the building lean. | N8: Six pillars holding up a roof labelled workload. | O8: The confidence of a design that was checked against a list. | P8: Well-architected frameworks are published sets of best-practice pillars, such as operational excellence, security, reliability, performance, cost and sustainability, used to review cloud designs. | R8: AWS lists six pillars, and Azure and Google Cloud publish similar frameworks. Each pillar has questions, such as whether backups are tested or access is least privilege. A review finds risks before they become incidents. You do not need perfection in every pillar, but you should make each trade-off on purpose. | S8: Check the design against reliability, security, cost, performance, operations and sustainability before shipping. | T8: The pillars are supports under a roof. Remove one and the building leans. | U8: Review each pillar and decide the trade-off on purpose. | V8: Asking whether a database has tested backups, under reliability. | W8: Checking that nothing has more access than it needs, under security. | X8: Reviewing monthly spend against budget, under cost. | Y8: least privilege, disaster recovery, cost alerts, monitoring | Z8: pillar, framework, review, trade-off, best practice | AA8: Design reviews | Launch checks | Customer audits | AB8: A: Is this design ready to ship? | B: Let us review it against the pillars first. | AC8: ✗ A well-architected design never fails → ✓ It reduces risk, but failures still happen and must be planned for | AD8: Pillars vs rules: pillars guide trade-offs, they are not strict laws. | AE8: Do not skip security or cost review just to launch faster. | AF8: Review every pillar, then choose trade-offs knowingly. | AG8: Reviewing a customer pipeline against the pillars and finding missing alerts. | AH8: An interviewer may ask: What does a well-architected review check? | AI8: It is like a checklist for supports under a roof. | AJ8: Which is one of the pillars? | AK8: A) Fashion B) Typing speed C) Reliability D) Colour | AL8: C | AM8: Reliability, security, cost, performance, operations and sustainability are pillars. | AN8: A published checklist of design best practice is called a well-____ framework → architected | AO8: You are about to launch. What do you review the design against? → The framework pillars | AP8: Explain the well-architected idea in three lines. | AQ8: Pick two pillars and write one question for each. | AR8: =IF(J8="","",REPT("★",J8)&REPT("☆",5-J8)&" ("&J8&"/5)") | AS8: =IF(Q8="","","Meaning: "&Q8&" = ______ (Answer: "&F8&")") | AT8: New
A9: CLD-007 | B9: 02 Identity and Access | C9: Beginner | D9: 7 | E9: Claude knowledge | F9: IAM users, groups and roles | G9: Which three identity objects decide who or what may act in your cloud account? | H9: Core concept | I9: Very high | J9: 5 | K9: A cloud account holds powerful controls, so providers created identity objects to give each person and service only the access they need. | L9: Give people access through groups, and give services access through roles. | M9: Users are named staff badges, groups are departments, and roles are hats anyone authorised can wear for a while. | N9: Badges grouped into departments, with a hat passed to a service. | O9: The calm of knowing each person has only their own keys. | P9: An IAM user is a long-term identity for a person or tool, a group is a set of users sharing permissions, and a role is a temporary identity that a trusted user or service can assume. | R9: Permissions are attached to groups and roles through policies. A role has no password or long-term key. It gives short-lived credentials to whoever assumes it, such as a server or a function. The root account should be locked away and used rarely. Azure uses users, groups and managed identities, and GCP uses accounts and service accounts. | S9: Users are people, groups share permissions, roles are temporary identities for services and trusted people. | T9: Users are staff badges, groups are departments, and roles are hats that authorised people wear for a while. | U9: People get groups. Services get roles. Root stays locked. | V9: A developer added to a read-only group for logs. | W9: A server using a role to read from storage with no stored key. | X9: A support engineer assuming an admin role for one hour. | Y9: policies, least privilege, MFA, temporary credentials | Z9: user, group, role, policy, principal | AA9: Account setup | Security reviews | Application access | AB9: A: Where does the app keep its cloud key? | B: It does not, it uses a role. | AC9: ✗ Everyone should use the root account for convenience → ✓ The root account is for rare tasks only and should be protected | AD9: User vs role: a user is a long-term identity, a role is assumed temporarily. | AE9: Do not use the root account for daily work. | AF9: People use groups, services use roles. | AG9: Replacing a stored access key in a script with a role attached to the server. | AH9: An interviewer may ask: When do you use a role instead of a user? | AI9: It is like staff badges, departments and temporary hats. | AJ9: What gives an application short-lived credentials without a stored key? | AK9: A) The root account B) A role C) A password D) A shared file | AL9: B | AM9: Roles hand out temporary credentials to trusted identities. | AN9: A set of users sharing the same permissions is a ____ → group | AO9: A server needs to read storage without a stored key. What identity? → A role | AP9: Explain users, groups and roles in three lines. | AQ9: Design which groups a small team of four would need. | AR9: =IF(J9="","",REPT("★",J9)&REPT("☆",5-J9)&" ("&J9&"/5)") | AS9: =IF(Q9="","","Meaning: "&Q9&" = ______ (Answer: "&F9&")") | AT9: New
A10: CLD-008 | B10: 02 Identity and Access | C10: Intermediate | D10: 8 | E10: Claude knowledge | F10: IAM policies | G10: Which JSON documents state what an identity is allowed or denied to do? | H10: Core concept | I10: Very high | J10: 5 | K10: Access had to be precise and reviewable, so permissions were written as structured documents rather than clicked into place. | L10: Start with no access and add only the actions and resources a task needs. | M10: A policy is a signed permission slip naming the person, the action and the place. | N10: A JSON document with Effect, Action and Resource lines. | O10: The precision of saying exactly what is allowed. | P10: An IAM policy is a document of statements, each with an effect, actions and resources, that is attached to an identity to allow or deny access. | R10: By default everything is denied. A statement with Effect Allow grants the listed actions on the listed resources. An explicit Deny always wins over an Allow. Policies can be attached to users, groups or roles, and some resources have their own policies. Conditions can narrow access, for example by IP address or by time. | S10: Policies list what is allowed. Default is deny, and an explicit deny always wins. | T10: A policy is a signed permission slip naming who may do what and where. | U10: Default deny. Allow adds access. Explicit deny wins. | V10: A policy allowing s3:GetObject on one bucket only. | W10: A policy denying deletion of anything in production. | X10: A policy that works only from the office network range. | Y10: least privilege, roles, S3 bucket policies, MFA | Z10: policy, statement, effect, action, resource | AA10: Access control | Audits | Application setup | AB10: A: I have Allow, but it still fails. | B: Another statement may deny it, and deny wins. | AC10: ✗ An Allow in one policy overrides a Deny elsewhere → ✓ An explicit Deny always wins | AD10: Allow vs explicit deny: allow grants access, an explicit deny blocks it even if allowed elsewhere. | AE10: Do not use a wildcard for all actions on all resources. | AF10: Default is no, deny always beats allow. | AG10: Narrowing a wildcard policy to one bucket and two actions after a review. | AH10: An interviewer may ask: What happens if one policy allows and another denies? | AI10: It is like a permission slip that names the person and the place. | AJ10: What is the default access when no policy allows an action? | AK10: A) Admin B) Read only C) Allowed D) Denied | AL10: D | AM10: Access is denied unless something explicitly allows it. | AN10: Each policy statement has an effect, actions and ____ → resources | AO10: Two policies disagree, one allows and one denies. What happens? → Access is denied | AP10: Explain the parts of a policy statement. | AQ10: Write in words a policy that lets a user read one bucket only. | AR10: =IF(J10="","",REPT("★",J10)&REPT("☆",5-J10)&" ("&J10&"/5)") | AS10: =IF(Q10="","","Meaning: "&Q10&" = ______ (Answer: "&F10&")") | AT10: New
A11: CLD-009 | B11: 02 Identity and Access | C11: Intermediate | D11: 9 | E11: Claude knowledge | F11: Least privilege | G11: Which principle says to give only the minimum access needed to do a job? | H11: Core concept | I11: Very high | J11: 5 | K11: Over-powerful accounts turned small mistakes into disasters, so security teams adopted the rule of granting as little as possible. | L11: Start narrow and widen only when a real task fails, not the other way round. | M11: Least privilege is handing a visitor one room key instead of the master key. | N11: A person holding one key labelled with a single door. | O11: The ease of knowing a mistake cannot reach far. | P11: Least privilege means granting each identity only the permissions it needs for its task, for only as long as it needs them. | R11: It limits the damage from a stolen key or a mistake. Practise it by using specific actions and resources instead of wildcards, by using roles with short sessions, and by reviewing unused permissions. Access analysers and last-used reports show what can be removed. It is a main idea in every security framework. | S11: Give the smallest permission that works, review it often, and remove what is not used. | T11: It is like giving a visitor one room key instead of the master key. | U11: Needed actions + needed resources + needed time, and nothing more. | V11: A reporting job that can only read one table. | W11: A deploy role limited to one service. | X11: A contractor given access for two weeks only. | Y11: IAM policies, roles, temporary credentials, audits | Z11: privilege, minimum, scope, wildcard, review | AA11: Security design | Access reviews | Compliance | AB11: A: Can we just give admin to make it work? | B: No, let us find the exact permission it needs. | AC11: ✗ Giving broad admin access saves time and does no harm → ✓ It makes any leak or mistake far more damaging | AD11: Least privilege vs convenience: broad access is faster today but riskier tomorrow. | AE11: Do not leave temporary broad access in place after testing. | AF11: One key for one door only. | AG11: Replacing an admin policy on a pipeline with a role scoped to one deployment. | AH11: An interviewer may ask: How do you apply least privilege in practice? | AI11: It is like giving a visitor a single room key. | AJ11: Which practice supports least privilege? | AK11: A) Never reviewing access B) Specific actions and resources C) Sharing one admin login D) Wildcards everywhere | AL11: B | AM11: Narrow permissions limit the damage of a mistake. | AN11: Least privilege grants the ____ access needed → minimum | AO11: A job only reads one table. How much access does it get? → Read on that table only | AP11: Explain least privilege in two lines. | AQ11: Review one script you wrote and list the minimum permissions it needs. | AR11: =IF(J11="","",REPT("★",J11)&REPT("☆",5-J11)&" ("&J11&"/5)") | AS11: =IF(Q11="","","Meaning: "&Q11&" = ______ (Answer: "&F11&")") | AT11: New
A12: CLD-010 | B12: 02 Identity and Access | C12: Beginner | D12: 10 | E12: Claude knowledge | F12: MFA | G12: Which extra login step protects an account even if the password is stolen? | H12: Core concept | I12: Very high | J12: 5 | K12: Passwords leak and get guessed, so a second proof that only the real owner has was added to logins. | L12: Turn on MFA first for the root account and every admin. | M12: MFA is a second lock on the door that needs a key from your pocket. | N12: A password box followed by a six-digit code. | O12: The security of a stolen password being useless. | P12: Multi-factor authentication requires two or more proofs of identity, such as a password plus a code from an app or a hardware key. | R12: The factors are something you know, something you have and something you are. Hardware keys and authenticator apps are stronger than text-message codes. Cloud providers can require MFA for the console and for sensitive actions. Always store recovery options safely, since losing the device can lock you out. | S12: Use a password and a second proof. Prefer an authenticator app or hardware key over text messages. | T12: It is like a second lock that needs a key from your pocket. | U12: Know + have + are. Two or more of these is MFA. | V12: An authenticator app code needed after the password. | W12: A hardware key tapped to approve an admin login. | X12: MFA required before deleting a production database. | Y12: IAM users, root account, access keys, SSO | Z12: factor, authenticator, hardware key, one-time code, recovery | AA12: Account security | Admin access | Compliance | AB12: A: Someone guessed the password. | B: MFA would have stopped the login. | AC12: ✗ A long password makes MFA unnecessary → ✓ Passwords can still be phished or leaked, and MFA adds a second barrier | AD12: Text message vs hardware key: a hardware key resists phishing better. | AE12: Do not skip MFA on the root account. | AF12: A second lock needs a second key. | AG12: Enforcing MFA for all admin roles after a phishing attempt. | AH12: An interviewer may ask: Why is MFA important for cloud accounts? | AI12: It is like a second lock that needs a key from your pocket. | AJ12: Which account should always have MFA turned on? | AK12: A) Only test accounts B) No account C) Only read-only users D) The root account | AL12: D | AM12: The root account has unlimited power. | AN12: A password plus a code is an example of ____ authentication → multi-factor | AO12: A password leaked. What would still block the login? → A second factor | AP12: Explain why MFA matters in three lines. | AQ12: List the safest and weakest second factors you know. | AR12: =IF(J12="","",REPT("★",J12)&REPT("☆",5-J12)&" ("&J12&"/5)") | AS12: =IF(Q12="","","Meaning: "&Q12&" = ______ (Answer: "&F12&")") | AT12: New
A13: CLD-011 | B13: 02 Identity and Access | C13: Intermediate | D13: 11 | E13: Claude knowledge | F13: Access keys | G13: Which long-lived credentials let a script or tool call the cloud API, and why are they risky? | H13: Core concept | I13: High | J13: 5 | K13: Programs cannot type passwords, so providers issue key pairs that sign API requests. | L13: Prefer roles and temporary credentials, and rotate or delete any key you must keep. | M13: An access key is a spare house key. Lose it and anyone can walk in. | N13: A key id and a secret on a sticky note taped to a monitor. | O13: The dread of finding a key in a public repository. | P13: An access key is a pair of an identifier and a secret that signs programmatic requests to the cloud, and it stays valid until rotated or deleted. | R13: The secret is shown only once at creation. Keys in code, chat or public repositories get stolen and abused within minutes by bots. Store them in a secrets manager, never in Git, and rotate them on a schedule. Better still, avoid them by using roles. Unused keys should be deactivated and then deleted. | S13: Keys are long-lived passwords for programs. Avoid them, protect them, rotate them, and delete the unused ones. | T13: An access key is a spare house key. If it is lost, anyone can walk in. | U13: Prefer role over key. If a key is unavoidable, rotate and restrict it. | V13: A key committed to GitHub and used by bots to mine coins. | W13: A script using a role instead of any key. | X13: A quarterly job that rotates keys and deletes unused ones. | Y13: temporary credentials, secrets, IAM roles, secret scanning | Z13: key, secret, rotation, credential, leak | AA13: Automation | Local tools | Security reviews | AB13: A: I pushed my key by mistake. | B: Deactivate it right now and create a new one. | AC13: ✗ Deleting a commit removes a leaked key from the world → ✓ The key must be revoked, because copies may exist | AD13: Access key vs role credentials: keys are long-lived, role credentials expire. | AE13: Do not commit keys to Git, even in a private repository. | AF13: Leaked key means revoke first, then clean up. | AG13: Revoking a key leaked in a repository and moving the script to a role. | AH13: An interviewer may ask: What do you do if an access key leaks? | AI13: It is like losing a spare house key. | AJ13: What is the first action when a key leaks? | AK13: A) Delete the commit only B) Ignore it C) Deactivate the key D) Email the team only | AL13: C | AM13: Revoking stops abuse immediately, since copies may exist. | AN13: A key should be changed on a schedule, which is called key ____ → rotation | AO13: You find a key in a repository. What do you do first? → Revoke it | AP13: Explain why access keys are risky in three lines. | AQ13: List three places where keys should never be stored. | AR13: =IF(J13="","",REPT("★",J13)&REPT("☆",5-J13)&" ("&J13&"/5)") | AS13: =IF(Q13="","","Meaning: "&Q13&" = ______ (Answer: "&F13&")") | AT13: New
A14: CLD-012 | B14: 02 Identity and Access | C14: Intermediate | D14: 12 | E14: Claude knowledge | F14: Temporary credentials | G14: Which short-lived credentials replace permanent keys and expire on their own? | H14: Core concept | I14: High | J14: 4 | K14: Permanent keys kept leaking, so providers created credentials that expire after minutes or hours. | L14: Use roles, single sign-on or workload identity so no permanent key exists at all. | M14: Temporary credentials are a hotel key card that stops working at checkout. | N14: A key card with an expiry time. | O14: The comfort of leaked credentials that are already dead. | P14: Temporary credentials are short-lived access tokens, issued when an identity assumes a role, that expire automatically. | R14: An identity asks the security token service to assume a role and receives a key, a secret and a session token valid for a limited time. The same idea appears as managed identities in Azure and workload identity in GCP. CI systems can use OpenID Connect to get these tokens without any stored secret. A leaked token is far less dangerous because it soon expires. | S14: Ask for a role, receive credentials that expire, and keep no permanent key. | T14: It is like a hotel key card that stops working at checkout. | U14: Assume role → receive short-lived credentials → they expire. | V14: A server role giving credentials that refresh automatically. | W14: A pipeline using OIDC to deploy with no stored key. | X14: An engineer assuming an admin role for one hour. | Y14: roles, access keys, SSO, OIDC in CI | Z14: token, session, expiry, assume role, federation | AA14: CI pipelines | Servers | Admin access | AB14: A: Do we store a key for the pipeline? | B: No, it assumes a role through OIDC. | AC14: ✗ Temporary credentials are less secure because they are not permanent → ✓ They are safer, since they expire if stolen | AD14: Temporary vs permanent credentials: temporary ones expire by themselves. | AE14: Do not extend session lifetimes far beyond the need. | AF14: Short life means short damage. | AG14: Moving a deployment pipeline to temporary credentials and deleting its stored key. | AH14: An interviewer may ask: Why prefer temporary credentials? | AI14: It is like a hotel key card that expires at checkout. | AJ14: What is the main benefit of temporary credentials? | AK14: A) A leaked token expires soon B) They cost nothing C) They skip MFA D) They never need a role | AL14: A | AM14: Expiry limits how long a stolen credential works. | AN14: A role gives credentials that ____ automatically → expire | AO14: A pipeline needs cloud access. How can it avoid stored keys? → Use a role through OIDC | AP14: Explain temporary credentials in three lines. | AQ14: Write the steps for a pipeline to get temporary credentials. | AR14: =IF(J14="","",REPT("★",J14)&REPT("☆",5-J14)&" ("&J14&"/5)") | AS14: =IF(Q14="","","Meaning: "&Q14&" = ______ (Answer: "&F14&")") | AT14: New
... A52: CLD-050 | B52: 08 Choosing and Mapping | C52: Intermediate | D52: 50 | E52: Claude knowledge | F52: Choosing between functions, containers and virtual machines | G52: Which questions decide whether to run code on a function, a container service or a virtual machine? | H52: Reference | I52: High | J52: 4 | K52: Cloud offers several ways to run code, so teams need a simple method to pick the right one for each job. | L52: Start with the most managed option that fits, and move down only when you need more control. | M52: It is choosing between a taxi, a rented car and owning a car. | N52: A ladder from functions to containers to virtual machines, with control growing downward. | O52: The ease of a clear rule of thumb. | P52: Functions suit short event-driven tasks, container services suit long-running packaged apps, and virtual machines suit workloads that need full control of the operating system. | R52: Functions have time limits and stateless design but need no servers. Containers give portability and steady services with moderate effort. Virtual machines give maximum control but need patching and sizing. Consider run time, traffic pattern, state, skills and cost. Spiky, short jobs favour functions, steady services favour containers, and legacy or special software favours virtual machines. | S52: Use the most managed option that fits the job, and move toward more control only when needed. | T52: It is choosing between a taxi, a rented car and owning a car. | U52: More control means more work. Pick the least you need. | V52: A nightly cleanup as a function. | W52: A web API as a container service. | X52: Licensed legacy software on a virtual machine. | Y52: serverless functions, container services, virtual machines, cost | Z52: function, container, virtual machine, control, managed | AA52: Architecture decisions | Customer designs | Migrations | AB52: A: Should we use a server for this small task? | B: A function is simpler if it finishes quickly. | AC52: ✗ Virtual machines are always the safest default → ✓ A more managed option often costs less effort and fits better | AD52: Function vs container: a function is short and event-driven, a container service runs steadily. | AE52: Do not use functions for jobs that run longer than their limit. | AF52: Least control that works wins. | AG52: Choosing containers for a steady API and functions for its nightly cleanup jobs. | AH52: An interviewer may ask: How do you decide between functions and containers? | AI52: It is like choosing between a taxi and a rented car. | AJ52: Which suits a long-running web service with steady traffic? | AK52: A) A bucket B) A function with a short limit C) A container service D) A queue | AL52: C | AM52: Containers run steadily without function time limits. | AN52: Functions are best for short, ____ tasks → event-driven | AO52: Legacy licensed software needs full OS control. Which option? → A virtual machine | AP52: Explain how to choose a compute option in three lines. | AQ52: Choose a compute option for three jobs and explain why. | AR52: =IF(J52="","",REPT("★",J52)&REPT("☆",5-J52)&" ("&J52&"/5)") | AS52: =IF(Q52="","","Meaning: "&Q52&" = ______ (Answer: "&F52&")") | AT52: New

Sheet Topic card view
A1: Topic (56-pt) · card view
A2: Card ID chuno ▸ | B2: CLD-001
A4: FRONT · Recognition (pehchano)
A5: ID | B5: =INDEX('Topic (56-pt) cards'!$A$3:$BB$52,MATCH($B$2,'Topic (56-pt) cards'!$A$3:$A$52,0),MATCH("ID",'Topic (56-pt) cards'!$A$2:$BB$2,0))&""
A6: Topic | B6: =INDEX('Topic (56-pt) cards'!$A$3:$BB$52,MATCH($B$2,'Topic (56-pt) cards'!$A$3:$A$52,0),MATCH("Topic",'Topic (56-pt) cards'!$A$2:$BB$2,0))&""
A7: Level | B7: =INDEX('Topic (56-pt) cards'!$A$3:$BB$52,MATCH($B$2,'Topic (56-pt) cards'!$A$3:$A$52,0),MATCH("Level",'Topic (56-pt) cards'!$A$2:$BB$2,0))&""
A8: Term / topic | B8: =INDEX('Topic (56-pt) cards'!$A$3:$BB$52,MATCH($B$2,'Topic (56-pt) cards'!$A$3:$A$52,0),MATCH("Term / topic",'Topic (56-pt) cards'!$A$2:$BB$2,0))&""
A9: Recall cue | B9: =INDEX('Topic (56-pt) cards'!$A$3:$BB$52,MATCH($B$2,'Topic (56-pt) cards'!$A$3:$A$52,0),MATCH("Recall cue",'Topic (56-pt) cards'!$A$2:$BB$2,0))&""
A10: Category | B10: =INDEX('Topic (56-pt) cards'!$A$3:$BB$52,MATCH($B$2,'Topic (56-pt) cards'!$A$3:$A$52,0),MATCH("Category",'Topic (56-pt) cards'!$A$2:$BB$2,0))&""
A11: How often used | B11: =INDEX('Topic (56-pt) cards'!$A$3:$BB$52,MATCH($B$2,'Topic (56-pt) cards'!$A$3:$A$52,0),MATCH("How often used",'Topic (56-pt) cards'!$A$2:$BB$2,0))&""
A12: Importance (1-5) | B12: =INDEX('Topic (56-pt) cards'!$A$3:$BB$52,MATCH($B$2,'Topic (56-pt) cards'!$A$3:$A$52,0),MATCH("Importance (1-5)",'Topic (56-pt) cards'!$A$2:$BB$2,0))&""
A13: Origin / why it exists | B13: =INDEX('Topic (56-pt) cards'!$A$3:$BB$52,MATCH($B$2,'Topic (56-pt) cards'!$A$3:$A$52,0),MATCH("Origin / why it exists",'Topic (56-pt) cards'!$A$2:$BB$2,0))&""
A14: Pro tip | B14: =INDEX('Topic (56-pt) cards'!$A$3:$BB$52,MATCH($B$2,'Topic (56-pt) cards'!$A$3:$A$52,0),MATCH("Pro tip",'Topic (56-pt) cards'!$A$2:$BB$2,0))&""
A15: Memory story | B15: =INDEX('Topic (56-pt) cards'!$A$3:$BB$52,MATCH($B$2,'Topic (56-pt) cards'!$A$3:$A$52,0),MATCH("Memory story",'Topic (56-pt) cards'!$A$2:$BB$2,0))&""
A16: Picture it | B16: =INDEX('Topic (56-pt) cards'!$A$3:$BB$52,MATCH($B$2,'Topic (56-pt) cards'!$A$3:$A$52,0),MATCH("Picture it",'Topic (56-pt) cards'!$A$2:$BB$2,0))&""
A17: Emotion hook | B17: =INDEX('Topic (56-pt) cards'!$A$3:$BB$52,MATCH($B$2,'Topic (56-pt) cards'!$A$3:$A$52,0),MATCH("Emotion hook",'Topic (56-pt) cards'!$A$2:$BB$2,0))&""
A18: Importance ★ | B18: =INDEX('Topic (56-pt) cards'!$A$3:$BB$52,MATCH($B$2,'Topic (56-pt) cards'!$A$3:$A$52,0),MATCH("Importance ★",'Topic (56-pt) cards'!$A$2:$BB$2,0))&""
A19: BACK · Understanding (samjho)
A20: Definition (simple) | B20: =INDEX('Topic (56-pt) cards'!$A$3:$BB$52,MATCH($B$2,'Topic (56-pt) cards'!$A$3:$A$52,0),MATCH("Definition (simple)",'Topic (56-pt) cards'!$A$2:$BB$2,0))&""
A21: Meaning in learner's language | B21: =INDEX('Topic (56-pt) cards'!$A$3:$BB$52,MATCH($B$2,'Topic (56-pt) cards'!$A$3:$A$52,0),MATCH("Meaning in learner's language",'Topic (56-pt) cards'!$A$2:$BB$2,0))&""
A22: How / why it works | B22: =INDEX('Topic (56-pt) cards'!$A$3:$BB$52,MATCH($B$2,'Topic (56-pt) cards'!$A$3:$A$52,0),MATCH("How / why it works",'Topic (56-pt) cards'!$A$2:$BB$2,0))&""
A23: Simple explanation (Hinglish) | B23: =INDEX('Topic (56-pt) cards'!$A$3:$BB$52,MATCH($B$2,'Topic (56-pt) cards'!$A$3:$A$52,0),MATCH("Simple explanation (Hinglish)",'Topic (56-pt) cards'!$A$2:$BB$2,0))&""
A24: Real-life analogy | B24: =INDEX('Topic (56-pt) cards'!$A$3:$BB$52,MATCH($B$2,'Topic (56-pt) cards'!$A$3:$A$52,0),MATCH("Real-life analogy",'Topic (56-pt) cards'!$A$2:$BB$2,0))&""
A25: Formula / rule | B25: =INDEX('Topic (56-pt) cards'!$A$3:$BB$52,MATCH($B$2,'Topic (56-pt) cards'!$A$3:$A$52,0),MATCH("Formula / rule",'Topic (56-pt) cards'!$A$2:$BB$2,0))&""
A26: Example 1 | B26: =INDEX('Topic (56-pt) cards'!$A$3:$BB$52,MATCH($B$2,'Topic (56-pt) cards'!$A$3:$A$52,0),MATCH("Example 1",'Topic (56-pt) cards'!$A$2:$BB$2,0))&""
A27: Example 2 | B27: =INDEX('Topic (56-pt) cards'!$A$3:$BB$52,MATCH($B$2,'Topic (56-pt) cards'!$A$3:$A$52,0),MATCH("Example 2",'Topic (56-pt) cards'!$A$2:$BB$2,0))&""
A28: Example 3 | B28: =INDEX('Topic (56-pt) cards'!$A$3:$BB$52,MATCH($B$2,'Topic (56-pt) cards'!$A$3:$A$52,0),MATCH("Example 3",'Topic (56-pt) cards'!$A$2:$BB$2,0))&""
A29: Related concepts | B29: =INDEX('Topic (56-pt) cards'!$A$3:$BB$52,MATCH($B$2,'Topic (56-pt) cards'!$A$3:$A$52,0),MATCH("Related concepts",'Topic (56-pt) cards'!$A$2:$BB$2,0))&""
A30: Family / group | B30: =INDEX('Topic (56-pt) cards'!$A$3:$BB$52,MATCH($B$2,'Topic (56-pt) cards'!$A$3:$A$52,0),MATCH("Family / group",'Topic (56-pt) cards'!$A$2:$BB$2,0))&""
A31: Where it is used | B31: =INDEX('Topic (56-pt) cards'!$A$3:$BB$52,MATCH($B$2,'Topic (56-pt) cards'!$A$3:$A$52,0),MATCH("Where it is used",'Topic (56-pt) cards'!$A$2:$BB$2,0))&""
A32: Mini conversation | B32: =INDEX('Topic (56-pt) cards'!$A$3:$BB$52,MATCH($B$2,'Topic (56-pt) cards'!$A$3:$A$52,0),MATCH("Mini conversation",'Topic (56-pt) cards'!$A$2:$BB$2,0))&""
A33: Common mistake | B33: =INDEX('Topic (56-pt) cards'!$A$3:$BB$52,MATCH($B$2,'Topic (56-pt) cards'!$A$3:$A$52,0),MATCH("Common mistake",'Topic (56-pt) cards'!$A$2:$BB$2,0))&""
A34: Don't confuse with | B34: =INDEX('Topic (56-pt) cards'!$A$3:$BB$52,MATCH($B$2,'Topic (56-pt) cards'!$A$3:$A$52,0),MATCH("Don't confuse with",'Topic (56-pt) cards'!$A$2:$BB$2,0))&""
A35: Avoid / don't | B35: =INDEX('Topic (56-pt) cards'!$A$3:$BB$52,MATCH($B$2,'Topic (56-pt) cards'!$A$3:$A$52,0),MATCH("Avoid / don't",'Topic (56-pt) cards'!$A$2:$BB$2,0))&""
A36: Memory trick | B36: =INDEX('Topic (56-pt) cards'!$A$3:$BB$52,MATCH($B$2,'Topic (56-pt) cards'!$A$3:$A$52,0),MATCH("Memory trick",'Topic (56-pt) cards'!$A$2:$BB$2,0))&""
A37: Real life: project / work | B37: =INDEX('Topic (56-pt) cards'!$A$3:$BB$52,MATCH($B$2,'Topic (56-pt) cards'!$A$3:$A$52,0),MATCH("Real life: project / work",'Topic (56-pt) cards'!$A$2:$BB$2,0))&""
A38: Real life: interview / exam | B38: =INDEX('Topic (56-pt) cards'!$A$3:$BB$52,MATCH($B$2,'Topic (56-pt) cards'!$A$3:$A$52,0),MATCH("Real life: interview / exam",'Topic (56-pt) cards'!$A$2:$BB$2,0))&""
A39: Real life: daily life | B39: =INDEX('Topic (56-pt) cards'!$A$3:$BB$52,MATCH($B$2,'Topic (56-pt) cards'!$A$3:$A$52,0),MATCH("Real life: daily life",'Topic (56-pt) cards'!$A$2:$BB$2,0))&""
A40: PRACTICE · Khud karo
A41: MCQ question | B41: =INDEX('Topic (56-pt) cards'!$A$3:$BB$52,MATCH($B$2,'Topic (56-pt) cards'!$A$3:$A$52,0),MATCH("MCQ question",'Topic (56-pt) cards'!$A$2:$BB$2,0))&""
...

Sheet Anki Import
A1: Front | B1: Back | C1: Tags
A2: IaaS, PaaS and SaaS Which three service models differ in how much of the stack you manage yourself? | B2: DEFINITION (SIMPLE): IaaS rents virtual infrastructure such as servers and networks, PaaS rents a platform for running your code without managing servers, and SaaS delivers a finished application over the internet. HOW / WHY IT WORKS: With IaaS, such as AWS EC2, you manage the operating system and everything above it. With PaaS, such as Elastic Beanstalk, App Service or App Engine, you deploy code and the provider runs the servers. With SaaS, such as Gmail or Salesforce, you only use the product. The more the provider manages, the less control and the less work you have. SIMPLE EXPLANATION (HINGLISH): IaaS gives you servers, PaaS gives you a place to run code, SaaS gives you the finished app. Each step hands more work to the provider. REAL-LIFE ANALOGY: IaaS is an empty rented kitchen, PaaS is a kitchen with tools ready, and SaaS is a meal delivered to your table. FORMULA / RULE: More provider management = less control for you, and less work for you. EXAMPLE 1: Launching an EC2 virtual machine and installing your own web server on it. EXAMPLE 2: Deploying a Python app to a platform service that handles servers for you. EXAMPLE 3: Using a hosted email service through a web browser. RELATED CONCEPTS: cloud vs on-premises, shared responsibility, virtual machines FAMILY / GROUP: infrastructure, platform, software, service, managed WHERE IT IS USED: Choosing hosting | Planning budgets | Customer architecture talks MINI CONVERSATION: A: Do we patch the operating system ourselves? | B: Only if we pick IaaS. A platform service patches it for us. COMMON MISTAKE: ✗ SaaS and PaaS are the same because both are managed → ✓ PaaS runs your code, while SaaS is a finished product you simply use DON'T CONFUSE WITH: IaaS vs PaaS: with IaaS you manage the operating system, with PaaS you only manage your code and data. AVOID / DON'T: Do not choose IaaS only for control if nobody on the team wants to patch servers. MEMORY TRICK: Infrastructure, platform, software, each hands over more. REAL LIFE: PROJECT / WORK: Moving a customer script from a rented server to a managed platform to avoid patching work. REAL LIFE: INTERVIEW / EXAM: An interviewer may ask: What is the difference between IaaS, PaaS and SaaS? REAL LIFE: DAILY LIFE: It is like cooking in a rented kitchen versus ordering delivery. | C2: 01_Basics_Beginner_CLD-001
A3: Regions and availability zones Which two ideas describe where in the world your cloud resources physically run, and how they survive a failure? | B3: DEFINITION (SIMPLE): A region is a geographic area containing several availability zones, and an availability zone is one or more isolated data centres with independent power and networking. HOW / WHY IT WORKS: Resources are created in a chosen region, such as ap-south-1 in Mumbai. Zones inside a region are connected with fast links, so you can run copies of a service in several zones. Data does not leave a region unless you move it. Azure calls them regions and availability zones, and GCP calls them regions and zones. Not every service exists in every region. SIMPLE EXPLANATION (HINGLISH): Pick a region close to your users and rules, and spread copies across zones inside it for resilience. REAL-LIFE ANALOGY: A region is a city, and zones are separate buildings with their own power supply. FORMULA / RULE: Region = location. Zone = isolated data centre inside it. EXAMPLE 1: Running a web server in two zones of Mumbai so one can fail safely. EXAMPLE 2: Storing customer data only in a region that meets local law. EXAMPLE 3: Choosing a nearby region to reduce latency for users. RELATED CONCEPTS: disaster recovery, latency, data residency, load balancers FAMILY / GROUP: region, zone, data centre, latency, resilience WHERE IT IS USED: Architecture design | Compliance | Cost and speed decisions MINI CONVERSATION: A: If one data centre burns down, are we down? | B: Not if we run in two zones. COMMON MISTAKE: ✗ Data automatically copies to every region → ✓ Data stays in the chosen region unless you set up replication DON'T CONFUSE WITH: Region vs zone: a region is a whole area, a zone is one isolated location inside it. AVOID / DON'T: Do not put every copy of a critical service in a single zone. MEMORY TRICK: Regions are cities, zones are buildings inside. REAL LIFE: PROJECT / WORK: Placing a customer database in a regional location to meet their data residency rule. REAL LIFE: INTERVIEW / EXAM: An interviewer may ask: How do you make an application survive a data centre failure? REAL LIFE: DAILY LIFE: It is like keeping backups in separate buildings of one city. | C3: 01_Basics_Beginner_CLD-002
A4: Shared responsibility model Which model says what the provider secures and what you must secure? | B4: DEFINITION (SIMPLE): The shared responsibility model divides security duties, so the provider secures the underlying infrastructure and the customer secures their data, access and configuration. HOW / WHY IT WORKS: The provider handles buildings, hardware and the virtualisation layer. You handle identity and access, data, encryption choices, network rules and, with IaaS, the operating system. Many cloud breaches come from customer misconfiguration, such as a public storage bucket or an exposed key. The line moves up as you use more managed services. SIMPLE EXPLANATION (HINGLISH): The provider protects the cloud, and you protect what you place in it and how you configure it. REAL-LIFE ANALOGY: The landlord secures the building, and you lock your own door. FORMULA / RULE: Provider = security of the cloud. Customer = security in the cloud. EXAMPLE 1: A provider securing the data centre while you set the storage permissions. EXAMPLE 2: A leaked access key causing a breach, which is the customer's duty. EXAMPLE 3: A managed database where the provider patches the engine but you control who can connect. RELATED CONCEPTS: IAM, least privilege, encryption, secrets FAMILY / GROUP: responsibility, security, configuration, compliance, provider WHERE IT IS USED: Security reviews | Customer questions | Audits MINI CONVERSATION: A: Is our data safe because we are on AWS? | B: Only if we set permissions and encryption correctly. COMMON MISTAKE: ✗ The cloud provider secures everything, including my settings → ✓ You remain responsible for access, data and configuration DON'T CONFUSE WITH: Security of the cloud vs security in the cloud: the first is the provider's job, the second is yours. AVOID / DON'T: Do not assume a default setting is safe without checking it. MEMORY TRICK: Provider secures the cloud, you secure contents. REAL LIFE: PROJECT / WORK: Fixing a public bucket found in a review, which was a customer-side mistake. REAL LIFE: INTERVIEW / EXAM: An interviewer may ask: Who is responsible when a storage bucket is left public? REAL LIFE: DAILY LIFE: It is like the landlord securing the building while you lock your door. | C4: 01_Basics_Beginner_CLD-003
A5: Pay-as-you-go pricing Which pricing idea means you pay for what you use rather than buying equipment upfront? | B5: DEFINITION (SIMPLE): Pay-as-you-go pricing charges for the resources and time you actually use, with options to commit for a lower price. HOW / WHY IT WORKS: Compute is often billed per second, storage per gigabyte per month, and data leaving the cloud per gigabyte. Savings plans or reserved capacity give a discount for committing. Spot capacity is cheaper but can be taken back. Free tiers have limits and expire. Forgotten resources are the most common surprise on a bill. SIMPLE EXPLANATION (HINGLISH): You are billed for usage, so stop what you do not need and set budget alerts. REAL-LIFE ANALOGY: It is like a taxi meter instead of buying a car. FORMULA / RULE: Cost = quantity used × price per unit × time. EXAMPLE 1: A test server that costs money only while it is switched on. EXAMPLE 2: A stored backup billed per gigabyte per month. EXAMPLE 3: A discount for committing to steady usage for a year. RELATED CONCEPTS: cost alerts, tagging, spot instances, cleanup FAMILY / GROUP: metered, billing, reserved, spot, commitment WHERE IT IS USED: Budget planning | Cost reviews | Customer estimates MINI CONVERSATION: A: Why is the bill high? | B: A forgotten test server ran all month. COMMON MISTAKE: ✗ If I stop using a service it stops costing money → ✓ Resources keep billing until you stop or delete them DON'T CONFUSE WITH: On-demand vs reserved: on-demand has no commitment, reserved is cheaper for steady use. AVOID / DON'T: Do not leave test resources running after a demo. MEMORY TRICK: Idle resources still ring the meter. REAL LIFE: PROJECT / WORK: Deleting forgotten test resources after a bill alert and saving the monthly budget. REAL LIFE: INTERVIEW / EXAM: An interviewer may ask: How do you control cloud cost? REAL LIFE: DAILY LIFE: It is like a taxi meter that runs until you get out. | C5: 01_Basics_Beginner_CLD-004
A6: Cloud vs on-premises Which two ways of running servers differ in who owns and maintains the hardware? | B6: DEFINITION (SIMPLE): On-premises means running servers you own in your own location, while cloud means renting computing resources from a provider over the internet. HOW / WHY IT WORKS: On-premises gives full control and can suit strict rules or steady heavy workloads, but needs upfront cost and staff. Cloud gives fast setup, easy scaling and no hardware to maintain, but ongoing fees and dependence on a provider. Hybrid setups mix both. Many customers keep sensitive systems on-premises and connect them to the cloud. SIMPLE EXPLANATION (HINGLISH): Cloud rents capacity on demand, on-premises owns it. Many companies use both. REAL-LIFE ANALOGY: On-premises is owning a house, cloud is renting a flat with services included. FORMULA / RULE: Own = control and upfront cost. Rent = speed and ongoing cost. EXAMPLE 1: A hospital keeping patient records on its own servers. EXAMPLE 2: A start-up renting servers for a new product launch. EXAMPLE 3: A bank linking its own data centre to a cloud analytics service. RELATED CONCEPTS: hybrid cloud, regions, compliance, shared responsibility FAMILY / GROUP: on-premises, hybrid, colocation, capacity, ownership WHERE IT IS USED: Customer discovery | Migration planning | Architecture reviews MINI CONVERSATION: A: Why can we not move everything to the cloud? | B: Some data must stay in our own data centre by rule. COMMON MISTAKE: ✗ The cloud is always cheaper than on-premises → ✓ It depends on usage, because steady heavy loads can cost less on owned hardware DON'T CONFUSE WITH: Cloud vs on-premises: cloud is flexible and rented, on-premises is owned and controlled. AVOID / DON'T: Do not recommend a move without checking rules and total cost. MEMORY TRICK: Own the house, or rent the flat. REAL LIFE: PROJECT / WORK: Designing a link between a customer's own servers and a cloud analytics service. REAL LIFE: INTERVIEW / EXAM: An interviewer may ask: When would a customer stay on-premises? REAL LIFE: DAILY LIFE: It is like owning a house versus renting a furnished flat. | C6: 01_Basics_Beginner_CLD-005
