Workbook

Sheet Read Me
A1: 220 English Chunks · Two Learner Paths
A3: What this is | B3: All 220 chunks built in this project, covering all 23 chunk types, ordered two ways: one path for true beginners and one for learners who know grammar but freeze when speaking.
A4: Path A: Beginner | B4: Follows the 5-level research order from chunk-learning-priority.md: Survival → Slot stems → Collocations & fillers → Connectors → Idioms. Goal-based chunks are added on demand.
A5: Path B: Knows grammar | B5: For the typical Speak Sarthi learner. Starts by stopping the freeze (repair + fillers), then fixes the errors listeners notice (prepositions, question word order, politeness), skims Levels 1–2, then joins the research order at Level 3.
A6: How the order works | B6: Within each stage: easiest CEFR level first (A1 → A2 → B1), then by chunk type. The # columns give the full teaching sequence 1–220 for each path.
A8: Sheets
A9: Path A – Beginner | B9: All 220 chunks sorted in Path A order.
A10: Path B – Knows Grammar | B10: The same 220 chunks sorted in Path B order.
A11: Summary | B11: Live chunk counts per stage, per type and per CEFR level (formulas).
A13: Filtering tip | B13: Both data sheets have filters on the header row. Filter by Type, CEFR or either path's stage.
A15: Slot column | B15: What the learner fills in to complete the chunk: base verb, -ing verb, noun, clause, past participle, etc. 'No slot' means the chunk is used as it is (only tense or person may change).
A16: Gap-fill question + Answer | B16: One ready question per chunk. Three styles, chosen by type: (1) blank the slot and give the verb in brackets, testing the grammar after the chunk; (2) blank a word inside the chunk, testing the fixed partner (for, make/do, pepper); (3) a situation prompt with the key word blanked, testing recall of whole lines.
A18: Judgement calls
A19: Eight types placed by Claude | B19: The research doc does not mention Short replies, Polite softeners, Dependent prepositions, Topic, Reactions, Agreeing & disagreeing, Binomials, Situational or Formal & written. Their placement is Claude's judgement, not the doc's.
A20: Phrasal verbs | B20: The doc sends phrasal verbs with tricky meanings to Level 5. Here all phrasal verbs stay in Level 3 because they are very frequent (give up, look after). The non-obvious ones are flagged in the Meaning / Watch out column instead.
A21: CEFR levels | B21: A1/A2/B1 tags are estimates, not taken from a frequency corpus or official CEFR wordlist.
A22: Research figures | B22: Statistics quoted in chunk-learning-priority.md have not been re-checked against the original papers. Verify before publishing them.
A24: Path A stages
A25: Level 1 · Survival chunks | B25: Keep any conversation going and turn it into a lesson. Types: Clarification & repair, Openers & closers, Fixed expressions, Short replies
A26: Level 2 · Slot stems | B26: Highest return: each stem carries grammar and makes many sentences. Types: Sentence frames, Question frames, Grammatical chunks, Opinion, Polite softeners
A27: Level 3 · Collocations & fillers | B27: The most frequent word groups in real speech. Types: Collocations, Polywords, Fillers & time-buyers, Phrasal verbs, Dependent prepositions, Topic, Reactions, Agreeing & disagreeing, Binomials
A28: Level 4 · Connectors | B28: Link short sentences into longer speech. Types: Discourse markers
A29: Level 5 · Idioms | B29: Understand first, use last. Types: Idioms, Proverbs & sayings
A30: On demand · Goal-based | B30: Add when a real need appears: interview, phone, email. Types: Situational, Formal & written
A32: Path B stages
A33: Stage 1 · Unfreeze | B33: Stop the freeze: never go silent, always have a way to recover. Types: Clarification & repair, Fillers & time-buyers
A34: Stage 2 · Fix errors people notice | B34: The mistakes a listener hears immediately. Types: Dependent prepositions, Question frames, Polite softeners
A35: Stage 3 · Skim the basics | B35: Quick check of Levels 1–2; these learners often know them already. Types: Openers & closers, Fixed expressions, Short replies, Sentence frames, Grammatical chunks, Opinion
A36: Stage 4 · Collocations & natural speech | B36: Joins the research order at Level 3. Types: Collocations, Polywords, Phrasal verbs, Topic, Reactions, Agreeing & disagreeing, Binomials
A37: Stage 5 · Connectors | B37: Link short sentences into longer speech. Types: Discourse markers
A38: Stage 6 · Idioms | B38: Understand first, use last. Types: Idioms, Proverbs & sayings
A39: On demand · Goal-based | B39: Add when a real need appears: interview, phone, email. Types: Situational, Formal & written

Sheet Path A – Beginner
A1: Path A # | B1: Path A: Beginner | C1: Path B # | D1: Path B: Knows grammar, can't speak | E1: Chunk | F1: Type | G1: CEFR | H1: Slot | I1: Example / When to use | J1: Meaning / Watch out | K1: Gap-fill question | L1: Answer
A2: 1 | B2: Level 1 · Survival chunks | C2: 1 | D2: Stage 1 · Unfreeze | E2: Sorry, could you say that again? | F2: Clarification & repair | G2: A1 | H2: No slot | I2: When you missed what someone said | K2: You didn't hear the teacher. Say: "Sorry, could you say that ___?" | L2: again
A3: 2 | B3: Level 1 · Survival chunks | C3: 44 | D3: Stage 3 · Skim the basics | E3: How's it going? | F3: Openers & closers | G3: A1 | H3: No slot | I3: Hi Ravi, how's it going? | K3: Hi Ravi, how's it ___? | L3: going
A4: 3 | B4: Level 1 · Survival chunks | C4: 45 | D4: Stage 3 · Skim the basics | E4: Nice to meet you. | F4: Openers & closers | G4: A1 | H4: No slot | I4: I'm Sana. Nice to meet you. | K4: I'm Sana. Nice to ___ you. | L4: meet
A5: 4 | B5: Level 1 · Survival chunks | C5: 46 | D5: Stage 3 · Skim the basics | E5: What do you do? | F5: Openers & closers | G5: A1 | H5: No slot | I5: Asking about someone's job | J5: Means 'What is your job?', not 'What are you doing now?' | K5: You want to know someone's job. Ask: "What do you ___?" | L5: do
A6: 5 | B6: Level 1 · Survival chunks | C6: 47 | D6: Stage 3 · Skim the basics | E6: No problem. | F6: Fixed expressions | G6: A1 | H6: No slot | I6: Replying to thanks or a request | K6: "Thanks for waiting." "No ___." | L6: problem
A7: 6 | B7: Level 1 · Survival chunks | C7: 48 | D7: Stage 3 · Skim the basics | E7: You're welcome. | F7: Fixed expressions | G7: A1 | H7: No slot | I7: Replying to "thank you" | K7: "Thank you!" "You're ___." | L7: welcome
A8: 7 | B8: Level 1 · Survival chunks | C8: 49 | D8: Stage 3 · Skim the basics | E8: Good luck! | F8: Fixed expressions | G8: A1 | H8: No slot | I8: Before someone's exam or interview | K8: Your friend has an interview today. Say: "Good ___!" | L8: luck
A9: 8 | B9: Level 1 · Survival chunks | C9: 50 | D9: Stage 3 · Skim the basics | E9: Take care. | F9: Fixed expressions | G9: A1 | H9: No slot | I9: Ending a call or meeting | K9: Ending a call: "Bye, take ___." | L9: care
A10: 9 | B10: Level 1 · Survival chunks | C10: 51 | D10: Stage 3 · Skim the basics | E10: Same to you. | F10: Fixed expressions | G10: A1 | H10: No slot | I10: Returning a wish ("Happy Diwali!") | K10: "Happy Diwali!" "Same ___ you." | L10: to
A11: 10 | B11: Level 1 · Survival chunks | C11: 52 | D11: Stage 3 · Skim the basics | E11: I hope so. | F11: Short replies | G11: A1 | H11: No slot | I11: "Will it be sunny tomorrow?" "I hope so." | J11: Not "I hope yes" | K11: "Will it be sunny tomorrow?" "I hope ___." | L11: so
A12: 11 | B12: Level 1 · Survival chunks | C12: 53 | D12: Stage 3 · Skim the basics | E12: I don't think so. | F12: Short replies | G12: A1 | H12: No slot | I12: "Is the shop open?" "I don't think so." | J12: Not "I think no" | K12: "Is the shop open?" "I don't think ___." | L12: so
A13: 12 | B13: Level 1 · Survival chunks | C13: 54 | D13: Stage 3 · Skim the basics | E13: Not yet. | F13: Short replies | G13: A1 | H13: No slot | I13: "Have you eaten?" "Not yet." | K13: "Have you eaten?" "Not ___." | L13: yet
A14: 13 | B14: Level 1 · Survival chunks | C14: 55 | D14: Stage 3 · Skim the basics | E14: Sure, go ahead. | F14: Short replies | G14: A1 | H14: No slot | I14: "Can I use your phone?" "Sure, go ahead." | K14: "Can I use your phone?" "Sure, go ___." | L14: ahead
A15: 14 | B15: Level 1 · Survival chunks | C15: 4 | D15: Stage 1 · Unfreeze | E15: What do you mean by…? | F15: Clarification & repair | G15: A2 | H15: noun | I15: What do you mean by 'deadline'? | K15: What do you ___ by 'deadline'? | L15: mean
A16: 15 | B16: Level 1 · Survival chunks | C16: 61 | D16: Stage 3 · Skim the basics | E16: Never mind. | F16: Fixed expressions | G16: A2 | H16: No slot | I16: It's not important, forget it. | K16: "Sorry, what did you say?" "Oh, never ___. It's not important." | L16: mind
A17: 16 | B17: Level 1 · Survival chunks | C17: 62 | D17: Stage 3 · Skim the basics | E17: It depends. | F17: Fixed expressions | G17: A2 | H17: No slot | I17: When the answer isn't yes or no | K17: "Is it far?" "It ___. By car, no. On foot, yes." | L17: depends
A18: 17 | B18: Level 1 · Survival chunks | C18: 63 | D18: Stage 3 · Skim the basics | E18: Sounds good. | F18: Short replies | G18: A2 | H18: No slot | I18: "Let's meet at six." "Sounds good." | K18: "Let's meet at six." "Sounds ___." | L18: good
A19: 18 | B19: Level 1 · Survival chunks | C19: 64 | D19: Stage 3 · Skim the basics | E19: I guess so. | F19: Short replies | G19: A2 | H19: No slot | I19: "Is this the right bus?" "I guess so." | K19: "Is this the right bus?" "I ___ so." | L19: guess (think also works)
A20: 19 | B20: Level 1 · Survival chunks | C20: 65 | D20: Stage 3 · Skim the basics | E20: Not really. | F20: Short replies | G20: A2 | H20: No slot | I20: "Are you tired?" "Not really." | K20: "Are you tired?" "Not ___." | L20: really
A21: 20 | B21: Level 1 · Survival chunks | C21: 66 | D21: Stage 3 · Skim the basics | E21: I'd love to. | F21: Short replies | G21: A2 | H21: No slot | I21: "Want to join us for dinner?" "I'd love to." | K21: "Want to join us for dinner?" "I'd ___ to." | L21: love
A22: 21 | B22: Level 1 · Survival chunks | C22: 67 | D22: Stage 3 · Skim the basics | E22: Why not? | F22: Short replies | G22: A2 | H22: No slot | I22: "Shall we try the new café?" "Why not?" | J22: Here = yes, let's | K22: "Shall we try the new café?" "Why ___?" | L22: not
A23: 22 | B23: Level 1 · Survival chunks | C23: 6 | D23: Stage 1 · Unfreeze | E23: Let me put it another way. | F23: Clarification & repair | G23: B1 | H23: No slot | I23: When your first sentence came out wrong | K23: Your sentence came out wrong. Say: "Let me put it ___ way." | L23: another
A24: 23 | B24: Level 1 · Survival chunks | C24: 7 | D24: Stage 1 · Unfreeze | E24: I'm not sure how to say this, but… | F24: Clarification & repair | G24: B1 | H24: clause | I24: …but I think we need more time. | K24: I'm not sure how to ___ this, but I think we need more time. | L24: say
A25: 24 | B25: Level 1 · Survival chunks | C25: 82 | D25: Stage 3 · Skim the basics | E25: It's up to you. | F25: Fixed expressions | G25: B1 | H25: No slot | I25: Letting the other person decide | K25: "Tea or coffee?" "I don't mind. It's up ___ you." | L25: to
A26: 25 | B26: Level 1 · Survival chunks | C26: 83 | D26: Stage 3 · Skim the basics | E26: I'm afraid not. | F26: Fixed expressions | G26: B1 | H26: No slot | I26: A polite "no" | K26: "Is there any milk left?" "I'm ___ not." | L26: afraid
A27: 26 | B27: Level 1 · Survival chunks | C27: 84 | D27: Stage 3 · Skim the basics | E27: Better late than never. | F27: Fixed expressions | G27: B1 | H27: No slot | I27: When something finally happens | K27: Better late ___ never. | L27: than
A28: 27 | B28: Level 1 · Survival chunks | C28: 85 | D28: Stage 3 · Skim the basics | E28: Fair enough. | F28: Short replies | G28: B1 | H28: No slot | I28: "I can't come; I have an exam." "Fair enough." | J28: Means: that's reasonable | K28: "I can't come; I have an exam." "Fair ___." | L28: enough
A29: 28 | B29: Level 2 · Slot stems | C29: 56 | D29: Stage 3 · Skim the basics | E29: Let's… | F29: Sentence frames | G29: A1 | H29: base verb | I29: Let's meet at six. | K29: Let's ___ (meet) at six. | L29: meet
A30: 29 | B30: Level 2 · Slot stems | C30: 57 | D30: Stage 3 · Skim the basics | E30: I need to… | F30: Sentence frames | G30: A1 | H30: base verb | I30: I need to buy a new phone. | K30: I need ___ (buy) a new phone. | L30: to buy
A31: 30 | B31: Level 2 · Slot stems | C31: 12 | D31: Stage 2 · Fix errors people notice | E31: Can you help me with…? | F31: Question frames | G31: A1 | H31: noun | I31: Can you help me with this bag? | K31: Can you help me ___ this bag? | L31: with
A32: 31 | B32: Level 2 · Slot stems | C32: 13 | D32: Stage 2 · Fix errors people notice | E32: What time does…? | F32: Question frames | G32: A1 | H32: base verb | I32: What time does the shop open? | J32: Not "What time the shop opens?" | K32: What time ___ the shop open? | L32: does
A33: 32 | B33: Level 2 · Slot stems | C33: 14 | D33: Stage 2 · Fix errors people notice | E33: How much is / are…? | F33: Question frames | G33: A1 | H33: noun | I33: How much are these shoes? | J33: Not "How much these shoes?" | K33: How much ___ these shoes? | L33: are
A34: 33 | B34: Level 2 · Slot stems | C34: 15 | D34: Stage 2 · Fix errors people notice | E34: Where can I…? | F34: Question frames | G34: A1 | H34: base verb | I34: Where can I buy a SIM card? | J34: Not "Where I can buy…?" | K34: Put in order (I / can / where): "___ buy a SIM card?" | L34: Where can I
A35: 34 | B35: Level 2 · Slot stems | C35: 58 | D35: Stage 3 · Skim the basics | E35: I'm going to… | F35: Grammatical chunks | G35: A1 | H35: base verb | I35: I'm going to visit my uncle. | J35: Future plan | K35: I'm going ___ (visit) my uncle. | L35: to visit
A36: 35 | B36: Level 2 · Slot stems | C36: 59 | D36: Stage 3 · Skim the basics | E36: There is / There are… | F36: Grammatical chunks | G36: A1 | H36: noun | I36: There are two banks near my house. | J36: Singular vs plural | K36: There ___ two banks near my house. | L36: are
A37: 36 | B37: Level 2 · Slot stems | C37: 60 | D37: Stage 3 · Skim the basics | E37: I think… | F37: Opinion | G37: A1 | H37: clause | I37: I think this plan is good. | K37: Give your opinion: "I ___ this plan is good." | L37: think
A38: 37 | B38: Level 2 · Slot stems | C38: 16 | D38: Stage 2 · Fix errors people notice | E38: Could I…? | F38: Polite softeners | G38: A1 | H38: base verb | I38: Could I borrow a pen? | J38: Too direct: "Give me a pen." | K38: Ask politely: "___ I borrow a pen?" | L38: Could (May also works)
A39: 38 | B39: Level 2 · Slot stems | C39: 17 | D39: Stage 2 · Fix errors people notice | E39: Would you like…? | F39: Polite softeners | G39: A1 | H39: noun or to + verb | I39: Would you like some tea? | J39: Too direct: "Take tea." | K39: Would you ___ some tea? | L39: like
A40: 39 | B40: Level 2 · Slot stems | C40: 68 | D40: Stage 3 · Skim the basics | E40: So, tell me about… | F40: Sentence frames | G40: A2 | H40: noun | I40: So, tell me about your new job. | K40: So, tell me ___ your new job. | L40: about
...

Sheet Path B – Knows Grammar
A1: Path A # | B1: Path A: Beginner | C1: Path B # | D1: Path B: Knows grammar, can't speak | E1: Chunk | F1: Type | G1: CEFR | H1: Slot | I1: Example / When to use | J1: Meaning / Watch out | K1: Gap-fill question | L1: Answer
A2: 1 | B2: Level 1 · Survival chunks | C2: 1 | D2: Stage 1 · Unfreeze | E2: Sorry, could you say that again? | F2: Clarification & repair | G2: A1 | H2: No slot | I2: When you missed what someone said | K2: You didn't hear the teacher. Say: "Sorry, could you say that ___?" | L2: again
A3: 93 | B3: Level 3 · Collocations & fillers | C3: 2 | D3: Stage 1 · Unfreeze | E3: Let me think. | F3: Fillers & time-buyers | G3: A1 | H3: No slot | I3: Before answering a question | K3: Someone asks a hard question. Buy time: "Let me ___." | L3: think
A4: 94 | B4: Level 3 · Collocations & fillers | C4: 3 | D4: Stage 1 · Unfreeze | E4: Give me a second. | F4: Fillers & time-buyers | G4: A1 | H4: No slot | I4: While you find a word or a paper | K4: You need a moment to find a word. Say: "Give me a ___." | L4: second
A5: 14 | B5: Level 1 · Survival chunks | C5: 4 | D5: Stage 1 · Unfreeze | E5: What do you mean by…? | F5: Clarification & repair | G5: A2 | H5: noun | I5: What do you mean by 'deadline'? | K5: What do you ___ by 'deadline'? | L5: mean
A6: 122 | B6: Level 3 · Collocations & fillers | C6: 5 | D6: Stage 1 · Unfreeze | E6: That's a good question. | F6: Fillers & time-buyers | G6: A2 | H6: No slot | I6: Gives you 2–3 seconds to plan | K6: "Why did you choose this job?" "That's a good ___." | L6: question
A7: 22 | B7: Level 1 · Survival chunks | C7: 6 | D7: Stage 1 · Unfreeze | E7: Let me put it another way. | F7: Clarification & repair | G7: B1 | H7: No slot | I7: When your first sentence came out wrong | K7: Your sentence came out wrong. Say: "Let me put it ___ way." | L7: another
A8: 23 | B8: Level 1 · Survival chunks | C8: 7 | D8: Stage 1 · Unfreeze | E8: I'm not sure how to say this, but… | F8: Clarification & repair | G8: B1 | H8: clause | I8: …but I think we need more time. | K8: I'm not sure how to ___ this, but I think we need more time. | L8: say
A9: 156 | B9: Level 3 · Collocations & fillers | C9: 8 | D9: Stage 1 · Unfreeze | E9: The thing is,… | F9: Fillers & time-buyers | G9: B1 | H9: clause | I9: The thing is, I don't have much time today. | K9: The ___ is, I don't have much time today. | L9: thing
A10: 98 | B10: Level 3 · Collocations & fillers | C10: 9 | D10: Stage 2 · Fix errors people notice | E10: listen to | F10: Dependent prepositions | G10: A1 | H10: No slot | I10: I listen to music every day. | J10: Not "listen music" | K10: I listen ___ music every day. | L10: to
A11: 99 | B11: Level 3 · Collocations & fillers | C11: 10 | D11: Stage 2 · Fix errors people notice | E11: wait for | F11: Dependent prepositions | G11: A1 | H11: No slot | I11: I'm waiting for the bus. | J11: Not "waiting the bus" | K11: I'm waiting ___ the bus. | L11: for
A12: 100 | B12: Level 3 · Collocations & fillers | C12: 11 | D12: Stage 2 · Fix errors people notice | E12: good at | F12: Dependent prepositions | G12: A1 | H12: No slot | I12: She's good at maths. | J12: Not "good in maths" | K12: She's good ___ maths. | L12: at
A13: 30 | B13: Level 2 · Slot stems | C13: 12 | D13: Stage 2 · Fix errors people notice | E13: Can you help me with…? | F13: Question frames | G13: A1 | H13: noun | I13: Can you help me with this bag? | K13: Can you help me ___ this bag? | L13: with
A14: 31 | B14: Level 2 · Slot stems | C14: 13 | D14: Stage 2 · Fix errors people notice | E14: What time does…? | F14: Question frames | G14: A1 | H14: base verb | I14: What time does the shop open? | J14: Not "What time the shop opens?" | K14: What time ___ the shop open? | L14: does
A15: 32 | B15: Level 2 · Slot stems | C15: 14 | D15: Stage 2 · Fix errors people notice | E15: How much is / are…? | F15: Question frames | G15: A1 | H15: noun | I15: How much are these shoes? | J15: Not "How much these shoes?" | K15: How much ___ these shoes? | L15: are
A16: 33 | B16: Level 2 · Slot stems | C16: 15 | D16: Stage 2 · Fix errors people notice | E16: Where can I…? | F16: Question frames | G16: A1 | H16: base verb | I16: Where can I buy a SIM card? | J16: Not "Where I can buy…?" | K16: Put in order (I / can / where): "___ buy a SIM card?" | L16: Where can I
A17: 37 | B17: Level 2 · Slot stems | C17: 16 | D17: Stage 2 · Fix errors people notice | E17: Could I…? | F17: Polite softeners | G17: A1 | H17: base verb | I17: Could I borrow a pen? | J17: Too direct: "Give me a pen." | K17: Ask politely: "___ I borrow a pen?" | L17: Could (May also works)
A18: 38 | B18: Level 2 · Slot stems | C18: 17 | D18: Stage 2 · Fix errors people notice | E18: Would you like…? | F18: Polite softeners | G18: A1 | H18: noun or to + verb | I18: Would you like some tea? | J18: Too direct: "Take tea." | K18: Would you ___ some tea? | L18: like
A19: 130 | B19: Level 3 · Collocations & fillers | C19: 18 | D19: Stage 2 · Fix errors people notice | E19: interested in | F19: Dependent prepositions | G19: A2 | H19: No slot | I19: I'm interested in photography. | J19: Not "interested for" | K19: I'm interested ___ photography. | L19: in
A20: 131 | B20: Level 3 · Collocations & fillers | C20: 19 | D20: Stage 2 · Fix errors people notice | E20: married to | F20: Dependent prepositions | G20: A2 | H20: No slot | I20: He's married to my cousin. | J20: Not "married with" | K20: He's married ___ my cousin. | L20: to
A21: 132 | B21: Level 3 · Collocations & fillers | C21: 20 | D21: Stage 2 · Fix errors people notice | E21: explain (it) to (someone) | F21: Dependent prepositions | G21: A2 | H21: noun | I21: Can you explain this to me? | J21: Not "explain me this" | K21: Can you explain this ___ me? | L21: to
A22: 133 | B22: Level 3 · Collocations & fillers | C22: 21 | D22: Stage 2 · Fix errors people notice | E22: reach + place (no preposition) | F22: Dependent prepositions | G22: A2 | H22: noun | I22: We reached the station at six. | J22: Not "reached to the station" | K22: We reached ___ the station at six. (to / at / no word) | L22: (no word)
A23: 134 | B23: Level 3 · Collocations & fillers | C23: 22 | D23: Stage 2 · Fix errors people notice | E23: enter + place (no preposition) | F23: Dependent prepositions | G23: A2 | H23: noun | I23: She entered the room quietly. | J23: Not "entered into the room" | K23: She entered ___ the room quietly. (into / in / no word) | L23: (no word)
A24: 47 | B24: Level 2 · Slot stems | C24: 23 | D24: Stage 2 · Fix errors people notice | E24: Do you want me to…? | F24: Question frames | G24: A2 | H24: base verb | I24: Do you want me to call him? | K24: Do you want me ___ (call) him? | L24: to call
A25: 48 | B25: Level 2 · Slot stems | C25: 24 | D25: Stage 2 · Fix errors people notice | E25: What are you doing this weekend? | F25: Question frames | G25: A2 | H25: No slot | I25: Easy small talk | J25: Present continuous for future plans | K25: What are you ___ this weekend? | L25: doing
A26: 49 | B26: Level 2 · Slot stems | C26: 25 | D26: Stage 2 · Fix errors people notice | E26: How long does it take to…? | F26: Question frames | G26: A2 | H26: base verb | I26: How long does it take to get to the airport? | J26: Not "How much time it takes…?" | K26: How long does it ___ to get to the airport? | L26: take
A27: 50 | B27: Level 2 · Slot stems | C27: 26 | D27: Stage 2 · Fix errors people notice | E27: What's … like? | F27: Question frames | G27: A2 | H27: noun | I27: What's your new boss like? | J27: Not "How is your boss like?" | K27: What's your new boss ___? | L27: like
A28: 51 | B28: Level 2 · Slot stems | C28: 27 | D28: Stage 2 · Fix errors people notice | E28: How often do you…? | F28: Question frames | G28: A2 | H28: base verb | I28: How often do you exercise? | J28: Not "How many times you exercise?" | K28: How ___ do you exercise? | L28: often
A29: 52 | B29: Level 2 · Slot stems | C29: 28 | D29: Stage 2 · Fix errors people notice | E29: What do you think about…? | F29: Question frames | G29: A2 | H29: noun or -ing verb | I29: What do you think about online classes? | J29: Not "What you think about…?" | K29: What ___ you think about online classes? | L29: do
A30: 53 | B30: Level 2 · Slot stems | C30: 29 | D30: Stage 2 · Fix errors people notice | E30: Why don't we…? | F30: Question frames | G30: A2 | H30: base verb | I30: Why don't we order pizza? | J30: A friendly suggestion, not a complaint | K30: Suggest a plan: "Why ___ we order pizza?" | L30: don't
A31: 60 | B31: Level 2 · Slot stems | C31: 30 | D31: Stage 2 · Fix errors people notice | E31: Could you please…? | F31: Polite softeners | G31: A2 | H31: base verb | I31: Could you please send the file? | K31: Could you please ___ (send) the file? | L31: send
A32: 61 | B32: Level 2 · Slot stems | C32: 31 | D32: Stage 2 · Fix errors people notice | E32: I'd like to… | F32: Polite softeners | G32: A2 | H32: base verb | I32: I'd like to ask a question. | J32: Too direct: "I want to ask a question." | K32: I'd like ___ (ask) a question. | L32: to ask
A33: 62 | B33: Level 2 · Slot stems | C33: 32 | D33: Stage 2 · Fix errors people notice | E33: Do you mind if I…? | F33: Polite softeners | G33: A2 | H33: base verb | I33: Do you mind if I open the window? | J33: To say yes, answer "No, not at all." | K33: Do you mind if I ___ (open) the window? | L33: open
A34: 63 | B34: Level 2 · Slot stems | C34: 33 | D34: Stage 2 · Fix errors people notice | E34: Sorry to bother you, but… | F34: Polite softeners | G34: A2 | H34: clause | I34: Sorry to bother you, but where's the lift? | J34: Too direct: "Where is the lift?" | K34: Sorry to ___ you, but where's the lift? | L34: bother
A35: 64 | B35: Level 2 · Slot stems | C35: 34 | D35: Stage 2 · Fix errors people notice | E35: Just a quick question:… | F35: Polite softeners | G35: A2 | H35: clause | I35: Just a quick question: when is the meeting? | J35: Too direct: "Tell me the meeting time." | K35: Just a ___ question: when is the meeting? | L35: quick
A36: 162 | B36: Level 3 · Collocations & fillers | C36: 35 | D36: Stage 2 · Fix errors people notice | E36: discuss + topic (no preposition) | F36: Dependent prepositions | G36: B1 | H36: noun | I36: Let's discuss the plan. | J36: Not "discuss about the plan" | K36: Let's discuss ___ the plan. (about / on / no word) | L36: (no word)
A37: 163 | B37: Level 3 · Collocations & fillers | C37: 36 | D37: Stage 2 · Fix errors people notice | E37: insist on + -ing | F37: Dependent prepositions | G37: B1 | H37: -ing verb | I37: He insisted on paying. | J37: Not "insisted to pay" | K37: He insisted ___ (pay) for dinner. | L37: on paying
A38: 68 | B38: Level 2 · Slot stems | C38: 37 | D38: Stage 2 · Fix errors people notice | E38: What made you…? | F38: Question frames | G38: B1 | H38: base verb | I38: What made you choose teaching? | J38: Not "Why you chose teaching?" | K38: What made you ___ (choose) teaching? | L38: choose
A39: 69 | B39: Level 2 · Slot stems | C39: 38 | D39: Stage 2 · Fix errors people notice | E39: …, isn't it? / …, don't you? | F39: Question frames | G39: B1 | H39: matching tag | I39: It's hot, isn't it? / You like tea, don't you? | J39: The tag must match the verb: not "You like tea, isn't it?" | K39: You like tea, ___ you? | L39: don't
A40: 77 | B40: Level 2 · Slot stems | C40: 39 | D40: Stage 2 · Fix errors people notice | E40: Would you mind + -ing…? | F40: Polite softeners | G40: B1 | H40: -ing verb | I40: Would you mind closing the window? | J40: Verb takes -ing: not "mind to close" | K40: Would you mind ___ (close) the window? | L40: closing
...

Sheet Summary
A1: Path A: Beginner
A2: Stage | B2: Types included | C2: Chunks
A3: Level 1 · Survival chunks | B3: Clarification & repair, Openers & closers, Fixed expressions, Short replies | C3: =COUNTIF('Path A – Beginner'!$B$2:$B$221,A3) -> 27
A4: Level 2 · Slot stems | B4: Sentence frames, Question frames, Grammatical chunks, Opinion, Polite softeners | C4: =COUNTIF('Path A – Beginner'!$B$2:$B$221,A4) -> 54
A5: Level 3 · Collocations & fillers | B5: Collocations, Polywords, Fillers & time-buyers, Phrasal verbs, Dependent prepositions, Topic, Reactions, Agreeing & disagreeing, Binomials | C5: =COUNTIF('Path A – Beginner'!$B$2:$B$221,A5) -> 89
A6: Level 4 · Connectors | B6: Discourse markers | C6: =COUNTIF('Path A – Beginner'!$B$2:$B$221,A6) -> 10
A7: Level 5 · Idioms | B7: Idioms, Proverbs & sayings | C7: =COUNTIF('Path A – Beginner'!$B$2:$B$221,A7) -> 20
A8: On demand · Goal-based | B8: Situational, Formal & written | C8: =COUNTIF('Path A – Beginner'!$B$2:$B$221,A8) -> 20
A9: Total | C9: =SUM(C3:C8) -> 220
A11: Path B: Knows grammar, can't speak
A12: Stage | B12: Types included | C12: Chunks
A13: Stage 1 · Unfreeze | B13: Clarification & repair, Fillers & time-buyers | C13: =COUNTIF('Path A – Beginner'!$D$2:$D$221,A13) -> 8
A14: Stage 2 · Fix errors people notice | B14: Dependent prepositions, Question frames, Polite softeners | C14: =COUNTIF('Path A – Beginner'!$D$2:$D$221,A14) -> 35
A15: Stage 3 · Skim the basics | B15: Openers & closers, Fixed expressions, Short replies, Sentence frames, Grammatical chunks, Opinion | C15: =COUNTIF('Path A – Beginner'!$D$2:$D$221,A15) -> 52
A16: Stage 4 · Collocations & natural speech | B16: Collocations, Polywords, Phrasal verbs, Topic, Reactions, Agreeing & disagreeing, Binomials | C16: =COUNTIF('Path A – Beginner'!$D$2:$D$221,A16) -> 75
A17: Stage 5 · Connectors | B17: Discourse markers | C17: =COUNTIF('Path A – Beginner'!$D$2:$D$221,A17) -> 10
A18: Stage 6 · Idioms | B18: Idioms, Proverbs & sayings | C18: =COUNTIF('Path A – Beginner'!$D$2:$D$221,A18) -> 20
A19: On demand · Goal-based | B19: Situational, Formal & written | C19: =COUNTIF('Path A – Beginner'!$D$2:$D$221,A19) -> 20
A20: Total | C20: =SUM(C13:C19) -> 220
A22: Chunks per type
A23: Type | C23: Chunks
A24: Clarification & repair | C24: =COUNTIF('Path A – Beginner'!$F$2:$F$221,A24) -> 4
A25: Openers & closers | C25: =COUNTIF('Path A – Beginner'!$F$2:$F$221,A25) -> 3
A26: Fixed expressions | C26: =COUNTIF('Path A – Beginner'!$F$2:$F$221,A26) -> 10
A27: Short replies | C27: =COUNTIF('Path A – Beginner'!$F$2:$F$221,A27) -> 10
A28: Sentence frames | C28: =COUNTIF('Path A – Beginner'!$F$2:$F$221,A28) -> 13
A29: Question frames | C29: =COUNTIF('Path A – Beginner'!$F$2:$F$221,A29) -> 13
A30: Grammatical chunks | C30: =COUNTIF('Path A – Beginner'!$F$2:$F$221,A30) -> 13
A31: Opinion | C31: =COUNTIF('Path A – Beginner'!$F$2:$F$221,A31) -> 3
A32: Polite softeners | C32: =COUNTIF('Path A – Beginner'!$F$2:$F$221,A32) -> 12
A33: Collocations | C33: =COUNTIF('Path A – Beginner'!$F$2:$F$221,A33) -> 23
A34: Polywords | C34: =COUNTIF('Path A – Beginner'!$F$2:$F$221,A34) -> 10
A35: Fillers & time-buyers | C35: =COUNTIF('Path A – Beginner'!$F$2:$F$221,A35) -> 4
... A46: Formal & written | C46: =COUNTIF('Path A – Beginner'!$F$2:$F$221,A46) -> 10
A47: Total | C47: =SUM(C24:C46) -> 220
A49: Chunks per slot
A50: Slot | C50: Chunks
A51: base verb | C51: =COUNTIF('Path A – Beginner'!$H$2:$H$221,A51) -> 27
A52: noun | C52: =COUNTIF('Path A – Beginner'!$H$2:$H$221,A52) -> 18
A53: clause | C53: =COUNTIF('Path A – Beginner'!$H$2:$H$221,A53) -> 12
...
