Workbook

Sheet Read Me
A1: 100 Hindi → English Sentence Frames
A3: What this is | B3: 100 fill-in-the-blank frames (discontinuous chunks) like "main ___ raha hoon" → "I am ___ing". Each Hindi frame sits next to its English twin, so the learner reuses a frame they already have and only learns where the blank goes in English.
A4: How it's organised | B4: 10 groups of 10: Present, Past, Future & plans, Can/must/should, Wants & feelings, Questions, Comparing & pairs, Linking ideas, Polite & social, Opinions & everyday. Within each group, easiest first (A1 → A2 → B1).
A6: Columns
A7: Hindi frame / English frame | B7: The two twins. ___ marks the blank. Hindi is in Roman script (Hinglish).
A8: Slot | B8: What goes in the English blank: base verb, -ing verb, past participle, noun, clause, etc.
A9: Hindi example / English example | B9: One full sentence each. Use as a speaking drill: learner reads the Hindi and says the English aloud.
A10: Watch out | B10: The most common error Indian learners make with that frame, where there is one.
A11: Also in the 220 list | B11: The matching chunk from the 220-chunk workbook, when there is one. Blank = new frame.
A13: Sheets
A14: Frames | B14: All 100 frames, with filters on the header row.
A15: Summary | B15: Live counts by group, level and slot (formulas).
A17: Judgement calls
A18: Levels | B18: A1/A2/B1 tags are estimates, not taken from an official CEFR list.
A19: Hindi wording | B19: Frames use everyday spoken Hindi, not formal Hindi. Some frames have more than one natural Hindi version; one common version is given.
A20: One-to-one mapping | B20: Hindi and English don't always match one-to-one. Notes in Watch out flag the tricky ones (e.g. "mujhe ___na hai" can mean "I have to" or "I want to").

Sheet Frames
A1: # | B1: Group | C1: Hindi frame | D1: English frame | E1: Slot | F1: Level | G1: Hindi example | H1: English example | I1: Watch out | J1: Also in the 220 list
A2: 1 | B2: 1. Present | C2: main ___ raha hoon | D2: I am ___ing | E2: -ing verb | F2: A1 | G2: Main khana kha raha hoon. | H2: I am eating. | I2: Not "I eating": am is needed
A3: 2 | B3: 1. Present | C3: main roz ___ta hoon | D3: I ___ every day | E3: base verb | F3: A1 | G3: Main roz chai peeta hoon. | H3: I drink tea every day. | I3: Not "I am drinking tea every day" for a habit
A4: 3 | B4: 1. Present | C4: woh ___ta hai | D4: He / She ___s | E4: verb + s | F4: A1 | G4: Woh school jaata hai. | H4: He goes to school. | I4: Not "He go": add -s
A5: 4 | B5: 1. Present | C5: main ___ nahi ___ta | D5: I don't ___ | E5: base verb | F5: A1 | G5: Main coffee nahi peeta. | H5: I don't drink coffee. | I5: Not "I not drink"
A6: 5 | B6: 1. Present | C6: kya tum ___te ho? | D6: Do you ___? | E6: base verb | F6: A1 | G6: Kya tum cricket khelte ho? | H6: Do you play cricket? | I6: Not "Are you play cricket?"
A7: 6 | B7: 1. Present | C7: woh abhi ___ raha hai | D7: He is ___ing right now | E7: -ing verb | F7: A1 | G7: Woh abhi so raha hai. | H7: He is sleeping right now.
A8: 7 | B8: 1. Present | C8: kya tum ___ rahe ho? | D8: Are you ___ing? | E8: -ing verb | F8: A1 | G8: Kya tum sun rahe ho? | H8: Are you listening?
A9: 8 | B9: 1. Present | C9: main ___ nahi raha hoon | D9: I am not ___ing | E9: -ing verb | F9: A2 | G9: Main so nahi raha hoon. | H9: I'm not sleeping.
A10: 9 | B10: 1. Present | C10: main subah se ___ raha hoon | D10: I have been ___ing since morning | E10: -ing verb | F10: B1 | G10: Main subah se padh raha hoon. | H10: I have been studying since morning. | I10: Not "I am studying since morning" | J10: I have been + -ing for/since…
A11: 10 | B11: 1. Present | C11: main ___ta rehta hoon | D11: I keep ___ing | E11: -ing verb | F11: B1 | G11: Main naam bhoolta rehta hoon. | H11: I keep forgetting names. | I11: Not "I keep forget"
A12: 11 | B12: 2. Past | C12: maine ___ kiya | D12: I ___ed | E12: past verb | F12: A1 | G12: Maine kaam khatam kiya. | H12: I finished the work. | I12: Not "I did finished"
A13: 12 | B13: 2. Past | C13: maine ___ nahi kiya | D13: I didn't ___ | E13: base verb | F13: A1 | G13: Maine usse nahi dekha. | H13: I didn't see him. | I13: Not "I didn't saw"
A14: 13 | B14: 2. Past | C14: kya tumne ___ kiya? | D14: Did you ___? | E14: base verb | F14: A1 | G14: Kya tumne homework kiya? | H14: Did you do your homework? | I14: Not "Did you did…?"
A15: 14 | B15: 2. Past | C15: main ___ raha tha | D15: I was ___ing | E15: -ing verb | F15: A2 | G15: Main TV dekh raha tha. | H15: I was watching TV.
A16: 15 | B16: 2. Past | C16: main pehle ___ta tha | D16: I used to ___ | E16: base verb | F16: A2 | G16: Main pehle cricket khelta tha. | H16: I used to play cricket. | I16: Not "I was used to play" | J16: I used to…
A17: 16 | B17: 2. Past | C17: main ___ chuka hoon | D17: I have ___ | E17: past participle | F17: A2 | G17: Main khana kha chuka hoon. | H17: I have eaten. | I17: Not "I have ate"
A18: 17 | B18: 2. Past | C18: maine abhi-abhi ___ hai | D18: I have just ___ | E18: past participle | F18: A2 | G18: Maine abhi-abhi email bheja hai. | H18: I have just sent the email.
A19: 18 | B19: 2. Past | C19: maine kabhi ___ nahi kiya | D19: I have never ___ | E19: past participle | F19: A2 | G19: Maine kabhi sushi nahi khaya. | H19: I have never eaten sushi. | J19: I have never…
A20: 19 | B20: 2. Past | C20: jab main ___ raha tha, tab ___ | D20: While I was ___ing, ___ | E20: -ing verb + clause | F20: B1 | G20: Jab main naha raha tha, tab phone baja. | H20: While I was taking a shower, the phone rang.
A21: 20 | B21: 2. Past | C21: mere pahunchne se pehle hi ___ chuka tha | D21: ___ had already ___ before I arrived | E21: noun + past participle | F21: B1 | G21: Mere pahunchne se pehle hi train ja chuki thi. | H21: The train had already left before I arrived.
A22: 21 | B22: 3. Future & plans | C22: main kal ___unga | D22: I will ___ tomorrow | E22: base verb | F22: A1 | G22: Main kal call karunga. | H22: I will call tomorrow.
A23: 22 | B23: 3. Future & plans | C23: kya tum ___oge? | D23: Will you ___? | E23: base verb | F23: A1 | G23: Kya tum meri madad karoge? | H23: Will you help me?
A24: 23 | B24: 3. Future & plans | C24: main ___ne ja raha hoon | D24: I am going to ___ | E24: base verb | F24: A1 | G24: Main naukri badalne ja raha hoon. | H24: I am going to change my job. | J24: I'm going to…
A25: 24 | B25: 3. Future & plans | C25: main ___ne wala hoon | D25: I am about to ___ | E25: base verb | F25: A2 | G25: Main nikalne wala hoon. | H25: I'm about to leave. | J25: I was about to… (past form)
A26: 25 | B26: 3. Future & plans | C26: mera ___ne ka plan hai | D26: I'm planning to ___ | E26: base verb | F26: A2 | G26: Mera Goa jaane ka plan hai. | H26: I'm planning to go to Goa. | J26: I'm planning to…
A27: 26 | B27: 3. Future & plans | C27: main ___ne ki koshish karunga | D27: I will try to ___ | E27: base verb | F27: A2 | G27: Main jaldi aane ki koshish karunga. | H27: I'll try to come early. | J27: I'm trying to… (present form)
A28: 27 | B28: 3. Future & plans | C28: agar ___, toh main ___unga | D28: If ___, I will ___ | E28: clause + base verb | F28: A2 | G28: Agar baarish hui, toh main nahi aaunga. | H28: If it rains, I won't come. | I28: Not "If it will rain"
A29: 28 | B29: 3. Future & plans | C29: main ___ne ka soch raha hoon | D29: I'm thinking of ___ing | E29: -ing verb | F29: B1 | G29: Main MBA karne ka soch raha hoon. | H29: I'm thinking of doing an MBA. | I29: Not "I'm thinking to do"
A30: 29 | B30: 3. Future & plans | C30: jaise hi ___, main ___unga | D30: As soon as ___, I will ___ | E30: clause + base verb | F30: B1 | G30: Jaise hi main pahunchunga, tumhe call karunga. | H30: As soon as I arrive, I'll call you. | I30: Not "As soon as I will arrive" | J30: as soon as
A31: 30 | B31: 3. Future & plans | C31: ___ tak main ___ kar lunga | D31: I will have ___ by ___ | E31: past participle + time | F31: B1 | G31: Shaam tak main report khatam kar lunga. | H31: I'll have finished the report by evening.
A32: 31 | B32: 4. Can / must / should | C32: main ___ sakta hoon | D32: I can ___ | E32: base verb | F32: A1 | G32: Main tair sakta hoon. | H32: I can swim. | I32: Not "I can to swim"
A33: 32 | B33: 4. Can / must / should | C33: main ___ nahi sakta | D33: I can't ___ | E33: base verb | F33: A1 | G33: Main aaj nahi aa sakta. | H33: I can't come today.
A34: 33 | B34: 4. Can / must / should | C34: kya main ___ sakta hoon? | D34: May I ___? / Can I ___? | E34: base verb | F34: A1 | G34: Kya main andar aa sakta hoon? | H34: May I come in? | J34: Could I…?
A35: 34 | B35: 4. Can / must / should | C35: mujhe ___na hai | D35: I have to ___ | E35: base verb | F35: A1 | G35: Mujhe bank jaana hai. | H35: I have to go to the bank. | I35: In Hindi this can also mean "I want to": check the context
A36: 35 | B36: 4. Can / must / should | C36: mujhe ___na padega | D36: I will have to ___ | E36: base verb | F36: A2 | G36: Mujhe jaldi uthna padega. | H36: I'll have to get up early.
A37: 36 | B37: 4. Can / must / should | C37: tumhe ___na chahiye | D37: You should ___ | E37: base verb | F37: A2 | G37: Tumhe doctor ko dikhana chahiye. | H37: You should see a doctor. | I37: Not "You should to see"
A38: 37 | B38: 4. Can / must / should | C38: tumhe ___ nahi ___na chahiye | D38: You shouldn't ___ | E38: base verb | F38: A2 | G38: Tumhe der tak nahi jaagna chahiye. | H38: You shouldn't stay up late.
A39: 38 | B39: 4. Can / must / should | C39: main ___ paaya | D39: I managed to ___ | E39: base verb | F39: B1 | G39: Main time par pahunch paaya. | H39: I managed to get there on time.
A40: 39 | B40: 4. Can / must / should | C40: ho sakta hai ki woh ___ | D40: He might ___ | E40: base verb | F40: B1 | G40: Ho sakta hai ki woh late aaye. | H40: He might come late. | I40: Not "He might comes"
...

Sheet Summary
A1: Frames per group
A2: Value | B2: Frames
A3: 1. Present | B3: =COUNTIF(Frames!$B$2:$B$101,A3) -> 10
A4: 2. Past | B4: =COUNTIF(Frames!$B$2:$B$101,A4) -> 10
A5: 3. Future & plans | B5: =COUNTIF(Frames!$B$2:$B$101,A5) -> 10
A6: 4. Can / must / should | B6: =COUNTIF(Frames!$B$2:$B$101,A6) -> 10
A7: 5. Wants & feelings | B7: =COUNTIF(Frames!$B$2:$B$101,A7) -> 10
A8: 6. Questions | B8: =COUNTIF(Frames!$B$2:$B$101,A8) -> 10
A9: 7. Comparing & pairs | B9: =COUNTIF(Frames!$B$2:$B$101,A9) -> 10
A10: 8. Linking ideas | B10: =COUNTIF(Frames!$B$2:$B$101,A10) -> 10
A11: 9. Polite & social | B11: =COUNTIF(Frames!$B$2:$B$101,A11) -> 10
A12: 10. Opinions & everyday | B12: =COUNTIF(Frames!$B$2:$B$101,A12) -> 10
A13: Total | B13: =SUM(B3:B12) -> 100
A15: Frames per level (estimated)
A16: Value | B16: Frames
A17: A1 | B17: =COUNTIF(Frames!$F$2:$F$101,A17) -> 31
A18: A2 | B18: =COUNTIF(Frames!$F$2:$F$101,A18) -> 39
A19: B1 | B19: =COUNTIF(Frames!$F$2:$F$101,A19) -> 30
A20: Total | B20: =SUM(B17:B19) -> 100
A22: Frames per slot
A23: Value | B23: Frames
A24: base verb | B24: =COUNTIF(Frames!$E$2:$E$101,A24) -> 32
A25: -ing verb | B25: =COUNTIF(Frames!$E$2:$E$101,A25) -> 15
A26: noun | B26: =COUNTIF(Frames!$E$2:$E$101,A26) -> 15
A27: noun or -ing verb | B27: =COUNTIF(Frames!$E$2:$E$101,A27) -> 9
A28: clause | B28: =COUNTIF(Frames!$E$2:$E$101,A28) -> 6
A29: past participle | B29: =COUNTIF(Frames!$E$2:$E$101,A29) -> 4
A30: adjective | B30: =COUNTIF(Frames!$E$2:$E$101,A30) -> 3
A31: clause + base verb | B31: =COUNTIF(Frames!$E$2:$E$101,A31) -> 2
A32: two options | B32: =COUNTIF(Frames!$E$2:$E$101,A32) -> 2
A33: adjective + base verb | B33: =COUNTIF(Frames!$E$2:$E$101,A33) -> 2
A34: verb + s | B34: =COUNTIF(Frames!$E$2:$E$101,A34) -> 1
A35: past verb | B35: =COUNTIF(Frames!$E$2:$E$101,A35) -> 1
... A43: clause + clause | B43: =COUNTIF(Frames!$E$2:$E$101,A43) -> 1
A44: Total | B44: =SUM(B24:B43) -> 100
A46: Overlap with the 220 list
A47: Frames that match a 220 chunk | B47: =COUNTIF(Frames!$J$2:$J$101,"?*") -> 31
A48: New frames | B48: =100-B47 -> 69
