Workbook

Sheet Read Me
A1: EduSarthi — Customer Support English cards
A2: 180 cards: Voice, Chat and Email × Basic, Intermediate, Advanced × 20 cards. In every group of 20: 14 'Say it' cards (what the agent says or writes) and 6 'Understand it' cards (what the customer says, what it means, and what to say next).
A3: Every card has the same 56 fields on three sides, like every EduSarthi card: Side 1 Recognition · Side 2 Meaning & use · Side 3 Practice. The 'Field guide' sheet explains each field.
A4: How to study
A5: 1. Open 'Card View' and pick a card ID in the yellow cell (B3). 2. Read Side 1 and answer 'Recall first' before you look further. 3. Read Side 2. 4. Do every task on Side 3 out loud or in writing. 5. Voice and chat cards: record yourself. Email cards: write the reply and send it as text or a photo for audit. 6. In the card's sheet (Voice, Chat or Email), fill in your review columns. 7. Review again on days 1 · 3 · 7 · 15 · 30 · 60.
A6: Cells you fill in
A7: Only the yellow cells: Card View B3 (the card ID) and the 'MY REVIEW' columns at the right of the Voice, Chat and Email sheets — Status (pick Known / Unknown / Learning / Fix), Day 1 … Day 60 (the date you reviewed), My remark. Example: Status = Learning · Day 1 = 14 Oct · Day 3 = 17 Oct · My remark = 'I keep saying "one minute" instead of a real time'. The 'Summary' sheet counts your Known cards automatically.
A8: Placeholders
A9: [Company] stands for the company name. Names, order numbers, amounts and dates in the examples are made up.
A10: Status: DRAFT
A11: Every line was written by Claude from public customer-service guidance (see 'Sources') and checked twice (a script plus two rounds of independent review). It still needs a check by a verified teacher before students use it. Indian-English phrases such as 'revert' or 'prepone' are taught as switches for international customers, not as mistakes.

Sheet Card View
A1: Card View — pick a card ID in the yellow cell
A3: Card ID | B3: CSV-B-001
A5: CARD
A6: ID | B6: =IFERROR(INDEX(Voice!$A:$A,MATCH($B$3,Voice!$A:$A,0)),IFERROR(INDEX(Chat!$A:$A,MATCH($B$3,Chat!$A:$A,0)),IFERROR(INDEX(Email!$A:$A,MATCH($B$3,Email!$A:$A,0)),""))) -> CSV-B-001
A7: Channel | B7: =IFERROR(INDEX(Voice!$B:$B,MATCH($B$3,Voice!$A:$A,0)),IFERROR(INDEX(Chat!$B:$B,MATCH($B$3,Chat!$A:$A,0)),IFERROR(INDEX(Email!$B:$B,MATCH($B$3,Email!$A:$A,0)),""))) -> Voice
A8: Level | B8: =IFERROR(INDEX(Voice!$C:$C,MATCH($B$3,Voice!$A:$A,0)),IFERROR(INDEX(Chat!$C:$C,MATCH($B$3,Chat!$A:$A,0)),IFERROR(INDEX(Email!$C:$C,MATCH($B$3,Email!$A:$A,0)),""))) -> Basic
A9: CEFR | B9: =IFERROR(INDEX(Voice!$D:$D,MATCH($B$3,Voice!$A:$A,0)),IFERROR(INDEX(Chat!$D:$D,MATCH($B$3,Chat!$A:$A,0)),IFERROR(INDEX(Email!$D:$D,MATCH($B$3,Email!$A:$A,0)),""))) -> A2
A10: Kind | B10: =IFERROR(INDEX(Voice!$E:$E,MATCH($B$3,Voice!$A:$A,0)),IFERROR(INDEX(Chat!$E:$E,MATCH($B$3,Chat!$A:$A,0)),IFERROR(INDEX(Email!$E:$E,MATCH($B$3,Email!$A:$A,0)),""))) -> Say it
A11: Stage | B11: =IFERROR(INDEX(Voice!$F:$F,MATCH($B$3,Voice!$A:$A,0)),IFERROR(INDEX(Chat!$F:$F,MATCH($B$3,Chat!$A:$A,0)),IFERROR(INDEX(Email!$F:$F,MATCH($B$3,Email!$A:$A,0)),""))) -> Opening
A13: SIDE 1 · RECOGNITION
A14: Sentence | B14: =IFERROR(INDEX(Voice!$G:$G,MATCH($B$3,Voice!$A:$A,0)),IFERROR(INDEX(Chat!$G:$G,MATCH($B$3,Chat!$A:$A,0)),IFERROR(INDEX(Email!$G:$G,MATCH($B$3,Email!$A:$A,0)),""))) -> Thank you for calling [Company]. This is Priya. How can I help you today?
A15: Who says it | B15: =IFERROR(INDEX(Voice!$H:$H,MATCH($B$3,Voice!$A:$A,0)),IFERROR(INDEX(Chat!$H:$H,MATCH($B$3,Chat!$A:$A,0)),IFERROR(INDEX(Email!$H:$H,MATCH($B$3,Email!$A:$A,0)),""))) -> Agent
A16: Situation | B16: =IFERROR(INDEX(Voice!$I:$I,MATCH($B$3,Voice!$A:$A,0)),IFERROR(INDEX(Chat!$I:$I,MATCH($B$3,Chat!$A:$A,0)),IFERROR(INDEX(Email!$I:$I,MATCH($B$3,Email!$A:$A,0)),""))) -> The phone rings and you pick up the first call of your shift; you know nothing yet about the caller.
A17: Recall first | B17: =IFERROR(INDEX(Voice!$J:$J,MATCH($B$3,Voice!$A:$A,0)),IFERROR(INDEX(Chat!$J:$J,MATCH($B$3,Chat!$A:$A,0)),IFERROR(INDEX(Email!$J:$J,MATCH($B$3,Email!$A:$A,0)),""))) -> A new call connects. Which three things do you say in your first breath, and in what order?
A18: Say it like (stress) | B18: =IFERROR(INDEX(Voice!$K:$K,MATCH($B$3,Voice!$A:$A,0)),IFERROR(INDEX(Chat!$K:$K,MATCH($B$3,Chat!$A:$A,0)),IFERROR(INDEX(Email!$K:$K,MATCH($B$3,Email!$A:$A,0)),""))) -> THANK-you-for-CALL-ing-[COM-pa-ny] · this-is-PRI-ya · how-can-i-HELP-you-to-DAY
A19: Linking | B19: =IFERROR(INDEX(Voice!$L:$L,MATCH($B$3,Voice!$A:$A,0)),IFERROR(INDEX(Chat!$L:$L,MATCH($B$3,Chat!$A:$A,0)),IFERROR(INDEX(Email!$L:$L,MATCH($B$3,Email!$A:$A,0)),""))) -> thank_you → "thang-kyoo" · this_is → "thi-siz" · help_you → "hel-pyoo"
A20: Intonation & pace | B20: =IFERROR(INDEX(Voice!$M:$M,MATCH($B$3,Voice!$A:$A,0)),IFERROR(INDEX(Chat!$M:$M,MATCH($B$3,Chat!$A:$A,0)),IFERROR(INDEX(Email!$M:$M,MATCH($B$3,Email!$A:$A,0)),""))) -> Warm and steady on the greeting, with a short pause after the company name and again after your name. "How can I help you today?" is a wh- question, so let it fall gently at the end; do not rush it.
A21: Indian speaker tip | B21: =IFERROR(INDEX(Voice!$N:$N,MATCH($B$3,Voice!$A:$A,0)),IFERROR(INDEX(Chat!$N:$N,MATCH($B$3,Chat!$A:$A,0)),IFERROR(INDEX(Email!$N:$N,MATCH($B$3,Email!$A:$A,0)),""))) -> "Thank" and "this" both start with "th". For "thank", put the tongue tip lightly between the teeth and blow (not "tank"); for "this", use the same tongue position with voice (not "dis"). Minimal pairs: thin / tin (for "thank"), then / den (for "this").
A22: Register | B22: =IFERROR(INDEX(Voice!$O:$O,MATCH($B$3,Voice!$A:$A,0)),IFERROR(INDEX(Chat!$O:$O,MATCH($B$3,Chat!$A:$A,0)),IFERROR(INDEX(Email!$O:$O,MATCH($B$3,Email!$A:$A,0)),""))) -> Neutral
A23: Tone | B23: =IFERROR(INDEX(Voice!$P:$P,MATCH($B$3,Voice!$A:$A,0)),IFERROR(INDEX(Chat!$P:$P,MATCH($B$3,Chat!$A:$A,0)),IFERROR(INDEX(Email!$P:$P,MATCH($B$3,Email!$A:$A,0)),""))) -> Warm, welcoming, ready
A24: Importance (1-5) | B24: =IFERROR(INDEX(Voice!$Q:$Q,MATCH($B$3,Voice!$A:$A,0)),IFERROR(INDEX(Chat!$Q:$Q,MATCH($B$3,Chat!$A:$A,0)),IFERROR(INDEX(Email!$Q:$Q,MATCH($B$3,Email!$A:$A,0)),""))) -> 5
A25: Customer feels | B25: =IFERROR(INDEX(Voice!$R:$R,MATCH($B$3,Voice!$A:$A,0)),IFERROR(INDEX(Chat!$R:$R,MATCH($B$3,Chat!$A:$A,0)),IFERROR(INDEX(Email!$R:$R,MATCH($B$3,Email!$A:$A,0)),""))) -> Hopeful but unsure whether they have reached the right place.
A26: Memory hook | B26: =IFERROR(INDEX(Voice!$S:$S,MATCH($B$3,Voice!$A:$A,0)),IFERROR(INDEX(Chat!$S:$S,MATCH($B$3,Chat!$A:$A,0)),IFERROR(INDEX(Email!$S:$S,MATCH($B$3,Email!$A:$A,0)),""))) -> Think of opening a shop door: you thank them for coming in, show your name badge, then ask how you can help.
A28: SIDE 2 · MEANING & USE
A29: Hindi meaning | B29: =IFERROR(INDEX(Voice!$T:$T,MATCH($B$3,Voice!$A:$A,0)),IFERROR(INDEX(Chat!$T:$T,MATCH($B$3,Chat!$A:$A,0)),IFERROR(INDEX(Email!$T:$T,MATCH($B$3,Email!$A:$A,0)),""))) -> [Company] को कॉल करने के लिए धन्यवाद। मेरा नाम प्रिया है। आज मैं आपकी क्या मदद कर सकता/सकती हूँ?
A30: Hindi (Roman) | B30: =IFERROR(INDEX(Voice!$U:$U,MATCH($B$3,Voice!$A:$A,0)),IFERROR(INDEX(Chat!$U:$U,MATCH($B$3,Chat!$A:$A,0)),IFERROR(INDEX(Email!$U:$U,MATCH($B$3,Email!$A:$A,0)),""))) -> [Company] ko call karne ke liye dhanyavaad. Mera naam Priya hai. Aaj main aapki kya madad kar sakta/sakti hoon?
A31: In simple English | B31: =IFERROR(INDEX(Voice!$V:$V,MATCH($B$3,Voice!$A:$A,0)),IFERROR(INDEX(Chat!$V:$V,MATCH($B$3,Chat!$A:$A,0)),IFERROR(INDEX(Email!$V:$V,MATCH($B$3,Email!$A:$A,0)),""))) -> Thanks for phoning this company. My name is Priya. What would you like help with?
A32: Why it works | B32: =IFERROR(INDEX(Voice!$W:$W,MATCH($B$3,Voice!$A:$A,0)),IFERROR(INDEX(Chat!$W:$W,MATCH($B$3,Chat!$A:$A,0)),IFERROR(INDEX(Email!$W:$W,MATCH($B$3,Email!$A:$A,0)),""))) -> In one breath the caller learns they reached the right company, hears a real person's name, and is invited to explain. "How can I help" assumes you will help, which sounds far more willing than "What is your problem?"
A33: Key chunk | B33: =IFERROR(INDEX(Voice!$X:$X,MATCH($B$3,Voice!$A:$A,0)),IFERROR(INDEX(Chat!$X:$X,MATCH($B$3,Chat!$A:$A,0)),IFERROR(INDEX(Email!$X:$X,MATCH($B$3,Email!$A:$A,0)),""))) -> How can I help you ___?
A34: Grammar pattern | B34: =IFERROR(INDEX(Voice!$Y:$Y,MATCH($B$3,Voice!$A:$A,0)),IFERROR(INDEX(Chat!$Y:$Y,MATCH($B$3,Chat!$A:$A,0)),IFERROR(INDEX(Email!$Y:$Y,MATCH($B$3,Email!$A:$A,0)),""))) -> Thank you for + verb-ing · This is + name · How can I + base verb …?
A35: Grammar in one line | B35: =IFERROR(INDEX(Voice!$Z:$Z,MATCH($B$3,Voice!$A:$A,0)),IFERROR(INDEX(Chat!$Z:$Z,MATCH($B$3,Chat!$A:$A,0)),IFERROR(INDEX(Email!$Z:$Z,MATCH($B$3,Email!$A:$A,0)),""))) -> After "Thank you for", use the -ing form: "for calling", not "for call".
A36: Tone note | B36: =IFERROR(INDEX(Voice!$AA:$AA,MATCH($B$3,Voice!$A:$A,0)),IFERROR(INDEX(Chat!$AA:$AA,MATCH($B$3,Chat!$A:$A,0)),IFERROR(INDEX(Email!$AA:$AA,MATCH($B$3,Email!$A:$A,0)),""))) -> Saying your name makes you a person, not a machine. A flat, fast "Hello, tell me" sounds like you want the call to end quickly.
A37: Watch out | B37: =IFERROR(INDEX(Voice!$AB:$AB,MATCH($B$3,Voice!$A:$A,0)),IFERROR(INDEX(Chat!$AB:$AB,MATCH($B$3,Chat!$A:$A,0)),IFERROR(INDEX(Email!$AB:$AB,MATCH($B$3,Email!$A:$A,0)),""))) -> ✗ Thank you for calling to [Company]. I am Priya. How I can help you? → ✓ Thank you for calling [Company]. This is Priya. How can I help you today?
A38: Don't say | B38: =IFERROR(INDEX(Voice!$AC:$AC,MATCH($B$3,Voice!$A:$A,0)),IFERROR(INDEX(Chat!$AC:$AC,MATCH($B$3,Chat!$A:$A,0)),IFERROR(INDEX(Email!$AC:$AC,MATCH($B$3,Email!$A:$A,0)),""))) -> "Hello, tell me." — it skips the company name and your name, and sounds like an order.
A39: Positive swap | B39: =IFERROR(INDEX(Voice!$AD:$AD,MATCH($B$3,Voice!$A:$A,0)),IFERROR(INDEX(Chat!$AD:$AD,MATCH($B$3,Chat!$A:$A,0)),IFERROR(INDEX(Email!$AD:$AD,MATCH($B$3,Email!$A:$A,0)),""))) -> Instead of "Yes, tell me your problem", say "How can I help you today?"
A40: Another way 1 | B40: =IFERROR(INDEX(Voice!$AE:$AE,MATCH($B$3,Voice!$A:$A,0)),IFERROR(INDEX(Chat!$AE:$AE,MATCH($B$3,Chat!$A:$A,0)),IFERROR(INDEX(Email!$AE:$AE,MATCH($B$3,Email!$A:$A,0)),""))) -> Good morning, you're through to [Company]. My name is Priya. How can I help?
A41: Another way 2 | B41: =IFERROR(INDEX(Voice!$AF:$AF,MATCH($B$3,Voice!$A:$A,0)),IFERROR(INDEX(Chat!$AF:$AF,MATCH($B$3,Chat!$A:$A,0)),IFERROR(INDEX(Email!$AF:$AF,MATCH($B$3,Email!$A:$A,0)),""))) -> Hi, thanks for calling [Company]. Priya speaking. What can I do for you today?
A42: More formal | B42: =IFERROR(INDEX(Voice!$AG:$AG,MATCH($B$3,Voice!$A:$A,0)),IFERROR(INDEX(Chat!$AG:$AG,MATCH($B$3,Chat!$A:$A,0)),IFERROR(INDEX(Email!$AG:$AG,MATCH($B$3,Email!$A:$A,0)),""))) -> Good afternoon, and thank you for calling [Company]. My name is Priya. How may I assist you today?
A43: Ask next | B43: =IFERROR(INDEX(Voice!$AH:$AH,MATCH($B$3,Voice!$A:$A,0)),IFERROR(INDEX(Chat!$AH:$AH,MATCH($B$3,Chat!$A:$A,0)),IFERROR(INDEX(Email!$AH:$AH,MATCH($B$3,Email!$A:$A,0)),""))) -> Sure, I can look into that. Could I start with your name, please?
A44: Replies you may hear | B44: =IFERROR(INDEX(Voice!$AI:$AI,MATCH($B$3,Voice!$A:$A,0)),IFERROR(INDEX(Chat!$AI:$AI,MATCH($B$3,Chat!$A:$A,0)),IFERROR(INDEX(Email!$AI:$AI,MATCH($B$3,Email!$A:$A,0)),""))) -> Hi, I'm calling about my order. · Is this the billing team? · My internet has stopped working.
...

Sheet Voice
A1: CARD | G1: SIDE 1 · RECOGNITION | T1: SIDE 2 · MEANING & USE | AP1: SIDE 3 · PRACTICE | BE1: MY REVIEW (fill in)
A2: ID | B2: Channel | C2: Level | D2: CEFR | E2: Kind | F2: Stage | G2: Sentence | H2: Who says it | I2: Situation | J2: Recall first | K2: Say it like (stress) | L2: Linking | M2: Intonation & pace | N2: Indian speaker tip | O2: Register | P2: Tone | Q2: Importance (1-5) | R2: Customer feels | S2: Memory hook | T2: Hindi meaning | U2: Hindi (Roman) | V2: In simple English | W2: Why it works | X2: Key chunk | Y2: Grammar pattern | Z2: Grammar in one line | AA2: Tone note | AB2: Watch out | AC2: Don't say | AD2: Positive swap | AE2: Another way 1 | AF2: Another way 2 | AG2: More formal | AH2: Ask next | AI2: Replies you may hear | AJ2: If the customer pushes back | AK2: Indian English vs international | AL2: On other channels | AM2: When not to use | AN2: Mini conversation | AO2: Best-practice rule | AP2: Fill the blank | AQ2: Fill answer | AR2: MCQ question | AS2: MCQ options | AT2: MCQ answer | AU2: Why that answer | AV2: Put in order | AW2: Order answer | AX2: Say it in English | AY2: English answer | AZ2: Customer says next | BA2: Model reply | BB2: Role-play task | BC2: Record / write for audit | BD2: Self-check | BE2: Status | BF2: Day 1 | BG2: Day 3 | BH2: Day 7 | BI2: Day 15 | BJ2: Day 30 | BK2: Day 60 | BL2: My remark
A3: CSV-B-001 | B3: Voice | C3: Basic | D3: A2 | E3: Say it | F3: Opening | G3: Thank you for calling [Company]. This is Priya. How can I help you today? | H3: Agent | I3: The phone rings and you pick up the first call of your shift; you know nothing yet about the caller. | J3: A new call connects. Which three things do you say in your first breath, and in what order? | K3: THANK-you-for-CALL-ing-[COM-pa-ny] · this-is-PRI-ya · how-can-i-HELP-you-to-DAY | L3: thank_you → "thang-kyoo" · this_is → "thi-siz" · help_you → "hel-pyoo" | M3: Warm and steady on the greeting, with a short pause after the company name and again after your name. "How can I help you today?" is a wh- question, so let it fall gently at the end; do not rush it. | N3: "Thank" and "this" both start with "th". For "thank", put the tongue tip lightly between the teeth and blow (not "tank"); for "this", use the same tongue position with voice (not "dis"). Minimal pairs: thin / tin (for "thank"), then / den (for "this"). | O3: Neutral | P3: Warm, welcoming, ready | Q3: 5 | R3: Hopeful but unsure whether they have reached the right place. | S3: Think of opening a shop door: you thank them for coming in, show your name badge, then ask how you can help. | T3: [Company] को कॉल करने के लिए धन्यवाद। मेरा नाम प्रिया है। आज मैं आपकी क्या मदद कर सकता/सकती हूँ? | U3: [Company] ko call karne ke liye dhanyavaad. Mera naam Priya hai. Aaj main aapki kya madad kar sakta/sakti hoon? | V3: Thanks for phoning this company. My name is Priya. What would you like help with? | W3: In one breath the caller learns they reached the right company, hears a real person's name, and is invited to explain. "How can I help" assumes you will help, which sounds far more willing than "What is your problem?" | X3: How can I help you ___? | Y3: Thank you for + verb-ing · This is + name · How can I + base verb …? | Z3: After "Thank you for", use the -ing form: "for calling", not "for call". | AA3: Saying your name makes you a person, not a machine. A flat, fast "Hello, tell me" sounds like you want the call to end quickly. | AB3: ✗ Thank you for calling to [Company]. I am Priya. How I can help you? → ✓ Thank you for calling [Company]. This is Priya. How can I help you today? | AC3: "Hello, tell me." — it skips the company name and your name, and sounds like an order. | AD3: Instead of "Yes, tell me your problem", say "How can I help you today?" | AE3: Good morning, you're through to [Company]. My name is Priya. How can I help? | AF3: Hi, thanks for calling [Company]. Priya speaking. What can I do for you today? | AG3: Good afternoon, and thank you for calling [Company]. My name is Priya. How may I assist you today? | AH3: Sure, I can look into that. Could I start with your name, please? | AI3: Hi, I'm calling about my order. · Is this the billing team? · My internet has stopped working. | AJ3: Customer: "Is this a real person? I've been waiting ages." → Agent: "Yes, I'm Priya, a real person, and I'm sorry about the wait. How can I help you today?" | AK3: Many Indian agents say "Myself Priya" or open with "Yes, tell me". International callers may not expect these; they expect "This is Priya" or "My name is Priya", with the company name first. | AL3: Chat: "Hi, I'm Priya from [Company]. How can I help today?" Email: greet the customer by name and get to the point; no phone-style opening. | AM3: When you call the customer back, do not say "Thank you for calling"; say "Hi, this is Priya from [Company], returning your call." | AN3: Customer: Hello? | Agent: Thank you for calling [Company]. This is Priya. How can I help you today? | Customer: Hi, my parcel hasn't arrived. | Agent: I'm sorry to hear that. Could I have your order number, please? | AO3: Open with thanks, the company name and an offer of help, and give your own name. | AP3: Thank you ____ calling [Company]. This is Priya. How can I help you today? | AQ3: for | AR3: A call has just connected. Which opening is the most welcoming and complete? | AS3: A) Good morning, [Company] customer service. Yes, please tell me your problem. | B) Hello, [Company] customer service, Priya here. What is the problem today? | C) Thank you for calling [Company]. This is Priya. How can I help you today? | D) Hello, this is [Company]. Please give me your name and order number. | AT3: C | AU3: C thanks the caller and gives the company, your name and an offer of help. A and B ask for "the problem" bluntly, and D starts with a demand for details and skips your name. | AV3: help / today / I / can / How / you | AW3: How can I help you today | AX3: [Company] ko call karne ke liye shukriya, mera naam Rahul hai. Main aaj aapki kya madad kar sakta hoon? | AY3: Thank you for calling [Company]. This is Rahul. How can I help you today? | AZ3: Hi, I'm calling because I was charged twice. | BA3: I'm sorry you've been charged twice. I'll look into it for you. Could I have your name, please? | BB3: Partner A phones [Company] about a late delivery. Partner B answers with thanks, the company name, their own name and an offer of help, then asks for A's name. | BC3: Record your full opening three times: once normally, once smiling, once slowly. Submit the one that sounds the warmest. | BD3: Did you say the company name and your own name? · Did "today" fall at the end? · Did "thank" start with a soft "th", not "t"?
A4: CSV-B-002 | B4: Voice | C4: Basic | D4: A2 | E4: Say it | F4: Verify | G4: Could I have your full name, please? | H4: Agent | I4: The caller has said they need help with a refund, and you need their name to find their account. | J4: You need to know who you are speaking to. How do you ask without sounding like a police officer? | K4: could-i-HAVE · your-FULL-NAME · PLEASE | L4: could_I → "cu-dai" · have_your → "ha-vyor" · full_name → "ful-naym" (short "u" as in "put", not "fool"; no pause between the words) | M4: A polite request shaped like a yes/no question, so rise slightly on "please?". Slow down on "full name" so it is heard clearly. | N4: "Have" ends in a real /v/: top teeth touch the lower lip, not "haw" or "hab". Practise the pair vest / west so "have" does not slide into a w-sound. | O4: Neutral | P4: Polite, simple request | Q4: 5 | R4: Neutral and ready to give details, but wants the call to move fast. | S4: Imagine holding out an open hand for a business card: "Could I have…" asks for it, it does not grab. | T4: क्या मुझे आपका पूरा नाम मिल सकता है? | U4: Kya mujhe aapka poora naam mil sakta hai? | V4: Please tell me your first name and your surname. | W4: "Could I have" is a soft, standard request that international callers hear every day. Asking for the full name up front saves a second question later when two accounts share a first name. | X4: Could I have your ___, please? | Y4: Could + I + have + your + noun, please? | Z4: "Could I have…?" asks to receive something; it is softer than "Give me…" or "Tell me…". | AA4: The question form and "please" make it polite. "Name?" or "Tell your name" sounds like a form being filled in, not a person helping. | AB4: ✗ Can you tell your full name? → ✓ Could I have your full name, please? | AC4: "Tell me your good name." — "good name" echoes Hindi "shubh naam"; international callers may find it odd, and it sounds like an order. | AD4: Instead of "Tell me your name", say "Could I have your full name, please?" | AE4: Can I take your name, please? | AF4: Who am I speaking with today? | AG4: Before we go further, could you give me your full name as it appears on the account? | AH4: Thank you, Ms Okafor. Could you spell your surname for me, please? | AI4: It's James Walker. · Sarah, Sarah Jones. · Why do you need my name? | AJ4: Customer: "Why do you need my name? Just fix it." → Agent: "I understand you want this sorted quickly. I need your name to find your account, so I can see exactly what happened." | AK4: "Your good name" and "May I know your name?" are common Indian English forms. International callers may not expect them; switch to "Could I have your name?" or "Who am I speaking with?" | AL4: Chat: "Could I have your full name, please?" works as is. Email: the name is usually in the signature, so do not ask; use it in your greeting. | AM4: Do not ask again if the caller already gave their name in the first sentence; use it instead: "Thanks, Mr Walker." | AN4: Customer: I need help with a refund. | Agent: Sure. Could I have your full name, please? | Customer: It's Anna Brooks. | Agent: Thank you, Ms Brooks. Let me find your account. | AO4: Verification: ask only for what you need, and state the purpose when the caller asks why. | AP4: Could I have your full name, ____ (starts with p)? | AQ4: please | AR4: Which way of asking for the caller's name sounds most natural to an international customer? | AS4: A) Please tell me your name quickly. | B) Could I have your full name, please? | C) What is your name? I need it now. | D) First give your name, then I will help. | AT4: B | AU4: B is a soft, standard request. A and C are orders, and D sets a condition instead of asking. | AV4: name / I / your / please / Could / full / have | AW4: Could I have your full name please | AX4: Kya main aapka poora naam jaan sakti hoon? | AY4: Could I have your full name, please? | AZ4: It's Daniel O'Brien. | BA4: Thank you, Mr O'Brien. Let me check the spelling: O, apostrophe, B-R-I-E-N. Is that right? | BB4: Partner A calls to change a delivery address. Partner B asks for A's full name, repeats it back, and asks A to spell the surname. | BC4: Record yourself asking for the caller's name, then thanking them by name, as if the caller said "Anna Brooks". | BD4: Did your voice rise a little on "please?" · Did you ask with "Could I have..." rather than "Tell me"? · Did "have" end in a clear "v"?
A5: CSV-B-003 | B5: Voice | C5: Basic | D5: B1 | E5: Say it | F5: Verify | G5: To protect your account, could you confirm your registered mobile number or email address? | H5: Agent | I5: Before you can discuss a billing question, you must check that the caller is the account holder. | J5: Before sharing any account details, you must check who the caller is. What reason do you give first, and what do you ask for? | K5: to-pro-TECT-your-ac-COUNT · could-you-con-FIRM · your-REG-is-tered-MO-bile-NUM-ber · or-E-mail-ad-DRESS | L5: protect_your → "pro-tek-chor" · confirm_your → "con-fur-myor" · email_address → "ee-may-la-dress" | M5: Keep your voice level, or rise a little, after "account" and pause, so the caller hears that the request is still coming. In "mobile number or email address", rise on "number" and fall on "address" to show there are two choices. | N5: Final clusters: "protect" ends in "-kt" and "registered" ends in "-rd". Say pro-TEKT and REJ-is-terd with the last sound clear; dropping it ("pro-tek", "REJ-is-ter") makes the words harder to catch on a phone line. | O5: Neutral | P5: Calm, reassuring, clear | Q5: 5 | R5: Slightly impatient, and may wonder why they must prove who they are. | S5: A bank locker needs two keys: first show why (to keep it safe), then ask for the second key (their number). | T5: आपके अकाउंट की सुरक्षा के लिए, क्या आप अपना रजिस्टर्ड मोबाइल नंबर या ईमेल पता कन्फ़र्म कर सकते हैं? | U5: Aapke account ki suraksha ke liye, kya aap apna registered mobile number ya email address confirm kar sakte hain? | V5: So that nobody else can use your account, please tell me the phone number or email linked to it. | W5: Putting the reason first turns a check into something done for the customer, not against them. Offering two options lets them use whichever one they remember. | X5: To protect your account, could you confirm your ___? | Y5: To + base verb (purpose), could + you + confirm + noun? | Z5: "To protect…" at the start explains why; it means "so that I can protect…". | AA5: The reason makes it feel like care, not suspicion. "Give your number first, then I'll talk" sounds like you think they are lying. | AB5: ✗ For protect your account, could you confirm registered mobile number or email? → ✓ To protect your account, could you confirm your registered mobile number or email address? | AC5: "I can't tell you anything until you verify." — it sounds like a threat and gives no reason the caller cares about. | AD5: Instead of "I can't help without verification", say "To protect your account, could you confirm your registered mobile number or email address?" | AE5: For your security, could you tell me the mobile number on the account? | AF5: Just so I know I'm speaking with the account holder, could you confirm your email address? | AG5: To keep your account secure, could you please confirm the mobile number or email address registered with us? | AH5: Thank you, that matches. Now, how can I help with your bill today? | AI5: It's 07700 900123. · Which email, my work one or my personal one? · I don't remember which number I used. | AJ5: Customer: "I've already given this to the last agent!" → Agent: "I'm sorry to ask again. We check on every call to keep your account safe. Your email address works too, if that's easier." | AK5: "May I know your registered mobile number?" is common on Indian calls. It is grammatical, but international callers may not expect it; they more often hear "Could you confirm…?" or "Could you tell me…?" | AL5: Chat: same wording, but never ask for a full card number, PIN, password or one-time code (OTP). Email: ask the customer to reply from the email address registered on the account. | AM5: Do not use it if the caller only wants general information, such as opening hours, which needs no account access. | AN5: Customer: I want to check my last bill. | Agent: To protect your account, could you confirm your registered mobile number or email address? | Customer: It's lucy.grant@example.com. | Agent: Thank you, that matches. Let me open your bill. | AO5: Verification: state the purpose ("To protect your account…") and ask only for what you need. | AP5: ____ protect your account, could you confirm your registered mobile number or email address? | AQ5: To | AR5: You must verify the caller before discussing their bill. Which line explains the check best? | AS5: A) Before I tell you anything, you will have to prove you are the account holder. | B) To protect your account, could you confirm your registered mobile number or email address? | C) I can't discuss your bill until you give me your registered mobile number or email address. | D) It is company rule, so could you please confirm your registered mobile number or email? | AT5: B | AU5: B gives a reason the customer cares about. A sounds like a threat, C refuses until the customer complies, and D hides behind "company rule" instead of explaining why. | AV5: account / your / protect / To / could / confirm / you / email / your / address | AW5: To protect your account could you confirm your email address | AX5: Aapke account ki suraksha ke liye, kya aap apna registered email address confirm kar sakte hain? | AY5: To protect your account, could you confirm your registered email address? | AZ5: Why do you need that? I'm the account holder. | BA5: I understand, and I'm sorry for the extra step. It's a quick check we do on every call, so nobody else can get into your account. | BB5: Partner A calls about a high phone bill. Partner B explains the reason for the check, asks for the registered mobile number or email, confirms it matches, then asks how to help. | BC5: Record the verification line, then the line you say when the number matches, then the line you say when it does not match. | BD5: Did you give the reason before the request? · Did "address" fall at the end to show a choice? · Did you say the final "t" in "protect"?
A6: CSV-B-004 | B6: Voice | C6: Basic | D6: A2 | E6: Say it | F6: Listen & clarify | G6: I'm sorry, I didn't catch that. Could you say it again, please? | H6: Agent | I6: The caller said their order number quickly and you missed two of the digits. | J6: You missed part of what the caller said. How do you ask them to repeat it without blaming them? | K6: i'm-SOR-ry · i-DID-n't-CATCH-that · could-you-SAY-it-a-GAIN · PLEASE | L6: sorry_I → "sor-ree-yai" (a small "y" joins the two vowels) · didn't_catch → "didn-catch" · say_it_again → "say-yi-ta-gen" | M6: Gentle fall on "catch that", a short pause, then a rise on "please?". Keep the voice soft so it sounds like your miss, not theirs. | N6: "That" starts with a voiced "th": put the tongue tip between the teeth and add voice. Saying "dat" is a common habit because Hindi has no English-style "th" and uses a "d" or "t" instead; practise then / den. | O6: Neutral | P6: Apologetic, polite request | Q6: 5 | R6: Mildly impatient, and may feel they already spoke clearly. | S6: Their words were a ball thrown to you and you did not catch it: say sorry, then ask them to throw it once more. | T6: माफ़ कीजिए, मैं ठीक से सुन नहीं पाया/पाई। क्या आप फिर से बता सकते हैं? | U6: Maaf kijiye, main theek se sun nahin paaya/paayi. Kya aap phir se bata sakte hain? | V6: Sorry, I missed what you said. Please say it one more time. | W6: "I didn't catch that" puts the miss on you, not on the caller's accent or speed. A guessed digit leads to the wrong order later, so asking is always better than guessing. | X6: I didn't catch ___. Could you say it again, please? | Y6: I + didn't + catch + that · Could + you + say + it + again, please? | Z6: "Catch" here means "hear and understand"; use the past "didn't catch" because the words were already said. | AA6: Apologising first makes it your problem. "What?" or "Repeat" sounds rude, and "You are not clear" blames the caller. | AB6: ✗ Sorry, I am not understanding. Say again please. → ✓ I'm sorry, I didn't catch that. Could you say it again, please? | AC6: "Speak properly, I can't understand you." — it blames the caller and can sound like you are judging their accent. | AD6: Instead of "You are not audible", say "I'm sorry, I didn't catch that. Could you say it again, please?" | AE6: Sorry, could you repeat the last part, please? | AF6: I missed the last two digits. Could you read them out again? | AG6: I do apologise, I didn't quite catch that. Would you mind repeating it, please? | AH6: Thank you. So that's 4 8 1 7 2. Is that right? | AI6: Sure, it's 4 8 1 7 2. · Which part did you miss? · I just said it! | AJ6: Customer: "I just said it!" → Agent: "I know, and I'm sorry. I want to get the number exactly right so I find the correct order." | AK6: "Repeat once more" and "You are not audible" are common on Indian calls. International callers may hear them as abrupt or formal; "I didn't catch that" is the softer, more expected form. | AL6: Chat: hearing is not the issue, but you can ask "Could you check that number again? I can't find it." Email: ask for the missing detail in one clear question. | AM6: Do not ask a third time in the same way; ask the caller to spell it or read it slowly, digit by digit. | AN6: Customer: My order number is four-eight-one-something-two. | Agent: I'm sorry, I didn't catch that. Could you say it again, please? | Customer: Four, eight, one, seven, two. | Agent: Thank you. That's 4 8 1 7 2. Let me find it. | AO6: Ask politely for a repeat ("I'm sorry, could you please repeat that?") rather than guess. | AP6: I'm ____ (starts with s), I didn't catch that. Could you say it again, please? | AQ6: sorry | AR6: You missed part of the caller's account number. Which response is best? | AS6: A) Your voice is not clear. Please say the number again, and slowly. | B) I'm sorry, I didn't catch that. Could you say it again, please? | C) I think I got most of it, so I'll carry on with the number I heard. | D) Could you speak louder and slower? You are going too fast for me. | AT6: B | AU6: B apologises and asks politely. C risks opening the wrong account, and A and D put the blame on the caller. | AV6: again / Could / say / it / you / please | AW6: Could you say it again please | AX6: Maaf kijiye, main sun nahin paaya. Kya aap phir se bata sakte hain? | AY6: I'm sorry, I didn't catch that. Could you say it again, please? | AZ6: Sure. It's 4 8 1 7 2. | BA6: Thank you, that's much clearer. I've got all five digits now, so let me find your order. | BB6: Partner A reads a five-digit order number quickly and swallows one digit. Partner B asks for a repeat politely, then reads the full number back to confirm. | BC6: Record yourself asking for a repeat, then reading back the number 4 8 1 7 2 slowly, digit by digit. | BD6: Did you say sorry before asking? · Did you avoid "repeat" as a one-word order? · Did "that" start with a soft "th", not "d"?
A7: CSV-B-005 | B7: Voice | C7: Basic | D7: A2 | E7: Say it | F7: Listen & clarify | G7: Could you spell your email address for me, please? | H7: Agent | I7: The caller has given an unusual email address, and you need it exactly right to send a refund receipt. | J7: The caller's email has an unusual name in it. What do you ask so that you type it exactly right? | K7: could-you-SPELL · your-E-mail-ad-DRESS · for-ME · PLEASE | L7: spell_your → "spel-yor" · email_address → "ee-may-la-dress" · for_me → "fer-mee" | M7: One smooth question, rising on "please?". While they spell, say "Yes" or "Got it" after each group so they know you are with them. | N7: "Spell" starts with an s-cluster: say "spell" straight away, not "ispell" or "su-pell". Some speakers add a vowel before s-clusters (as in "iskul" for school); keep the "s" and "p" together. | O7: Neutral | P7: Careful, polite request | Q7: 4 | R7: Patient, but may be tired of spelling their email on every call. | S7: Picture the letters dropping one by one into your keyboard like coins: one wrong coin and the email bounces. | T7: क्या आप मेरे लिए अपना ईमेल पता स्पेल कर सकते हैं? | U7: Kya aap mere liye apna email address spell kar sakte hain? | V7: Please say the letters of your email one by one. | W7: Spelling stops mistakes with names that sound alike, like "Shaw" and "Shore". One wrong letter means the customer never gets the email and has to call back. | X7: Could you spell ___ for me, please? | Y7: Could + you + spell + noun + for me, please? | Z7: "Spell" means say each letter; "for me" makes the request personal and softer. | AA7: "For me, please" sounds like you want to get it right for them. "Spell it" on its own sounds like an order. | AB7: ✗ Please spelling your email address. → ✓ Could you spell your email address for me, please? | AC7: "Your email is not clear, spell it." — it blames the customer for a normal difficulty. | AD7: Instead of "Tell your email ID spelling", say "Could you spell your email address for me, please?" | AE7: Could you spell that for me, letter by letter? | AF7: Just to get it right, could you spell your email for me? | AG7: To make sure the receipt reaches you, would you mind spelling your email address for me? | AH7: Thank you. Let me read it back: r-o-s-s-k-a-y at example dot com. Is that right? | AI7: Sure, it's r-o-s-s-k-a-y at example dot com. · Is it the one on my account? · Didn't I give that already? | AJ7: Customer: "It's just my name, it's easy!" → Agent: "It is, and I want to be sure I don't mix up an 'e' and an 'i'. Spelling it now saves you a lost receipt." | AK7: "Email ID" is common in India; international callers usually say "email address" or just "email". Read it back with "at" and "dot", and use clear words for letters (B for Bravo) if needed. | AL7: Chat: no spelling needed; ask "Could you type your email here?" Email: you already have it, so do not ask. | AM7: Do not ask the caller to spell something already on your screen from verification; read it back and ask for a yes or no instead. | AN7: Customer: My email is rosskay at example dot com. | Agent: Could you spell your email address for me, please? | Customer: R-O-S-S-K-A-Y at example dot com. | Agent: Thank you. I have rosskay at example dot com. Is that right? | AO7: Ask callers to spell names and emails, then read them back. | AP7: Could you spell your email ____ for me, please? | AQ7: address | AR7: The caller's surname could be "Shaw" or "Shore". What is the best next step? | AS7: A) Type "Shaw" for now, because it is the more common spelling. | B) Ask, "Could you spell your surname for me, please?" | C) Say, "Sorry, your name is not clear. Please say it again." | D) Ask the caller to send their name by email later. | AT7: B | AU7: B removes the doubt politely. A is a guess that can put the wrong name on the account, C blames the caller, and D delays the fix and risks losing the detail. | AV7: email / spell / Could / for / you / me / your / address / please | AW7: Could you spell your email address for me please | AX7: Kya aap apne naam ki spelling bata sakte hain? | AY7: Could you spell your name for me, please? | AZ7: Sure. It's t-h-o-m-a-s dot r-e-e-d at example dot com. | BA7: Thank you. I have thomas dot reed at example dot com. Is that right? | BB7: Partner A has the email "lia.devane@example.com" and says it fast. Partner B asks A to spell it, reads it back with "dot" and "at", and confirms. | BC7: Record yourself asking for the spelling, then reading back the email "lia.devane at example dot com" letter by letter. | BD7: Did you say "spell" without an extra vowel at the start? · Did you read the email back? · Did you say "email address" in full?
A8: CSV-B-006 | B8: Voice | C8: Basic | D8: A2 | E8: Say it | F8: Hold & check | G8: Could you hold for about two minutes, please? I'll check your order. | H8: Agent | I8: The customer asked about their order and you need about two minutes to look it up in the system. | J8: You need a couple of minutes to look something up. What do you ask the caller first, and what do you promise them? | K8: could-you-HOLD · for-a-BOUT-two-MIN-utes · PLEASE · i'll-CHECK · your-OR-der | L8: could_you → "cud-joo" · hold_for → "hole-fer" · two_minutes → "too-MIN-its" | M8: Rising tone on "please?" because it is a real question. Short pause after it, then a falling, confident tone on "I'll check your order." | N8: Say "hold" with a long "oh" and a clear final "d"; do not drop it to "hol". "Minutes" is MIN-its, stress on the first part, with a clear final "s". | O8: Neutral | P8: Polite request, calm | Q8: 5 | R8: Patient but a little worried about how long this will take. | S8: Picture pressing a soft pause button on a remote: you ask before you press it, and you promise to press play again. | T8: क्या आप लगभग दो मिनट होल्ड कर सकते हैं? मैं आपका ऑर्डर देखता/देखती हूँ। | U8: Kya aap lagbhag do minute hold kar sakte hain? Main aapka order dekhta/dekhti hoon. | V8: Please stay on the line for about two minutes while I look at your order. | W8: It asks permission instead of giving an order, says why the caller is waiting and gives a real time. "A moment" is vague; "about two minutes" lets the caller decide. | X8: Could you ___, please? | Y8: Could + you + base verb + …, please? · I'll + base verb | Z8: "Could you" makes a polite request; "I'll" means you are deciding to do it now. | AA8: The question form lets the caller say yes. "Hold on" or "Wait" sounds like an order and can make a worried caller feel ignored. | AB8: ✗ Hold the line, I check it. → ✓ Could you hold for about two minutes, please? I'll check your order. | AC8: "Wait." or "Hold on." — it is an order, gives no reason, and the caller does not know if you are still there. | AD8: Instead of "Wait, I am checking", say "Could you hold for about two minutes, please? I'll check your order." | AE8: Would you mind holding for about two minutes while I look into this? | AF8: May I put you on hold for two or three minutes while I check your order? | AG8: Would it be all right if I placed you on hold for about two minutes while I review your account? | AH8: Thank you for holding. I can see your order — it was dispatched yesterday. | AI8: Sure, go ahead. · How long will it take? · Can't you just tell me now? | AJ8: Customer: "Can't you just tell me now?" → Agent: "I know you'd like it now, and I'll be quick. I need to check one detail so the answer is right. It will take about two minutes." | AK8: Many agents say "One minute, sir" and go silent. International callers expect a reason, a time, and a "thank you for holding" when you return. | AL8: Chat: "Let me check that for you. It'll take about two minutes." Email: not needed; say when you will reply instead. | AM8: Do not put an angry caller on hold right after they finish complaining; acknowledge their problem first. | AN8: Customer: My order still hasn't arrived. Can you check it? | Agent: Could you hold for about two minutes, please? I'll check your order. | Customer: Sure. | Agent: Thank you for holding. Your order was dispatched yesterday. | AO8: Ask permission before a hold, give the reason and a real time, and thank the caller first when you return. | AP8: Could you hold ____ about two minutes, please? I'll check your order. | AQ8: for | AR8: You need to check the order history. Which line puts the caller on hold in the most polite way? | AS8: A) You must hold the line now, because I need to check your order history. | B) Could you hold for about two minutes, please? I'll check your order. | C) Wait, please. I am checking your order now, so do not disconnect the call. | D) Hold on, sir, I will be back soon. I just need to look at a few things. | AT8: B | AU8: B asks permission, gives a reason and a real time. A and C are orders, and D gives no clear reason and no real time ("soon"). | AV8: hold / you / minutes / for / about / Could / two / please | AW8: Could you hold for about two minutes please | AX8: Kya aap lagbhag do minute hold kar sakte hain? Main aapka payment check karta hoon. | AY8: Could you hold for about two minutes, please? I'll check your payment. | AZ8: How long will it take? | BA8: About two minutes. If it's going to take longer, I'll come back and tell you before then. | BB8: Partner A calls about a missing parcel. Partner B asks to put A on hold, checks for two minutes, comes back, thanks A for holding and gives an update. | BC8: Record yourself saying the sentence, then the "Thank you for holding" line you would say when you return. | BD8: Did your voice rise on "please?" · Did you say why the caller is waiting? · Did you pronounce the final "d" in "hold"?
A9: CSV-B-007 | B9: Voice | C9: Basic | D9: A2 | E9: Say it | F9: Hold & check | G9: Thank you for holding, Ms Carter. I've found your order, and it's on its way. | H9: Agent | I9: You return to the line after a two-minute hold with the order update the caller asked for. | J9: You come back after putting someone on hold. What is the very first thing you say, before any information? | K9: THANK-you-for-HOLD-ing · ms-CAR-ter · i've-FOUND-your-OR-der · and-it's-ON-its-WAY | L9: thank_you → "thang-kyoo" · found_your → "foun-jor" · it's_on_its_way → "it-son-it-sway" | M9: Warm, slightly lifted energy on "Thank you for holding". Pause after the name. Falling, confident tone on "on its way". | N9: "Way" starts with a W: round your lips and keep the teeth off the lip; do not say "vay". Minimal pair: west / vest. Also keep the final "d" in "found" before "your". | O9: Neutral | P9: Grateful, warm, positive | Q9: 5 | R9: A little restless after waiting, and hoping for good news. | S9: Coming back from hold is like returning to a guest you left at the door: thank them first, then hand over the parcel. | T9: होल्ड करने के लिए धन्यवाद, मिस कार्टर। मुझे आपका ऑर्डर मिल गया है, और वह रास्ते में है। | U9: Hold karne ke liye dhanyavaad, Ms Carter. Mujhe aapka order mil gaya hai, aur woh raaste mein hai. | V9: Thanks for waiting. I found your order, and it is being delivered. | W9: Thanking first rewards the caller's patience and tells them you are back. Using their name and giving the news straight away ends the uncertainty of the wait. | X9: Thank you for holding, ___. I've found ___. | Y9: Thank you for + verb-ing · I've (I have) + past participle | Z9: "I've found" (present perfect) means you have just found it and the result matters now. | AA9: The thanks and the name make the wait feel respected. Coming back with "Hello? Yes, so…" sounds like you forgot about them. | AB9: ✗ Thank you for hold, Ms Carter. I am finding your order. → ✓ Thank you for holding, Ms Carter. I've found your order. | AC9: "Hello? Are you there? Yes, so your order…" — it skips the thanks and sounds disorganised. | AD9: Instead of "Sorry, I took long", say "Thank you for holding, Ms Carter. I've found your order." | AE9: Thanks so much for waiting, Ms Carter. I have an update for you. | AF9: Thank you for your patience, Ms Carter. Good news: your order has shipped. | AG9: Thank you very much for holding, Ms Carter. I have now located your order, and it is on its way to you. | AH9: It should reach you by Thursday. Would you like the tracking number? | AI9: Oh, great, thank you. · When will it arrive? · That took longer than two minutes. | AJ9: Customer: "That took a lot longer than two minutes." → Agent: "You're right, and I'm sorry it took longer. The good news is your order is on its way and should arrive by Thursday." | AK9: Some agents come back with "Yes ma'am, I have checked the same." International callers may not expect "the same"; they expect a clear "Thank you for holding", their name, then the news. | AL9: Chat: "Thanks for waiting, Ms Carter. I've found your order." Email: there is no hold; thank them for their patience only if your reply is late. | AM9: Do not come back with this if you have no update yet; say "Thank you for holding. I need about two more minutes. Is that all right?" | AN9: Customer: Sure, I'll hold. | Agent: Thank you for holding, Ms Carter. I've found your order, and it's on its way. | Customer: Great! When will it arrive? | Agent: It should reach you by Thursday. | AO9: Thank the caller first when you return from hold, before giving information. | AP9: Thank you for holding, Ms Carter. I've found your order, and it's on its ____. | AQ9: way | AR9: You come back after a two-minute hold. Which line should you say first? | AS9: A) Hello? Are you still there? I have your order details now. | B) Okay, I have checked your order and it is shipped now, Ms Carter. | C) Sorry, the system is very slow today. I found your order, finally. | D) Thank you for holding, Ms Carter. I've found your order. | AT9: D | AU9: D thanks the caller first and uses their name. B jumps straight to the news, C blames the system before thanking the caller, and A sounds as if you forgot them. | AV9: order / found / for / Thank / I've / holding / you / your | AW9: Thank you for holding I've found your order | AX9: Hold karne ke liye shukriya. Mujhe aapka payment mil gaya hai. | AY9: Thank you for holding. I've found your payment. | AZ9: Oh good. When will it get here? | BA9: The courier is due to deliver on Thursday. I can text you the tracking link if that helps. | BB9: Partner A waits on hold for an order update. Partner B returns, thanks A by name, gives the update and the delivery day, then offers the tracking number. | BC9: Record your return-from-hold line twice: once with good news, and once telling the caller you need two more minutes. | BD9: Did you thank the caller before giving news? · Did you use their name? · Did "way" start with rounded lips, not "v"?
A10: CSV-B-008 | B10: Voice | C10: Basic | D10: A2 | E10: Say it | F10: Apologise | G10: I'm sorry your parcel arrived late. I'll find out what happened right away. | H10: Agent | I10: The customer says their birthday gift arrived three days after the promised delivery date. | J10: A parcel came late. How do you apologise for the exact problem and show that you will act? | K10: i'm-SOR-ry · your-PAR-cel-a-RIVED-LATE · i'll-FIND-OUT · what-HAP-pened · right-a-WAY | L10: arrived_late → "a-rived-late" (touch the d, then release it into the l) · find_out → "fine-dout" · right_away → "ry-ta-way" | M10: Slow, low and sincere on "I'm sorry your parcel arrived late." Pause. Then a firmer, falling tone on "right away" to show action. | N10: "Arrived" and "happened" end in a final "d" after another consonant: say a-RIVED and HAP-pend, not "a-rive" and "hap-pen". The past tense lives in that last sound. | O10: Neutral | P10: Sincere, responsible, active | Q10: 5 | R10: Disappointed and annoyed that a promise was broken. | S10: A good apology has two hands: one says sorry for the exact thing, the other reaches out to fix it. | T10: मुझे खेद है कि आपका पार्सल देर से पहुँचा। मैं अभी पता करता/करती हूँ कि क्या हुआ। | U10: Mujhe khed hai ki aapka parcel der se pahuncha. Main abhi pata karta/karti hoon ki kya hua. | V10: I am sorry the package came late. I will check the reason now. | W10: It names the exact problem, which shows you listened, and pairs the apology with action. In Lewicki, Polin and Lount's 2016 study, taking responsibility ranked first and offering repair second among the parts of an apology; say "we" when the company is at fault: "I'm sorry we didn't deliver on time." | X10: I'm sorry ___. I'll ___ right away. | Y10: I'm sorry + (that) + clause · I'll + base verb | Z10: After "I'm sorry", add the exact problem as a full clause: "I'm sorry your parcel arrived late." | AA10: A specific apology sounds real. "Sorry for the inconvenience" sounds scripted, and "It's not my fault" sounds like you are defending yourself. | AB10: ✗ Sorry for your parcel delay, I will check what is the matter. → ✓ I'm sorry your parcel arrived late. I'll find out what happened right away. | AC10: "Sorry for the inconvenience caused." — it is vague and scripted, and says nothing about what you will do. | AD10: Instead of "That is the courier's fault, not ours", say "I'm sorry your parcel arrived late. I'll find out what happened right away." | AE10: I'm really sorry it came late, especially for a birthday. Let me check what went wrong. | AF10: I'm sorry we didn't deliver on time. I'll look into it now. | AG10: Please accept my apologies for the late delivery of your parcel. I will look into the cause immediately. | AH10: Could you give me your order number so I can check the delivery history? | AI10: Thank you, I appreciate that. · It was a birthday present, it's ruined now. · Sorry doesn't help me. | AJ10: Customer: "Sorry doesn't help me." → Agent: "You're right, saying sorry isn't enough. I'm checking the delivery record now so I can tell you what went wrong and what I can do to put it right." | AK10: "Sorry for the inconvenience caused" is a common line in Indian scripts. International customers often hear it as automatic; naming the actual problem sounds sincere. | AL10: Chat: "I'm sorry your parcel arrived late. I'll check what happened now." Email: apologise in the first line, then say what you did and what happens next. | AM10: Do not promise "right away" if the check needs another team and takes days; say when you will update the customer instead. | AN10: Customer: My parcel came three days late. | Agent: I'm sorry your parcel arrived late. I'll find out what happened right away. | Customer: Thank you. It was a gift. | Agent: That makes it even more disappointing. Could I have your order number, please? | AO10: Apologise specifically and take responsibility, then offer a fix (Lewicki, Polin & Lount, 2016). | AP10: I'm sorry your parcel arrived late. I'll find ____ what happened right away. | AQ10: out | AR10: A customer's parcel came three days late. Which apology works best? | AS10: A) Sorry for the inconvenience. We value your patience and will try to improve. | B) I understand, but the courier is responsible for the late delivery, not our company. | C) These things happen sometimes, so please be patient and wait for the next delivery. | D) I'm sorry your parcel arrived late. I'll find out what happened right away. | AT10: D | AU10: D names the problem and promises action. A is vague and sounds scripted, B pushes the blame onto someone else, and C brushes the problem off. | AV10: late / arrived / sorry / your / I'm / parcel | AW10: I'm sorry your parcel arrived late | AX10: Mujhe khed hai ki aapka refund der se aaya. Main abhi check karta hoon. | AY10: I'm sorry your refund came late. I'll check it right now. | AZ10: It was for my son's birthday. It's too late now. | BA10: I'm really sorry it missed his birthday. Let me check the order and see what I can do for you. | BB10: Partner A's parcel arrived three days late and missed a birthday. Partner B apologises for the exact problem, asks for the order number and says what they will check. | BC10: Record your apology, then the next line where you ask for the order number. Keep your voice slow and low on the apology. | BD10: Did you name the exact problem? · Did you say what you will do next? · Did you say the final "d" in "arrived"?
A11: CSV-B-009 | B11: Voice | C11: Basic | D11: B1 | E11: Say it | F11: Listen & clarify | G11: Let me make sure I have this right: you were charged twice for one order. Is that correct? | H11: Agent | I11: The caller has explained a long billing problem, and you want to check you understood before you act. | J11: The caller has just explained a long problem. How do you check your understanding before you start fixing anything? | K11: let-me-make-SURE · i-have-this-RIGHT · you-were-CHARGED-TWICE · for-ONE-OR-der · is-that-cor-RECT | L11: let_me → "lem-mee" · charged_twice → "charjd-twice" (a quick d, no extra vowel) · that_correct → "tha-cor-rect" (the t of "that" is barely heard) | M11: Fall on "right", then pause. Say the summary more slowly, with stress on "twice" and "one". Rise on "correct?" because it is a yes/no question. | N11: "Charged" ends in two sounds, "j" then "d": say "charjd". Dropping the "d" gives "charge", which sounds like the present tense. Also "this" has a voiced "th", not "dis". | O11: Neutral | P11: Careful, attentive, checking | Q11: 5 | R11: Frustrated, and keen to be understood before anything else happens. | S11: A tailor measures twice and cuts once: you check the problem before you cut into the fix. | T11: मैं पक्का कर लूँ कि मैंने सही समझा है: आपके एक ही ऑर्डर के लिए दो बार पैसे कट गए। क्या यह सही है? | U11: Main pakka kar loon ki maine sahi samjha hai: aapke ek hi order ke liye do baar paise kat gaye. Kya yeh sahi hai? | V11: I want to check I understood: you paid two times for one order. Yes? | W11: Saying the problem back shows you listened and lets the caller correct you early. Fixing the wrong problem wastes their time and makes them explain everything again. | X11: Let me make sure I have this right: ___. Is that correct? | Y11: Let me + base verb · you + were + past participle (passive) · Is that + adjective? | Z11: "You were charged" is passive: it says what happened to the caller without blaming anyone. | AA11: It sounds careful and respectful. "So what you are saying is…" in a flat voice can sound like you doubt them. | AB11: ✗ So you was charged twice for one order, right? → ✓ Let me make sure I have this right: you were charged twice for one order. Is that correct? | AC11: "Okay, okay, I understood." — said before the caller finishes, it sounds like you are not listening. | AD11: Instead of "Your problem is not clear", say "Let me make sure I have this right: you were charged twice for one order. Is that correct?" | AE11: So, just to check: you paid twice for a single order. Is that right? | AF11: Just to check, the money came out of your account twice for one order? | AG11: To be sure I have understood, you were charged twice for a single order. Have I got that right? | AH11: Thank you. Could you tell me the date of the order so I can find both payments? | AI11: Yes, exactly. · Not quite, it was two different orders. · Yes, and I want the money back today. | AJ11: Customer: "Why are you repeating it? I just told you!" → Agent: "I'm sorry, I know you've just explained it. I'm checking so I fix the right thing first time. You were charged twice, so I'll look at both payments now." | AK11: "You are telling that…" is a common Indian English pattern. International callers more often expect "So, you…" or "If I've understood correctly…", with a clear question at the end. | AL11: Chat: "Just to confirm: you were charged twice for one order?" Email: open with a one-line summary, such as "You were charged twice for order 55021." | AM11: Do not paraphrase a one-line request like "What are your opening hours?"; just answer it. | AN11: Customer: I ordered once but my card shows two payments. | Agent: Let me make sure I have this right: you were charged twice for one order. Is that correct? | Customer: Yes, that's it. | Agent: Thank you. Let me find both payments. | AO11: Paraphrase before solving: sum up what you heard, then ask a yes/no question so the caller can correct you. | AP11: Let me make ____ (starts with s) I have this right: you were charged twice for one order. | AQ11: sure | AR11: The caller has just explained a confusing billing problem. What should you do before you start fixing it? | AS11: A) Start the refund straight away, then explain what you did. | B) Say "Okay, okay, I understand" so they know you are listening. | C) Summarise the problem back to them and ask "Is that correct?" | D) Ask them to email all the details so you can read them properly. | AT11: C | AU11: C catches misunderstandings early. A may fix the wrong problem, B can sound as if you are not really listening, and D makes the caller do more work. | AV11: right / make / Let / have / sure / me / I / this | AW11: Let me make sure I have this right | AX11: Main confirm kar leti hoon: aapka parcel galat address par gaya, sahi? | AY11: Let me make sure I have this right: your parcel went to the wrong address. Is that correct? | AZ11: Not exactly. I was charged twice, but for two different amounts. | BA11: Thank you for correcting me. So there are two payments with different amounts. Let me look at both. | BB11: Partner A explains, at length, that a subscription renewed twice this month. Partner B listens without interrupting, sums up the problem in one sentence and asks "Is that correct?" | BC11: Record yourself summing up this problem to the customer in one sentence: they ordered a blue shirt and received a red one. Start with "Let me make sure I have this right" and say "you". | BD11: Did you sum up in one short sentence? · Did your voice rise on "correct?" · Did you say the final "d" in "charged"?
